2024-12-21 11:55 ERROR Traceback (most recent call last):
  File "C:\Users\a046829713\Desktop\program\RLTrading\lib\site-packages\sqlalchemy\engine\base.py", line 1967, in _exec_single_context
    self.dialect.do_execute(
  File "C:\Users\a046829713\Desktop\program\RLTrading\lib\site-packages\sqlalchemy\engine\default.py", line 941, in do_execute
    cursor.execute(statement, parameters)
  File "C:\Users\a046829713\Desktop\program\RLTrading\lib\site-packages\pymysql\cursors.py", line 153, in execute
    result = self._query(query)
  File "C:\Users\a046829713\Desktop\program\RLTrading\lib\site-packages\pymysql\cursors.py", line 322, in _query
    conn.query(q)
  File "C:\Users\a046829713\Desktop\program\RLTrading\lib\site-packages\pymysql\connections.py", line 563, in query
    self._affected_rows = self._read_query_result(unbuffered=unbuffered)
  File "C:\Users\a046829713\Desktop\program\RLTrading\lib\site-packages\pymysql\connections.py", line 825, in _read_query_result
    result.read()
  File "C:\Users\a046829713\Desktop\program\RLTrading\lib\site-packages\pymysql\connections.py", line 1199, in read
    first_packet = self.connection._read_packet()
  File "C:\Users\a046829713\Desktop\program\RLTrading\lib\site-packages\pymysql\connections.py", line 775, in _read_packet
    packet.raise_for_error()
  File "C:\Users\a046829713\Desktop\program\RLTrading\lib\site-packages\pymysql\protocol.py", line 219, in raise_for_error
    err.raise_mysql_exception(self._data)
  File "C:\Users\a046829713\Desktop\program\RLTrading\lib\site-packages\pymysql\err.py", line 150, in raise_mysql_exception
    raise errorclass(errno, errval)
pymysql.err.ProgrammingError: (1064, "You have an error in your SQL syntax; check the manual that corresponds to your MySQL server version for the right syntax to use near 'moveusdt-f-d' at line 1")

The above exception was the direct cause of the following exception:

Traceback (most recent call last):
  File "C:\Users\a046829713\Desktop\program\RLTrading\SynapseX\Database\SQL_operate.py", line 48, in read_Dateframe
    return pd.read_sql(text_msg, con=conn)
  File "C:\Users\a046829713\Desktop\program\RLTrading\lib\site-packages\pandas\io\sql.py", line 734, in read_sql
    return pandas_sql.read_query(
  File "C:\Users\a046829713\Desktop\program\RLTrading\lib\site-packages\pandas\io\sql.py", line 1836, in read_query
    result = self.execute(sql, params)
  File "C:\Users\a046829713\Desktop\program\RLTrading\lib\site-packages\pandas\io\sql.py", line 1659, in execute
    return self.con.exec_driver_sql(sql, *args)
  File "C:\Users\a046829713\Desktop\program\RLTrading\lib\site-packages\sqlalchemy\engine\base.py", line 1779, in exec_driver_sql
    ret = self._execute_context(
  File "C:\Users\a046829713\Desktop\program\RLTrading\lib\site-packages\sqlalchemy\engine\base.py", line 1846, in _execute_context
    return self._exec_single_context(
  File "C:\Users\a046829713\Desktop\program\RLTrading\lib\site-packages\sqlalchemy\engine\base.py", line 1986, in _exec_single_context
    self._handle_dbapi_exception(
  File "C:\Users\a046829713\Desktop\program\RLTrading\lib\site-packages\sqlalchemy\engine\base.py", line 2355, in _handle_dbapi_exception
    raise sqlalchemy_exception.with_traceback(exc_info[2]) from e
  File "C:\Users\a046829713\Desktop\program\RLTrading\lib\site-packages\sqlalchemy\engine\base.py", line 1967, in _exec_single_context
    self.dialect.do_execute(
  File "C:\Users\a046829713\Desktop\program\RLTrading\lib\site-packages\sqlalchemy\engine\default.py", line 941, in do_execute
    cursor.execute(statement, parameters)
  File "C:\Users\a046829713\Desktop\program\RLTrading\lib\site-packages\pymysql\cursors.py", line 153, in execute
    result = self._query(query)
  File "C:\Users\a046829713\Desktop\program\RLTrading\lib\site-packages\pymysql\cursors.py", line 322, in _query
    conn.query(q)
  File "C:\Users\a046829713\Desktop\program\RLTrading\lib\site-packages\pymysql\connections.py", line 563, in query
    self._affected_rows = self._read_query_result(unbuffered=unbuffered)
  File "C:\Users\a046829713\Desktop\program\RLTrading\lib\site-packages\pymysql\connections.py", line 825, in _read_query_result
    result.read()
  File "C:\Users\a046829713\Desktop\program\RLTrading\lib\site-packages\pymysql\connections.py", line 1199, in read
    first_packet = self.connection._read_packet()
  File "C:\Users\a046829713\Desktop\program\RLTrading\lib\site-packages\pymysql\connections.py", line 775, in _read_packet
    packet.raise_for_error()
  File "C:\Users\a046829713\Desktop\program\RLTrading\lib\site-packages\pymysql\protocol.py", line 219, in raise_for_error
    err.raise_mysql_exception(self._data)
  File "C:\Users\a046829713\Desktop\program\RLTrading\lib\site-packages\pymysql\err.py", line 150, in raise_mysql_exception
    raise errorclass(errno, errval)
sqlalchemy.exc.ProgrammingError: (pymysql.err.ProgrammingError) (1064, "You have an error in your SQL syntax; check the manual that corresponds to your MySQL server version for the right syntax to use near 'moveusdt-f-d' at line 1")
[SQL: moveusdt-f-d]
(Background on this error at: https://sqlalche.me/e/20/f405)

2024-12-21 11:55 ERROR Traceback (most recent call last):
  File "C:\Users\a046829713\Desktop\program\RLTrading\lib\site-packages\sqlalchemy\engine\base.py", line 1967, in _exec_single_context
    self.dialect.do_execute(
  File "C:\Users\a046829713\Desktop\program\RLTrading\lib\site-packages\sqlalchemy\engine\default.py", line 941, in do_execute
    cursor.execute(statement, parameters)
  File "C:\Users\a046829713\Desktop\program\RLTrading\lib\site-packages\pymysql\cursors.py", line 153, in execute
    result = self._query(query)
  File "C:\Users\a046829713\Desktop\program\RLTrading\lib\site-packages\pymysql\cursors.py", line 322, in _query
    conn.query(q)
  File "C:\Users\a046829713\Desktop\program\RLTrading\lib\site-packages\pymysql\connections.py", line 563, in query
    self._affected_rows = self._read_query_result(unbuffered=unbuffered)
  File "C:\Users\a046829713\Desktop\program\RLTrading\lib\site-packages\pymysql\connections.py", line 825, in _read_query_result
    result.read()
  File "C:\Users\a046829713\Desktop\program\RLTrading\lib\site-packages\pymysql\connections.py", line 1199, in read
    first_packet = self.connection._read_packet()
  File "C:\Users\a046829713\Desktop\program\RLTrading\lib\site-packages\pymysql\connections.py", line 775, in _read_packet
    packet.raise_for_error()
  File "C:\Users\a046829713\Desktop\program\RLTrading\lib\site-packages\pymysql\protocol.py", line 219, in raise_for_error
    err.raise_mysql_exception(self._data)
  File "C:\Users\a046829713\Desktop\program\RLTrading\lib\site-packages\pymysql\err.py", line 150, in raise_mysql_exception
    raise errorclass(errno, errval)
pymysql.err.ProgrammingError: (1064, "You have an error in your SQL syntax; check the manual that corresponds to your MySQL server version for the right syntax to use near 'raysolusdt-f-d' at line 1")

The above exception was the direct cause of the following exception:

Traceback (most recent call last):
  File "C:\Users\a046829713\Desktop\program\RLTrading\SynapseX\Database\SQL_operate.py", line 48, in read_Dateframe
    return pd.read_sql(text_msg, con=conn)
  File "C:\Users\a046829713\Desktop\program\RLTrading\lib\site-packages\pandas\io\sql.py", line 734, in read_sql
    return pandas_sql.read_query(
  File "C:\Users\a046829713\Desktop\program\RLTrading\lib\site-packages\pandas\io\sql.py", line 1836, in read_query
    result = self.execute(sql, params)
  File "C:\Users\a046829713\Desktop\program\RLTrading\lib\site-packages\pandas\io\sql.py", line 1659, in execute
    return self.con.exec_driver_sql(sql, *args)
  File "C:\Users\a046829713\Desktop\program\RLTrading\lib\site-packages\sqlalchemy\engine\base.py", line 1779, in exec_driver_sql
    ret = self._execute_context(
  File "C:\Users\a046829713\Desktop\program\RLTrading\lib\site-packages\sqlalchemy\engine\base.py", line 1846, in _execute_context
    return self._exec_single_context(
  File "C:\Users\a046829713\Desktop\program\RLTrading\lib\site-packages\sqlalchemy\engine\base.py", line 1986, in _exec_single_context
    self._handle_dbapi_exception(
  File "C:\Users\a046829713\Desktop\program\RLTrading\lib\site-packages\sqlalchemy\engine\base.py", line 2355, in _handle_dbapi_exception
    raise sqlalchemy_exception.with_traceback(exc_info[2]) from e
  File "C:\Users\a046829713\Desktop\program\RLTrading\lib\site-packages\sqlalchemy\engine\base.py", line 1967, in _exec_single_context
    self.dialect.do_execute(
  File "C:\Users\a046829713\Desktop\program\RLTrading\lib\site-packages\sqlalchemy\engine\default.py", line 941, in do_execute
    cursor.execute(statement, parameters)
  File "C:\Users\a046829713\Desktop\program\RLTrading\lib\site-packages\pymysql\cursors.py", line 153, in execute
    result = self._query(query)
  File "C:\Users\a046829713\Desktop\program\RLTrading\lib\site-packages\pymysql\cursors.py", line 322, in _query
    conn.query(q)
  File "C:\Users\a046829713\Desktop\program\RLTrading\lib\site-packages\pymysql\connections.py", line 563, in query
    self._affected_rows = self._read_query_result(unbuffered=unbuffered)
  File "C:\Users\a046829713\Desktop\program\RLTrading\lib\site-packages\pymysql\connections.py", line 825, in _read_query_result
    result.read()
  File "C:\Users\a046829713\Desktop\program\RLTrading\lib\site-packages\pymysql\connections.py", line 1199, in read
    first_packet = self.connection._read_packet()
  File "C:\Users\a046829713\Desktop\program\RLTrading\lib\site-packages\pymysql\connections.py", line 775, in _read_packet
    packet.raise_for_error()
  File "C:\Users\a046829713\Desktop\program\RLTrading\lib\site-packages\pymysql\protocol.py", line 219, in raise_for_error
    err.raise_mysql_exception(self._data)
  File "C:\Users\a046829713\Desktop\program\RLTrading\lib\site-packages\pymysql\err.py", line 150, in raise_mysql_exception
    raise errorclass(errno, errval)
sqlalchemy.exc.ProgrammingError: (pymysql.err.ProgrammingError) (1064, "You have an error in your SQL syntax; check the manual that corresponds to your MySQL server version for the right syntax to use near 'raysolusdt-f-d' at line 1")
[SQL: raysolusdt-f-d]
(Background on this error at: https://sqlalche.me/e/20/f405)

2024-12-21 11:55 ERROR Traceback (most recent call last):
  File "C:\Users\a046829713\Desktop\program\RLTrading\lib\site-packages\sqlalchemy\engine\base.py", line 1967, in _exec_single_context
    self.dialect.do_execute(
  File "C:\Users\a046829713\Desktop\program\RLTrading\lib\site-packages\sqlalchemy\engine\default.py", line 941, in do_execute
    cursor.execute(statement, parameters)
  File "C:\Users\a046829713\Desktop\program\RLTrading\lib\site-packages\pymysql\cursors.py", line 153, in execute
    result = self._query(query)
  File "C:\Users\a046829713\Desktop\program\RLTrading\lib\site-packages\pymysql\cursors.py", line 322, in _query
    conn.query(q)
  File "C:\Users\a046829713\Desktop\program\RLTrading\lib\site-packages\pymysql\connections.py", line 563, in query
    self._affected_rows = self._read_query_result(unbuffered=unbuffered)
  File "C:\Users\a046829713\Desktop\program\RLTrading\lib\site-packages\pymysql\connections.py", line 825, in _read_query_result
    result.read()
  File "C:\Users\a046829713\Desktop\program\RLTrading\lib\site-packages\pymysql\connections.py", line 1199, in read
    first_packet = self.connection._read_packet()
  File "C:\Users\a046829713\Desktop\program\RLTrading\lib\site-packages\pymysql\connections.py", line 775, in _read_packet
    packet.raise_for_error()
  File "C:\Users\a046829713\Desktop\program\RLTrading\lib\site-packages\pymysql\protocol.py", line 219, in raise_for_error
    err.raise_mysql_exception(self._data)
  File "C:\Users\a046829713\Desktop\program\RLTrading\lib\site-packages\pymysql\err.py", line 150, in raise_mysql_exception
    raise errorclass(errno, errval)
pymysql.err.ProgrammingError: (1064, "You have an error in your SQL syntax; check the manual that corresponds to your MySQL server version for the right syntax to use near 'komausdt-f-d' at line 1")

The above exception was the direct cause of the following exception:

Traceback (most recent call last):
  File "C:\Users\a046829713\Desktop\program\RLTrading\SynapseX\Database\SQL_operate.py", line 48, in read_Dateframe
    return pd.read_sql(text_msg, con=conn)
  File "C:\Users\a046829713\Desktop\program\RLTrading\lib\site-packages\pandas\io\sql.py", line 734, in read_sql
    return pandas_sql.read_query(
  File "C:\Users\a046829713\Desktop\program\RLTrading\lib\site-packages\pandas\io\sql.py", line 1836, in read_query
    result = self.execute(sql, params)
  File "C:\Users\a046829713\Desktop\program\RLTrading\lib\site-packages\pandas\io\sql.py", line 1659, in execute
    return self.con.exec_driver_sql(sql, *args)
  File "C:\Users\a046829713\Desktop\program\RLTrading\lib\site-packages\sqlalchemy\engine\base.py", line 1779, in exec_driver_sql
    ret = self._execute_context(
  File "C:\Users\a046829713\Desktop\program\RLTrading\lib\site-packages\sqlalchemy\engine\base.py", line 1846, in _execute_context
    return self._exec_single_context(
  File "C:\Users\a046829713\Desktop\program\RLTrading\lib\site-packages\sqlalchemy\engine\base.py", line 1986, in _exec_single_context
    self._handle_dbapi_exception(
  File "C:\Users\a046829713\Desktop\program\RLTrading\lib\site-packages\sqlalchemy\engine\base.py", line 2355, in _handle_dbapi_exception
    raise sqlalchemy_exception.with_traceback(exc_info[2]) from e
  File "C:\Users\a046829713\Desktop\program\RLTrading\lib\site-packages\sqlalchemy\engine\base.py", line 1967, in _exec_single_context
    self.dialect.do_execute(
  File "C:\Users\a046829713\Desktop\program\RLTrading\lib\site-packages\sqlalchemy\engine\default.py", line 941, in do_execute
    cursor.execute(statement, parameters)
  File "C:\Users\a046829713\Desktop\program\RLTrading\lib\site-packages\pymysql\cursors.py", line 153, in execute
    result = self._query(query)
  File "C:\Users\a046829713\Desktop\program\RLTrading\lib\site-packages\pymysql\cursors.py", line 322, in _query
    conn.query(q)
  File "C:\Users\a046829713\Desktop\program\RLTrading\lib\site-packages\pymysql\connections.py", line 563, in query
    self._affected_rows = self._read_query_result(unbuffered=unbuffered)
  File "C:\Users\a046829713\Desktop\program\RLTrading\lib\site-packages\pymysql\connections.py", line 825, in _read_query_result
    result.read()
  File "C:\Users\a046829713\Desktop\program\RLTrading\lib\site-packages\pymysql\connections.py", line 1199, in read
    first_packet = self.connection._read_packet()
  File "C:\Users\a046829713\Desktop\program\RLTrading\lib\site-packages\pymysql\connections.py", line 775, in _read_packet
    packet.raise_for_error()
  File "C:\Users\a046829713\Desktop\program\RLTrading\lib\site-packages\pymysql\protocol.py", line 219, in raise_for_error
    err.raise_mysql_exception(self._data)
  File "C:\Users\a046829713\Desktop\program\RLTrading\lib\site-packages\pymysql\err.py", line 150, in raise_mysql_exception
    raise errorclass(errno, errval)
sqlalchemy.exc.ProgrammingError: (pymysql.err.ProgrammingError) (1064, "You have an error in your SQL syntax; check the manual that corresponds to your MySQL server version for the right syntax to use near 'komausdt-f-d' at line 1")
[SQL: komausdt-f-d]
(Background on this error at: https://sqlalche.me/e/20/f405)

2024-12-21 11:55 ERROR Traceback (most recent call last):
  File "C:\Users\a046829713\Desktop\program\RLTrading\lib\site-packages\sqlalchemy\engine\base.py", line 1967, in _exec_single_context
    self.dialect.do_execute(
  File "C:\Users\a046829713\Desktop\program\RLTrading\lib\site-packages\sqlalchemy\engine\default.py", line 941, in do_execute
    cursor.execute(statement, parameters)
  File "C:\Users\a046829713\Desktop\program\RLTrading\lib\site-packages\pymysql\cursors.py", line 153, in execute
    result = self._query(query)
  File "C:\Users\a046829713\Desktop\program\RLTrading\lib\site-packages\pymysql\cursors.py", line 322, in _query
    conn.query(q)
  File "C:\Users\a046829713\Desktop\program\RLTrading\lib\site-packages\pymysql\connections.py", line 563, in query
    self._affected_rows = self._read_query_result(unbuffered=unbuffered)
  File "C:\Users\a046829713\Desktop\program\RLTrading\lib\site-packages\pymysql\connections.py", line 825, in _read_query_result
    result.read()
  File "C:\Users\a046829713\Desktop\program\RLTrading\lib\site-packages\pymysql\connections.py", line 1199, in read
    first_packet = self.connection._read_packet()
  File "C:\Users\a046829713\Desktop\program\RLTrading\lib\site-packages\pymysql\connections.py", line 775, in _read_packet
    packet.raise_for_error()
  File "C:\Users\a046829713\Desktop\program\RLTrading\lib\site-packages\pymysql\protocol.py", line 219, in raise_for_error
    err.raise_mysql_exception(self._data)
  File "C:\Users\a046829713\Desktop\program\RLTrading\lib\site-packages\pymysql\err.py", line 150, in raise_mysql_exception
    raise errorclass(errno, errval)
pymysql.err.ProgrammingError: (1064, "You have an error in your SQL syntax; check the manual that corresponds to your MySQL server version for the right syntax to use near 'virtualusdt-f-d' at line 1")

The above exception was the direct cause of the following exception:

Traceback (most recent call last):
  File "C:\Users\a046829713\Desktop\program\RLTrading\SynapseX\Database\SQL_operate.py", line 48, in read_Dateframe
    return pd.read_sql(text_msg, con=conn)
  File "C:\Users\a046829713\Desktop\program\RLTrading\lib\site-packages\pandas\io\sql.py", line 734, in read_sql
    return pandas_sql.read_query(
  File "C:\Users\a046829713\Desktop\program\RLTrading\lib\site-packages\pandas\io\sql.py", line 1836, in read_query
    result = self.execute(sql, params)
  File "C:\Users\a046829713\Desktop\program\RLTrading\lib\site-packages\pandas\io\sql.py", line 1659, in execute
    return self.con.exec_driver_sql(sql, *args)
  File "C:\Users\a046829713\Desktop\program\RLTrading\lib\site-packages\sqlalchemy\engine\base.py", line 1779, in exec_driver_sql
    ret = self._execute_context(
  File "C:\Users\a046829713\Desktop\program\RLTrading\lib\site-packages\sqlalchemy\engine\base.py", line 1846, in _execute_context
    return self._exec_single_context(
  File "C:\Users\a046829713\Desktop\program\RLTrading\lib\site-packages\sqlalchemy\engine\base.py", line 1986, in _exec_single_context
    self._handle_dbapi_exception(
  File "C:\Users\a046829713\Desktop\program\RLTrading\lib\site-packages\sqlalchemy\engine\base.py", line 2355, in _handle_dbapi_exception
    raise sqlalchemy_exception.with_traceback(exc_info[2]) from e
  File "C:\Users\a046829713\Desktop\program\RLTrading\lib\site-packages\sqlalchemy\engine\base.py", line 1967, in _exec_single_context
    self.dialect.do_execute(
  File "C:\Users\a046829713\Desktop\program\RLTrading\lib\site-packages\sqlalchemy\engine\default.py", line 941, in do_execute
    cursor.execute(statement, parameters)
  File "C:\Users\a046829713\Desktop\program\RLTrading\lib\site-packages\pymysql\cursors.py", line 153, in execute
    result = self._query(query)
  File "C:\Users\a046829713\Desktop\program\RLTrading\lib\site-packages\pymysql\cursors.py", line 322, in _query
    conn.query(q)
  File "C:\Users\a046829713\Desktop\program\RLTrading\lib\site-packages\pymysql\connections.py", line 563, in query
    self._affected_rows = self._read_query_result(unbuffered=unbuffered)
  File "C:\Users\a046829713\Desktop\program\RLTrading\lib\site-packages\pymysql\connections.py", line 825, in _read_query_result
    result.read()
  File "C:\Users\a046829713\Desktop\program\RLTrading\lib\site-packages\pymysql\connections.py", line 1199, in read
    first_packet = self.connection._read_packet()
  File "C:\Users\a046829713\Desktop\program\RLTrading\lib\site-packages\pymysql\connections.py", line 775, in _read_packet
    packet.raise_for_error()
  File "C:\Users\a046829713\Desktop\program\RLTrading\lib\site-packages\pymysql\protocol.py", line 219, in raise_for_error
    err.raise_mysql_exception(self._data)
  File "C:\Users\a046829713\Desktop\program\RLTrading\lib\site-packages\pymysql\err.py", line 150, in raise_mysql_exception
    raise errorclass(errno, errval)
sqlalchemy.exc.ProgrammingError: (pymysql.err.ProgrammingError) (1064, "You have an error in your SQL syntax; check the manual that corresponds to your MySQL server version for the right syntax to use near 'virtualusdt-f-d' at line 1")
[SQL: virtualusdt-f-d]
(Background on this error at: https://sqlalche.me/e/20/f405)

2024-12-21 11:55 ERROR Traceback (most recent call last):
  File "C:\Users\a046829713\Desktop\program\RLTrading\lib\site-packages\sqlalchemy\engine\base.py", line 1967, in _exec_single_context
    self.dialect.do_execute(
  File "C:\Users\a046829713\Desktop\program\RLTrading\lib\site-packages\sqlalchemy\engine\default.py", line 941, in do_execute
    cursor.execute(statement, parameters)
  File "C:\Users\a046829713\Desktop\program\RLTrading\lib\site-packages\pymysql\cursors.py", line 153, in execute
    result = self._query(query)
  File "C:\Users\a046829713\Desktop\program\RLTrading\lib\site-packages\pymysql\cursors.py", line 322, in _query
    conn.query(q)
  File "C:\Users\a046829713\Desktop\program\RLTrading\lib\site-packages\pymysql\connections.py", line 563, in query
    self._affected_rows = self._read_query_result(unbuffered=unbuffered)
  File "C:\Users\a046829713\Desktop\program\RLTrading\lib\site-packages\pymysql\connections.py", line 825, in _read_query_result
    result.read()
  File "C:\Users\a046829713\Desktop\program\RLTrading\lib\site-packages\pymysql\connections.py", line 1199, in read
    first_packet = self.connection._read_packet()
  File "C:\Users\a046829713\Desktop\program\RLTrading\lib\site-packages\pymysql\connections.py", line 775, in _read_packet
    packet.raise_for_error()
  File "C:\Users\a046829713\Desktop\program\RLTrading\lib\site-packages\pymysql\protocol.py", line 219, in raise_for_error
    err.raise_mysql_exception(self._data)
  File "C:\Users\a046829713\Desktop\program\RLTrading\lib\site-packages\pymysql\err.py", line 150, in raise_mysql_exception
    raise errorclass(errno, errval)
pymysql.err.ProgrammingError: (1064, "You have an error in your SQL syntax; check the manual that corresponds to your MySQL server version for the right syntax to use near 'spxusdt-f-d' at line 1")

The above exception was the direct cause of the following exception:

Traceback (most recent call last):
  File "C:\Users\a046829713\Desktop\program\RLTrading\SynapseX\Database\SQL_operate.py", line 48, in read_Dateframe
    return pd.read_sql(text_msg, con=conn)
  File "C:\Users\a046829713\Desktop\program\RLTrading\lib\site-packages\pandas\io\sql.py", line 734, in read_sql
    return pandas_sql.read_query(
  File "C:\Users\a046829713\Desktop\program\RLTrading\lib\site-packages\pandas\io\sql.py", line 1836, in read_query
    result = self.execute(sql, params)
  File "C:\Users\a046829713\Desktop\program\RLTrading\lib\site-packages\pandas\io\sql.py", line 1659, in execute
    return self.con.exec_driver_sql(sql, *args)
  File "C:\Users\a046829713\Desktop\program\RLTrading\lib\site-packages\sqlalchemy\engine\base.py", line 1779, in exec_driver_sql
    ret = self._execute_context(
  File "C:\Users\a046829713\Desktop\program\RLTrading\lib\site-packages\sqlalchemy\engine\base.py", line 1846, in _execute_context
    return self._exec_single_context(
  File "C:\Users\a046829713\Desktop\program\RLTrading\lib\site-packages\sqlalchemy\engine\base.py", line 1986, in _exec_single_context
    self._handle_dbapi_exception(
  File "C:\Users\a046829713\Desktop\program\RLTrading\lib\site-packages\sqlalchemy\engine\base.py", line 2355, in _handle_dbapi_exception
    raise sqlalchemy_exception.with_traceback(exc_info[2]) from e
  File "C:\Users\a046829713\Desktop\program\RLTrading\lib\site-packages\sqlalchemy\engine\base.py", line 1967, in _exec_single_context
    self.dialect.do_execute(
  File "C:\Users\a046829713\Desktop\program\RLTrading\lib\site-packages\sqlalchemy\engine\default.py", line 941, in do_execute
    cursor.execute(statement, parameters)
  File "C:\Users\a046829713\Desktop\program\RLTrading\lib\site-packages\pymysql\cursors.py", line 153, in execute
    result = self._query(query)
  File "C:\Users\a046829713\Desktop\program\RLTrading\lib\site-packages\pymysql\cursors.py", line 322, in _query
    conn.query(q)
  File "C:\Users\a046829713\Desktop\program\RLTrading\lib\site-packages\pymysql\connections.py", line 563, in query
    self._affected_rows = self._read_query_result(unbuffered=unbuffered)
  File "C:\Users\a046829713\Desktop\program\RLTrading\lib\site-packages\pymysql\connections.py", line 825, in _read_query_result
    result.read()
  File "C:\Users\a046829713\Desktop\program\RLTrading\lib\site-packages\pymysql\connections.py", line 1199, in read
    first_packet = self.connection._read_packet()
  File "C:\Users\a046829713\Desktop\program\RLTrading\lib\site-packages\pymysql\connections.py", line 775, in _read_packet
    packet.raise_for_error()
  File "C:\Users\a046829713\Desktop\program\RLTrading\lib\site-packages\pymysql\protocol.py", line 219, in raise_for_error
    err.raise_mysql_exception(self._data)
  File "C:\Users\a046829713\Desktop\program\RLTrading\lib\site-packages\pymysql\err.py", line 150, in raise_mysql_exception
    raise errorclass(errno, errval)
sqlalchemy.exc.ProgrammingError: (pymysql.err.ProgrammingError) (1064, "You have an error in your SQL syntax; check the manual that corresponds to your MySQL server version for the right syntax to use near 'spxusdt-f-d' at line 1")
[SQL: spxusdt-f-d]
(Background on this error at: https://sqlalche.me/e/20/f405)

2024-12-21 11:55 ERROR Traceback (most recent call last):
  File "C:\Users\a046829713\Desktop\program\RLTrading\lib\site-packages\sqlalchemy\engine\base.py", line 1967, in _exec_single_context
    self.dialect.do_execute(
  File "C:\Users\a046829713\Desktop\program\RLTrading\lib\site-packages\sqlalchemy\engine\default.py", line 941, in do_execute
    cursor.execute(statement, parameters)
  File "C:\Users\a046829713\Desktop\program\RLTrading\lib\site-packages\pymysql\cursors.py", line 153, in execute
    result = self._query(query)
  File "C:\Users\a046829713\Desktop\program\RLTrading\lib\site-packages\pymysql\cursors.py", line 322, in _query
    conn.query(q)
  File "C:\Users\a046829713\Desktop\program\RLTrading\lib\site-packages\pymysql\connections.py", line 563, in query
    self._affected_rows = self._read_query_result(unbuffered=unbuffered)
  File "C:\Users\a046829713\Desktop\program\RLTrading\lib\site-packages\pymysql\connections.py", line 825, in _read_query_result
    result.read()
  File "C:\Users\a046829713\Desktop\program\RLTrading\lib\site-packages\pymysql\connections.py", line 1199, in read
    first_packet = self.connection._read_packet()
  File "C:\Users\a046829713\Desktop\program\RLTrading\lib\site-packages\pymysql\connections.py", line 775, in _read_packet
    packet.raise_for_error()
  File "C:\Users\a046829713\Desktop\program\RLTrading\lib\site-packages\pymysql\protocol.py", line 219, in raise_for_error
    err.raise_mysql_exception(self._data)
  File "C:\Users\a046829713\Desktop\program\RLTrading\lib\site-packages\pymysql\err.py", line 150, in raise_mysql_exception
    raise errorclass(errno, errval)
pymysql.err.ProgrammingError: (1064, "You have an error in your SQL syntax; check the manual that corresponds to your MySQL server version for the right syntax to use near 'meusdt-f-d' at line 1")

The above exception was the direct cause of the following exception:

Traceback (most recent call last):
  File "C:\Users\a046829713\Desktop\program\RLTrading\SynapseX\Database\SQL_operate.py", line 48, in read_Dateframe
    return pd.read_sql(text_msg, con=conn)
  File "C:\Users\a046829713\Desktop\program\RLTrading\lib\site-packages\pandas\io\sql.py", line 734, in read_sql
    return pandas_sql.read_query(
  File "C:\Users\a046829713\Desktop\program\RLTrading\lib\site-packages\pandas\io\sql.py", line 1836, in read_query
    result = self.execute(sql, params)
  File "C:\Users\a046829713\Desktop\program\RLTrading\lib\site-packages\pandas\io\sql.py", line 1659, in execute
    return self.con.exec_driver_sql(sql, *args)
  File "C:\Users\a046829713\Desktop\program\RLTrading\lib\site-packages\sqlalchemy\engine\base.py", line 1779, in exec_driver_sql
    ret = self._execute_context(
  File "C:\Users\a046829713\Desktop\program\RLTrading\lib\site-packages\sqlalchemy\engine\base.py", line 1846, in _execute_context
    return self._exec_single_context(
  File "C:\Users\a046829713\Desktop\program\RLTrading\lib\site-packages\sqlalchemy\engine\base.py", line 1986, in _exec_single_context
    self._handle_dbapi_exception(
  File "C:\Users\a046829713\Desktop\program\RLTrading\lib\site-packages\sqlalchemy\engine\base.py", line 2355, in _handle_dbapi_exception
    raise sqlalchemy_exception.with_traceback(exc_info[2]) from e
  File "C:\Users\a046829713\Desktop\program\RLTrading\lib\site-packages\sqlalchemy\engine\base.py", line 1967, in _exec_single_context
    self.dialect.do_execute(
  File "C:\Users\a046829713\Desktop\program\RLTrading\lib\site-packages\sqlalchemy\engine\default.py", line 941, in do_execute
    cursor.execute(statement, parameters)
  File "C:\Users\a046829713\Desktop\program\RLTrading\lib\site-packages\pymysql\cursors.py", line 153, in execute
    result = self._query(query)
  File "C:\Users\a046829713\Desktop\program\RLTrading\lib\site-packages\pymysql\cursors.py", line 322, in _query
    conn.query(q)
  File "C:\Users\a046829713\Desktop\program\RLTrading\lib\site-packages\pymysql\connections.py", line 563, in query
    self._affected_rows = self._read_query_result(unbuffered=unbuffered)
  File "C:\Users\a046829713\Desktop\program\RLTrading\lib\site-packages\pymysql\connections.py", line 825, in _read_query_result
    result.read()
  File "C:\Users\a046829713\Desktop\program\RLTrading\lib\site-packages\pymysql\connections.py", line 1199, in read
    first_packet = self.connection._read_packet()
  File "C:\Users\a046829713\Desktop\program\RLTrading\lib\site-packages\pymysql\connections.py", line 775, in _read_packet
    packet.raise_for_error()
  File "C:\Users\a046829713\Desktop\program\RLTrading\lib\site-packages\pymysql\protocol.py", line 219, in raise_for_error
    err.raise_mysql_exception(self._data)
  File "C:\Users\a046829713\Desktop\program\RLTrading\lib\site-packages\pymysql\err.py", line 150, in raise_mysql_exception
    raise errorclass(errno, errval)
sqlalchemy.exc.ProgrammingError: (pymysql.err.ProgrammingError) (1064, "You have an error in your SQL syntax; check the manual that corresponds to your MySQL server version for the right syntax to use near 'meusdt-f-d' at line 1")
[SQL: meusdt-f-d]
(Background on this error at: https://sqlalche.me/e/20/f405)

2024-12-21 11:55 ERROR Traceback (most recent call last):
  File "C:\Users\a046829713\Desktop\program\RLTrading\lib\site-packages\sqlalchemy\engine\base.py", line 1967, in _exec_single_context
    self.dialect.do_execute(
  File "C:\Users\a046829713\Desktop\program\RLTrading\lib\site-packages\sqlalchemy\engine\default.py", line 941, in do_execute
    cursor.execute(statement, parameters)
  File "C:\Users\a046829713\Desktop\program\RLTrading\lib\site-packages\pymysql\cursors.py", line 153, in execute
    result = self._query(query)
  File "C:\Users\a046829713\Desktop\program\RLTrading\lib\site-packages\pymysql\cursors.py", line 322, in _query
    conn.query(q)
  File "C:\Users\a046829713\Desktop\program\RLTrading\lib\site-packages\pymysql\connections.py", line 563, in query
    self._affected_rows = self._read_query_result(unbuffered=unbuffered)
  File "C:\Users\a046829713\Desktop\program\RLTrading\lib\site-packages\pymysql\connections.py", line 825, in _read_query_result
    result.read()
  File "C:\Users\a046829713\Desktop\program\RLTrading\lib\site-packages\pymysql\connections.py", line 1199, in read
    first_packet = self.connection._read_packet()
  File "C:\Users\a046829713\Desktop\program\RLTrading\lib\site-packages\pymysql\connections.py", line 775, in _read_packet
    packet.raise_for_error()
  File "C:\Users\a046829713\Desktop\program\RLTrading\lib\site-packages\pymysql\protocol.py", line 219, in raise_for_error
    err.raise_mysql_exception(self._data)
  File "C:\Users\a046829713\Desktop\program\RLTrading\lib\site-packages\pymysql\err.py", line 150, in raise_mysql_exception
    raise errorclass(errno, errval)
pymysql.err.ProgrammingError: (1064, "You have an error in your SQL syntax; check the manual that corresponds to your MySQL server version for the right syntax to use near 'avausdt-f-d' at line 1")

The above exception was the direct cause of the following exception:

Traceback (most recent call last):
  File "C:\Users\a046829713\Desktop\program\RLTrading\SynapseX\Database\SQL_operate.py", line 48, in read_Dateframe
    return pd.read_sql(text_msg, con=conn)
  File "C:\Users\a046829713\Desktop\program\RLTrading\lib\site-packages\pandas\io\sql.py", line 734, in read_sql
    return pandas_sql.read_query(
  File "C:\Users\a046829713\Desktop\program\RLTrading\lib\site-packages\pandas\io\sql.py", line 1836, in read_query
    result = self.execute(sql, params)
  File "C:\Users\a046829713\Desktop\program\RLTrading\lib\site-packages\pandas\io\sql.py", line 1659, in execute
    return self.con.exec_driver_sql(sql, *args)
  File "C:\Users\a046829713\Desktop\program\RLTrading\lib\site-packages\sqlalchemy\engine\base.py", line 1779, in exec_driver_sql
    ret = self._execute_context(
  File "C:\Users\a046829713\Desktop\program\RLTrading\lib\site-packages\sqlalchemy\engine\base.py", line 1846, in _execute_context
    return self._exec_single_context(
  File "C:\Users\a046829713\Desktop\program\RLTrading\lib\site-packages\sqlalchemy\engine\base.py", line 1986, in _exec_single_context
    self._handle_dbapi_exception(
  File "C:\Users\a046829713\Desktop\program\RLTrading\lib\site-packages\sqlalchemy\engine\base.py", line 2355, in _handle_dbapi_exception
    raise sqlalchemy_exception.with_traceback(exc_info[2]) from e
  File "C:\Users\a046829713\Desktop\program\RLTrading\lib\site-packages\sqlalchemy\engine\base.py", line 1967, in _exec_single_context
    self.dialect.do_execute(
  File "C:\Users\a046829713\Desktop\program\RLTrading\lib\site-packages\sqlalchemy\engine\default.py", line 941, in do_execute
    cursor.execute(statement, parameters)
  File "C:\Users\a046829713\Desktop\program\RLTrading\lib\site-packages\pymysql\cursors.py", line 153, in execute
    result = self._query(query)
  File "C:\Users\a046829713\Desktop\program\RLTrading\lib\site-packages\pymysql\cursors.py", line 322, in _query
    conn.query(q)
  File "C:\Users\a046829713\Desktop\program\RLTrading\lib\site-packages\pymysql\connections.py", line 563, in query
    self._affected_rows = self._read_query_result(unbuffered=unbuffered)
  File "C:\Users\a046829713\Desktop\program\RLTrading\lib\site-packages\pymysql\connections.py", line 825, in _read_query_result
    result.read()
  File "C:\Users\a046829713\Desktop\program\RLTrading\lib\site-packages\pymysql\connections.py", line 1199, in read
    first_packet = self.connection._read_packet()
  File "C:\Users\a046829713\Desktop\program\RLTrading\lib\site-packages\pymysql\connections.py", line 775, in _read_packet
    packet.raise_for_error()
  File "C:\Users\a046829713\Desktop\program\RLTrading\lib\site-packages\pymysql\protocol.py", line 219, in raise_for_error
    err.raise_mysql_exception(self._data)
  File "C:\Users\a046829713\Desktop\program\RLTrading\lib\site-packages\pymysql\err.py", line 150, in raise_mysql_exception
    raise errorclass(errno, errval)
sqlalchemy.exc.ProgrammingError: (pymysql.err.ProgrammingError) (1064, "You have an error in your SQL syntax; check the manual that corresponds to your MySQL server version for the right syntax to use near 'avausdt-f-d' at line 1")
[SQL: avausdt-f-d]
(Background on this error at: https://sqlalche.me/e/20/f405)

2024-12-21 11:55 ERROR Traceback (most recent call last):
  File "C:\Users\a046829713\Desktop\program\RLTrading\lib\site-packages\sqlalchemy\engine\base.py", line 1967, in _exec_single_context
    self.dialect.do_execute(
  File "C:\Users\a046829713\Desktop\program\RLTrading\lib\site-packages\sqlalchemy\engine\default.py", line 941, in do_execute
    cursor.execute(statement, parameters)
  File "C:\Users\a046829713\Desktop\program\RLTrading\lib\site-packages\pymysql\cursors.py", line 153, in execute
    result = self._query(query)
  File "C:\Users\a046829713\Desktop\program\RLTrading\lib\site-packages\pymysql\cursors.py", line 322, in _query
    conn.query(q)
  File "C:\Users\a046829713\Desktop\program\RLTrading\lib\site-packages\pymysql\connections.py", line 563, in query
    self._affected_rows = self._read_query_result(unbuffered=unbuffered)
  File "C:\Users\a046829713\Desktop\program\RLTrading\lib\site-packages\pymysql\connections.py", line 825, in _read_query_result
    result.read()
  File "C:\Users\a046829713\Desktop\program\RLTrading\lib\site-packages\pymysql\connections.py", line 1199, in read
    first_packet = self.connection._read_packet()
  File "C:\Users\a046829713\Desktop\program\RLTrading\lib\site-packages\pymysql\connections.py", line 775, in _read_packet
    packet.raise_for_error()
  File "C:\Users\a046829713\Desktop\program\RLTrading\lib\site-packages\pymysql\protocol.py", line 219, in raise_for_error
    err.raise_mysql_exception(self._data)
  File "C:\Users\a046829713\Desktop\program\RLTrading\lib\site-packages\pymysql\err.py", line 150, in raise_mysql_exception
    raise errorclass(errno, errval)
pymysql.err.ProgrammingError: (1064, "You have an error in your SQL syntax; check the manual that corresponds to your MySQL server version for the right syntax to use near 'degousdt-f-d' at line 1")

The above exception was the direct cause of the following exception:

Traceback (most recent call last):
  File "C:\Users\a046829713\Desktop\program\RLTrading\SynapseX\Database\SQL_operate.py", line 48, in read_Dateframe
    return pd.read_sql(text_msg, con=conn)
  File "C:\Users\a046829713\Desktop\program\RLTrading\lib\site-packages\pandas\io\sql.py", line 734, in read_sql
    return pandas_sql.read_query(
  File "C:\Users\a046829713\Desktop\program\RLTrading\lib\site-packages\pandas\io\sql.py", line 1836, in read_query
    result = self.execute(sql, params)
  File "C:\Users\a046829713\Desktop\program\RLTrading\lib\site-packages\pandas\io\sql.py", line 1659, in execute
    return self.con.exec_driver_sql(sql, *args)
  File "C:\Users\a046829713\Desktop\program\RLTrading\lib\site-packages\sqlalchemy\engine\base.py", line 1779, in exec_driver_sql
    ret = self._execute_context(
  File "C:\Users\a046829713\Desktop\program\RLTrading\lib\site-packages\sqlalchemy\engine\base.py", line 1846, in _execute_context
    return self._exec_single_context(
  File "C:\Users\a046829713\Desktop\program\RLTrading\lib\site-packages\sqlalchemy\engine\base.py", line 1986, in _exec_single_context
    self._handle_dbapi_exception(
  File "C:\Users\a046829713\Desktop\program\RLTrading\lib\site-packages\sqlalchemy\engine\base.py", line 2355, in _handle_dbapi_exception
    raise sqlalchemy_exception.with_traceback(exc_info[2]) from e
  File "C:\Users\a046829713\Desktop\program\RLTrading\lib\site-packages\sqlalchemy\engine\base.py", line 1967, in _exec_single_context
    self.dialect.do_execute(
  File "C:\Users\a046829713\Desktop\program\RLTrading\lib\site-packages\sqlalchemy\engine\default.py", line 941, in do_execute
    cursor.execute(statement, parameters)
  File "C:\Users\a046829713\Desktop\program\RLTrading\lib\site-packages\pymysql\cursors.py", line 153, in execute
    result = self._query(query)
  File "C:\Users\a046829713\Desktop\program\RLTrading\lib\site-packages\pymysql\cursors.py", line 322, in _query
    conn.query(q)
  File "C:\Users\a046829713\Desktop\program\RLTrading\lib\site-packages\pymysql\connections.py", line 563, in query
    self._affected_rows = self._read_query_result(unbuffered=unbuffered)
  File "C:\Users\a046829713\Desktop\program\RLTrading\lib\site-packages\pymysql\connections.py", line 825, in _read_query_result
    result.read()
  File "C:\Users\a046829713\Desktop\program\RLTrading\lib\site-packages\pymysql\connections.py", line 1199, in read
    first_packet = self.connection._read_packet()
  File "C:\Users\a046829713\Desktop\program\RLTrading\lib\site-packages\pymysql\connections.py", line 775, in _read_packet
    packet.raise_for_error()
  File "C:\Users\a046829713\Desktop\program\RLTrading\lib\site-packages\pymysql\protocol.py", line 219, in raise_for_error
    err.raise_mysql_exception(self._data)
  File "C:\Users\a046829713\Desktop\program\RLTrading\lib\site-packages\pymysql\err.py", line 150, in raise_mysql_exception
    raise errorclass(errno, errval)
sqlalchemy.exc.ProgrammingError: (pymysql.err.ProgrammingError) (1064, "You have an error in your SQL syntax; check the manual that corresponds to your MySQL server version for the right syntax to use near 'degousdt-f-d' at line 1")
[SQL: degousdt-f-d]
(Background on this error at: https://sqlalche.me/e/20/f405)

2024-12-21 11:55 ERROR Traceback (most recent call last):
  File "C:\Users\a046829713\Desktop\program\RLTrading\lib\site-packages\sqlalchemy\engine\base.py", line 1967, in _exec_single_context
    self.dialect.do_execute(
  File "C:\Users\a046829713\Desktop\program\RLTrading\lib\site-packages\sqlalchemy\engine\default.py", line 941, in do_execute
    cursor.execute(statement, parameters)
  File "C:\Users\a046829713\Desktop\program\RLTrading\lib\site-packages\pymysql\cursors.py", line 153, in execute
    result = self._query(query)
  File "C:\Users\a046829713\Desktop\program\RLTrading\lib\site-packages\pymysql\cursors.py", line 322, in _query
    conn.query(q)
  File "C:\Users\a046829713\Desktop\program\RLTrading\lib\site-packages\pymysql\connections.py", line 563, in query
    self._affected_rows = self._read_query_result(unbuffered=unbuffered)
  File "C:\Users\a046829713\Desktop\program\RLTrading\lib\site-packages\pymysql\connections.py", line 825, in _read_query_result
    result.read()
  File "C:\Users\a046829713\Desktop\program\RLTrading\lib\site-packages\pymysql\connections.py", line 1199, in read
    first_packet = self.connection._read_packet()
  File "C:\Users\a046829713\Desktop\program\RLTrading\lib\site-packages\pymysql\connections.py", line 775, in _read_packet
    packet.raise_for_error()
  File "C:\Users\a046829713\Desktop\program\RLTrading\lib\site-packages\pymysql\protocol.py", line 219, in raise_for_error
    err.raise_mysql_exception(self._data)
  File "C:\Users\a046829713\Desktop\program\RLTrading\lib\site-packages\pymysql\err.py", line 150, in raise_mysql_exception
    raise errorclass(errno, errval)
pymysql.err.ProgrammingError: (1064, "You have an error in your SQL syntax; check the manual that corresponds to your MySQL server version for the right syntax to use near 'velodromeusdt-f-d' at line 1")

The above exception was the direct cause of the following exception:

Traceback (most recent call last):
  File "C:\Users\a046829713\Desktop\program\RLTrading\SynapseX\Database\SQL_operate.py", line 48, in read_Dateframe
    return pd.read_sql(text_msg, con=conn)
  File "C:\Users\a046829713\Desktop\program\RLTrading\lib\site-packages\pandas\io\sql.py", line 734, in read_sql
    return pandas_sql.read_query(
  File "C:\Users\a046829713\Desktop\program\RLTrading\lib\site-packages\pandas\io\sql.py", line 1836, in read_query
    result = self.execute(sql, params)
  File "C:\Users\a046829713\Desktop\program\RLTrading\lib\site-packages\pandas\io\sql.py", line 1659, in execute
    return self.con.exec_driver_sql(sql, *args)
  File "C:\Users\a046829713\Desktop\program\RLTrading\lib\site-packages\sqlalchemy\engine\base.py", line 1779, in exec_driver_sql
    ret = self._execute_context(
  File "C:\Users\a046829713\Desktop\program\RLTrading\lib\site-packages\sqlalchemy\engine\base.py", line 1846, in _execute_context
    return self._exec_single_context(
  File "C:\Users\a046829713\Desktop\program\RLTrading\lib\site-packages\sqlalchemy\engine\base.py", line 1986, in _exec_single_context
    self._handle_dbapi_exception(
  File "C:\Users\a046829713\Desktop\program\RLTrading\lib\site-packages\sqlalchemy\engine\base.py", line 2355, in _handle_dbapi_exception
    raise sqlalchemy_exception.with_traceback(exc_info[2]) from e
  File "C:\Users\a046829713\Desktop\program\RLTrading\lib\site-packages\sqlalchemy\engine\base.py", line 1967, in _exec_single_context
    self.dialect.do_execute(
  File "C:\Users\a046829713\Desktop\program\RLTrading\lib\site-packages\sqlalchemy\engine\default.py", line 941, in do_execute
    cursor.execute(statement, parameters)
  File "C:\Users\a046829713\Desktop\program\RLTrading\lib\site-packages\pymysql\cursors.py", line 153, in execute
    result = self._query(query)
  File "C:\Users\a046829713\Desktop\program\RLTrading\lib\site-packages\pymysql\cursors.py", line 322, in _query
    conn.query(q)
  File "C:\Users\a046829713\Desktop\program\RLTrading\lib\site-packages\pymysql\connections.py", line 563, in query
    self._affected_rows = self._read_query_result(unbuffered=unbuffered)
  File "C:\Users\a046829713\Desktop\program\RLTrading\lib\site-packages\pymysql\connections.py", line 825, in _read_query_result
    result.read()
  File "C:\Users\a046829713\Desktop\program\RLTrading\lib\site-packages\pymysql\connections.py", line 1199, in read
    first_packet = self.connection._read_packet()
  File "C:\Users\a046829713\Desktop\program\RLTrading\lib\site-packages\pymysql\connections.py", line 775, in _read_packet
    packet.raise_for_error()
  File "C:\Users\a046829713\Desktop\program\RLTrading\lib\site-packages\pymysql\protocol.py", line 219, in raise_for_error
    err.raise_mysql_exception(self._data)
  File "C:\Users\a046829713\Desktop\program\RLTrading\lib\site-packages\pymysql\err.py", line 150, in raise_mysql_exception
    raise errorclass(errno, errval)
sqlalchemy.exc.ProgrammingError: (pymysql.err.ProgrammingError) (1064, "You have an error in your SQL syntax; check the manual that corresponds to your MySQL server version for the right syntax to use near 'velodromeusdt-f-d' at line 1")
[SQL: velodromeusdt-f-d]
(Background on this error at: https://sqlalche.me/e/20/f405)

2024-12-21 11:55 ERROR Traceback (most recent call last):
  File "C:\Users\a046829713\Desktop\program\RLTrading\lib\site-packages\sqlalchemy\engine\base.py", line 1967, in _exec_single_context
    self.dialect.do_execute(
  File "C:\Users\a046829713\Desktop\program\RLTrading\lib\site-packages\sqlalchemy\engine\default.py", line 941, in do_execute
    cursor.execute(statement, parameters)
  File "C:\Users\a046829713\Desktop\program\RLTrading\lib\site-packages\pymysql\cursors.py", line 153, in execute
    result = self._query(query)
  File "C:\Users\a046829713\Desktop\program\RLTrading\lib\site-packages\pymysql\cursors.py", line 322, in _query
    conn.query(q)
  File "C:\Users\a046829713\Desktop\program\RLTrading\lib\site-packages\pymysql\connections.py", line 563, in query
    self._affected_rows = self._read_query_result(unbuffered=unbuffered)
  File "C:\Users\a046829713\Desktop\program\RLTrading\lib\site-packages\pymysql\connections.py", line 825, in _read_query_result
    result.read()
  File "C:\Users\a046829713\Desktop\program\RLTrading\lib\site-packages\pymysql\connections.py", line 1199, in read
    first_packet = self.connection._read_packet()
  File "C:\Users\a046829713\Desktop\program\RLTrading\lib\site-packages\pymysql\connections.py", line 775, in _read_packet
    packet.raise_for_error()
  File "C:\Users\a046829713\Desktop\program\RLTrading\lib\site-packages\pymysql\protocol.py", line 219, in raise_for_error
    err.raise_mysql_exception(self._data)
  File "C:\Users\a046829713\Desktop\program\RLTrading\lib\site-packages\pymysql\err.py", line 150, in raise_mysql_exception
    raise errorclass(errno, errval)
pymysql.err.ProgrammingError: (1064, "You have an error in your SQL syntax; check the manual that corresponds to your MySQL server version for the right syntax to use near 'mocausdt-f-d' at line 1")

The above exception was the direct cause of the following exception:

Traceback (most recent call last):
  File "C:\Users\a046829713\Desktop\program\RLTrading\SynapseX\Database\SQL_operate.py", line 48, in read_Dateframe
    return pd.read_sql(text_msg, con=conn)
  File "C:\Users\a046829713\Desktop\program\RLTrading\lib\site-packages\pandas\io\sql.py", line 734, in read_sql
    return pandas_sql.read_query(
  File "C:\Users\a046829713\Desktop\program\RLTrading\lib\site-packages\pandas\io\sql.py", line 1836, in read_query
    result = self.execute(sql, params)
  File "C:\Users\a046829713\Desktop\program\RLTrading\lib\site-packages\pandas\io\sql.py", line 1659, in execute
    return self.con.exec_driver_sql(sql, *args)
  File "C:\Users\a046829713\Desktop\program\RLTrading\lib\site-packages\sqlalchemy\engine\base.py", line 1779, in exec_driver_sql
    ret = self._execute_context(
  File "C:\Users\a046829713\Desktop\program\RLTrading\lib\site-packages\sqlalchemy\engine\base.py", line 1846, in _execute_context
    return self._exec_single_context(
  File "C:\Users\a046829713\Desktop\program\RLTrading\lib\site-packages\sqlalchemy\engine\base.py", line 1986, in _exec_single_context
    self._handle_dbapi_exception(
  File "C:\Users\a046829713\Desktop\program\RLTrading\lib\site-packages\sqlalchemy\engine\base.py", line 2355, in _handle_dbapi_exception
    raise sqlalchemy_exception.with_traceback(exc_info[2]) from e
  File "C:\Users\a046829713\Desktop\program\RLTrading\lib\site-packages\sqlalchemy\engine\base.py", line 1967, in _exec_single_context
    self.dialect.do_execute(
  File "C:\Users\a046829713\Desktop\program\RLTrading\lib\site-packages\sqlalchemy\engine\default.py", line 941, in do_execute
    cursor.execute(statement, parameters)
  File "C:\Users\a046829713\Desktop\program\RLTrading\lib\site-packages\pymysql\cursors.py", line 153, in execute
    result = self._query(query)
  File "C:\Users\a046829713\Desktop\program\RLTrading\lib\site-packages\pymysql\cursors.py", line 322, in _query
    conn.query(q)
  File "C:\Users\a046829713\Desktop\program\RLTrading\lib\site-packages\pymysql\connections.py", line 563, in query
    self._affected_rows = self._read_query_result(unbuffered=unbuffered)
  File "C:\Users\a046829713\Desktop\program\RLTrading\lib\site-packages\pymysql\connections.py", line 825, in _read_query_result
    result.read()
  File "C:\Users\a046829713\Desktop\program\RLTrading\lib\site-packages\pymysql\connections.py", line 1199, in read
    first_packet = self.connection._read_packet()
  File "C:\Users\a046829713\Desktop\program\RLTrading\lib\site-packages\pymysql\connections.py", line 775, in _read_packet
    packet.raise_for_error()
  File "C:\Users\a046829713\Desktop\program\RLTrading\lib\site-packages\pymysql\protocol.py", line 219, in raise_for_error
    err.raise_mysql_exception(self._data)
  File "C:\Users\a046829713\Desktop\program\RLTrading\lib\site-packages\pymysql\err.py", line 150, in raise_mysql_exception
    raise errorclass(errno, errval)
sqlalchemy.exc.ProgrammingError: (pymysql.err.ProgrammingError) (1064, "You have an error in your SQL syntax; check the manual that corresponds to your MySQL server version for the right syntax to use near 'mocausdt-f-d' at line 1")
[SQL: mocausdt-f-d]
(Background on this error at: https://sqlalche.me/e/20/f405)

2024-12-21 11:55 ERROR Traceback (most recent call last):
  File "C:\Users\a046829713\Desktop\program\RLTrading\lib\site-packages\sqlalchemy\engine\base.py", line 1967, in _exec_single_context
    self.dialect.do_execute(
  File "C:\Users\a046829713\Desktop\program\RLTrading\lib\site-packages\sqlalchemy\engine\default.py", line 941, in do_execute
    cursor.execute(statement, parameters)
  File "C:\Users\a046829713\Desktop\program\RLTrading\lib\site-packages\pymysql\cursors.py", line 153, in execute
    result = self._query(query)
  File "C:\Users\a046829713\Desktop\program\RLTrading\lib\site-packages\pymysql\cursors.py", line 322, in _query
    conn.query(q)
  File "C:\Users\a046829713\Desktop\program\RLTrading\lib\site-packages\pymysql\connections.py", line 563, in query
    self._affected_rows = self._read_query_result(unbuffered=unbuffered)
  File "C:\Users\a046829713\Desktop\program\RLTrading\lib\site-packages\pymysql\connections.py", line 825, in _read_query_result
    result.read()
  File "C:\Users\a046829713\Desktop\program\RLTrading\lib\site-packages\pymysql\connections.py", line 1199, in read
    first_packet = self.connection._read_packet()
  File "C:\Users\a046829713\Desktop\program\RLTrading\lib\site-packages\pymysql\connections.py", line 775, in _read_packet
    packet.raise_for_error()
  File "C:\Users\a046829713\Desktop\program\RLTrading\lib\site-packages\pymysql\protocol.py", line 219, in raise_for_error
    err.raise_mysql_exception(self._data)
  File "C:\Users\a046829713\Desktop\program\RLTrading\lib\site-packages\pymysql\err.py", line 150, in raise_mysql_exception
    raise errorclass(errno, errval)
pymysql.err.ProgrammingError: (1064, "You have an error in your SQL syntax; check the manual that corresponds to your MySQL server version for the right syntax to use near 'vanausdt-f-d' at line 1")

The above exception was the direct cause of the following exception:

Traceback (most recent call last):
  File "C:\Users\a046829713\Desktop\program\RLTrading\SynapseX\Database\SQL_operate.py", line 48, in read_Dateframe
    return pd.read_sql(text_msg, con=conn)
  File "C:\Users\a046829713\Desktop\program\RLTrading\lib\site-packages\pandas\io\sql.py", line 734, in read_sql
    return pandas_sql.read_query(
  File "C:\Users\a046829713\Desktop\program\RLTrading\lib\site-packages\pandas\io\sql.py", line 1836, in read_query
    result = self.execute(sql, params)
  File "C:\Users\a046829713\Desktop\program\RLTrading\lib\site-packages\pandas\io\sql.py", line 1659, in execute
    return self.con.exec_driver_sql(sql, *args)
  File "C:\Users\a046829713\Desktop\program\RLTrading\lib\site-packages\sqlalchemy\engine\base.py", line 1779, in exec_driver_sql
    ret = self._execute_context(
  File "C:\Users\a046829713\Desktop\program\RLTrading\lib\site-packages\sqlalchemy\engine\base.py", line 1846, in _execute_context
    return self._exec_single_context(
  File "C:\Users\a046829713\Desktop\program\RLTrading\lib\site-packages\sqlalchemy\engine\base.py", line 1986, in _exec_single_context
    self._handle_dbapi_exception(
  File "C:\Users\a046829713\Desktop\program\RLTrading\lib\site-packages\sqlalchemy\engine\base.py", line 2355, in _handle_dbapi_exception
    raise sqlalchemy_exception.with_traceback(exc_info[2]) from e
  File "C:\Users\a046829713\Desktop\program\RLTrading\lib\site-packages\sqlalchemy\engine\base.py", line 1967, in _exec_single_context
    self.dialect.do_execute(
  File "C:\Users\a046829713\Desktop\program\RLTrading\lib\site-packages\sqlalchemy\engine\default.py", line 941, in do_execute
    cursor.execute(statement, parameters)
  File "C:\Users\a046829713\Desktop\program\RLTrading\lib\site-packages\pymysql\cursors.py", line 153, in execute
    result = self._query(query)
  File "C:\Users\a046829713\Desktop\program\RLTrading\lib\site-packages\pymysql\cursors.py", line 322, in _query
    conn.query(q)
  File "C:\Users\a046829713\Desktop\program\RLTrading\lib\site-packages\pymysql\connections.py", line 563, in query
    self._affected_rows = self._read_query_result(unbuffered=unbuffered)
  File "C:\Users\a046829713\Desktop\program\RLTrading\lib\site-packages\pymysql\connections.py", line 825, in _read_query_result
    result.read()
  File "C:\Users\a046829713\Desktop\program\RLTrading\lib\site-packages\pymysql\connections.py", line 1199, in read
    first_packet = self.connection._read_packet()
  File "C:\Users\a046829713\Desktop\program\RLTrading\lib\site-packages\pymysql\connections.py", line 775, in _read_packet
    packet.raise_for_error()
  File "C:\Users\a046829713\Desktop\program\RLTrading\lib\site-packages\pymysql\protocol.py", line 219, in raise_for_error
    err.raise_mysql_exception(self._data)
  File "C:\Users\a046829713\Desktop\program\RLTrading\lib\site-packages\pymysql\err.py", line 150, in raise_mysql_exception
    raise errorclass(errno, errval)
sqlalchemy.exc.ProgrammingError: (pymysql.err.ProgrammingError) (1064, "You have an error in your SQL syntax; check the manual that corresponds to your MySQL server version for the right syntax to use near 'vanausdt-f-d' at line 1")
[SQL: vanausdt-f-d]
(Background on this error at: https://sqlalche.me/e/20/f405)

2024-12-21 11:55 ERROR Traceback (most recent call last):
  File "C:\Users\a046829713\Desktop\program\RLTrading\lib\site-packages\sqlalchemy\engine\base.py", line 1967, in _exec_single_context
    self.dialect.do_execute(
  File "C:\Users\a046829713\Desktop\program\RLTrading\lib\site-packages\sqlalchemy\engine\default.py", line 941, in do_execute
    cursor.execute(statement, parameters)
  File "C:\Users\a046829713\Desktop\program\RLTrading\lib\site-packages\pymysql\cursors.py", line 153, in execute
    result = self._query(query)
  File "C:\Users\a046829713\Desktop\program\RLTrading\lib\site-packages\pymysql\cursors.py", line 322, in _query
    conn.query(q)
  File "C:\Users\a046829713\Desktop\program\RLTrading\lib\site-packages\pymysql\connections.py", line 563, in query
    self._affected_rows = self._read_query_result(unbuffered=unbuffered)
  File "C:\Users\a046829713\Desktop\program\RLTrading\lib\site-packages\pymysql\connections.py", line 825, in _read_query_result
    result.read()
  File "C:\Users\a046829713\Desktop\program\RLTrading\lib\site-packages\pymysql\connections.py", line 1199, in read
    first_packet = self.connection._read_packet()
  File "C:\Users\a046829713\Desktop\program\RLTrading\lib\site-packages\pymysql\connections.py", line 775, in _read_packet
    packet.raise_for_error()
  File "C:\Users\a046829713\Desktop\program\RLTrading\lib\site-packages\pymysql\protocol.py", line 219, in raise_for_error
    err.raise_mysql_exception(self._data)
  File "C:\Users\a046829713\Desktop\program\RLTrading\lib\site-packages\pymysql\err.py", line 150, in raise_mysql_exception
    raise errorclass(errno, errval)
pymysql.err.ProgrammingError: (1064, "You have an error in your SQL syntax; check the manual that corresponds to your MySQL server version for the right syntax to use near 'penguusdt-f-d' at line 1")

The above exception was the direct cause of the following exception:

Traceback (most recent call last):
  File "C:\Users\a046829713\Desktop\program\RLTrading\SynapseX\Database\SQL_operate.py", line 48, in read_Dateframe
    return pd.read_sql(text_msg, con=conn)
  File "C:\Users\a046829713\Desktop\program\RLTrading\lib\site-packages\pandas\io\sql.py", line 734, in read_sql
    return pandas_sql.read_query(
  File "C:\Users\a046829713\Desktop\program\RLTrading\lib\site-packages\pandas\io\sql.py", line 1836, in read_query
    result = self.execute(sql, params)
  File "C:\Users\a046829713\Desktop\program\RLTrading\lib\site-packages\pandas\io\sql.py", line 1659, in execute
    return self.con.exec_driver_sql(sql, *args)
  File "C:\Users\a046829713\Desktop\program\RLTrading\lib\site-packages\sqlalchemy\engine\base.py", line 1779, in exec_driver_sql
    ret = self._execute_context(
  File "C:\Users\a046829713\Desktop\program\RLTrading\lib\site-packages\sqlalchemy\engine\base.py", line 1846, in _execute_context
    return self._exec_single_context(
  File "C:\Users\a046829713\Desktop\program\RLTrading\lib\site-packages\sqlalchemy\engine\base.py", line 1986, in _exec_single_context
    self._handle_dbapi_exception(
  File "C:\Users\a046829713\Desktop\program\RLTrading\lib\site-packages\sqlalchemy\engine\base.py", line 2355, in _handle_dbapi_exception
    raise sqlalchemy_exception.with_traceback(exc_info[2]) from e
  File "C:\Users\a046829713\Desktop\program\RLTrading\lib\site-packages\sqlalchemy\engine\base.py", line 1967, in _exec_single_context
    self.dialect.do_execute(
  File "C:\Users\a046829713\Desktop\program\RLTrading\lib\site-packages\sqlalchemy\engine\default.py", line 941, in do_execute
    cursor.execute(statement, parameters)
  File "C:\Users\a046829713\Desktop\program\RLTrading\lib\site-packages\pymysql\cursors.py", line 153, in execute
    result = self._query(query)
  File "C:\Users\a046829713\Desktop\program\RLTrading\lib\site-packages\pymysql\cursors.py", line 322, in _query
    conn.query(q)
  File "C:\Users\a046829713\Desktop\program\RLTrading\lib\site-packages\pymysql\connections.py", line 563, in query
    self._affected_rows = self._read_query_result(unbuffered=unbuffered)
  File "C:\Users\a046829713\Desktop\program\RLTrading\lib\site-packages\pymysql\connections.py", line 825, in _read_query_result
    result.read()
  File "C:\Users\a046829713\Desktop\program\RLTrading\lib\site-packages\pymysql\connections.py", line 1199, in read
    first_packet = self.connection._read_packet()
  File "C:\Users\a046829713\Desktop\program\RLTrading\lib\site-packages\pymysql\connections.py", line 775, in _read_packet
    packet.raise_for_error()
  File "C:\Users\a046829713\Desktop\program\RLTrading\lib\site-packages\pymysql\protocol.py", line 219, in raise_for_error
    err.raise_mysql_exception(self._data)
  File "C:\Users\a046829713\Desktop\program\RLTrading\lib\site-packages\pymysql\err.py", line 150, in raise_mysql_exception
    raise errorclass(errno, errval)
sqlalchemy.exc.ProgrammingError: (pymysql.err.ProgrammingError) (1064, "You have an error in your SQL syntax; check the manual that corresponds to your MySQL server version for the right syntax to use near 'penguusdt-f-d' at line 1")
[SQL: penguusdt-f-d]
(Background on this error at: https://sqlalche.me/e/20/f405)

2024-12-21 11:55 ERROR Traceback (most recent call last):
  File "C:\Users\a046829713\Desktop\program\RLTrading\lib\site-packages\sqlalchemy\engine\base.py", line 1967, in _exec_single_context
    self.dialect.do_execute(
  File "C:\Users\a046829713\Desktop\program\RLTrading\lib\site-packages\sqlalchemy\engine\default.py", line 941, in do_execute
    cursor.execute(statement, parameters)
  File "C:\Users\a046829713\Desktop\program\RLTrading\lib\site-packages\pymysql\cursors.py", line 153, in execute
    result = self._query(query)
  File "C:\Users\a046829713\Desktop\program\RLTrading\lib\site-packages\pymysql\cursors.py", line 322, in _query
    conn.query(q)
  File "C:\Users\a046829713\Desktop\program\RLTrading\lib\site-packages\pymysql\connections.py", line 563, in query
    self._affected_rows = self._read_query_result(unbuffered=unbuffered)
  File "C:\Users\a046829713\Desktop\program\RLTrading\lib\site-packages\pymysql\connections.py", line 825, in _read_query_result
    result.read()
  File "C:\Users\a046829713\Desktop\program\RLTrading\lib\site-packages\pymysql\connections.py", line 1199, in read
    first_packet = self.connection._read_packet()
  File "C:\Users\a046829713\Desktop\program\RLTrading\lib\site-packages\pymysql\connections.py", line 775, in _read_packet
    packet.raise_for_error()
  File "C:\Users\a046829713\Desktop\program\RLTrading\lib\site-packages\pymysql\protocol.py", line 219, in raise_for_error
    err.raise_mysql_exception(self._data)
  File "C:\Users\a046829713\Desktop\program\RLTrading\lib\site-packages\pymysql\err.py", line 150, in raise_mysql_exception
    raise errorclass(errno, errval)
pymysql.err.ProgrammingError: (1064, "You have an error in your SQL syntax; check the manual that corresponds to your MySQL server version for the right syntax to use near 'lumiausdt-f-d' at line 1")

The above exception was the direct cause of the following exception:

Traceback (most recent call last):
  File "C:\Users\a046829713\Desktop\program\RLTrading\SynapseX\Database\SQL_operate.py", line 48, in read_Dateframe
    return pd.read_sql(text_msg, con=conn)
  File "C:\Users\a046829713\Desktop\program\RLTrading\lib\site-packages\pandas\io\sql.py", line 734, in read_sql
    return pandas_sql.read_query(
  File "C:\Users\a046829713\Desktop\program\RLTrading\lib\site-packages\pandas\io\sql.py", line 1836, in read_query
    result = self.execute(sql, params)
  File "C:\Users\a046829713\Desktop\program\RLTrading\lib\site-packages\pandas\io\sql.py", line 1659, in execute
    return self.con.exec_driver_sql(sql, *args)
  File "C:\Users\a046829713\Desktop\program\RLTrading\lib\site-packages\sqlalchemy\engine\base.py", line 1779, in exec_driver_sql
    ret = self._execute_context(
  File "C:\Users\a046829713\Desktop\program\RLTrading\lib\site-packages\sqlalchemy\engine\base.py", line 1846, in _execute_context
    return self._exec_single_context(
  File "C:\Users\a046829713\Desktop\program\RLTrading\lib\site-packages\sqlalchemy\engine\base.py", line 1986, in _exec_single_context
    self._handle_dbapi_exception(
  File "C:\Users\a046829713\Desktop\program\RLTrading\lib\site-packages\sqlalchemy\engine\base.py", line 2355, in _handle_dbapi_exception
    raise sqlalchemy_exception.with_traceback(exc_info[2]) from e
  File "C:\Users\a046829713\Desktop\program\RLTrading\lib\site-packages\sqlalchemy\engine\base.py", line 1967, in _exec_single_context
    self.dialect.do_execute(
  File "C:\Users\a046829713\Desktop\program\RLTrading\lib\site-packages\sqlalchemy\engine\default.py", line 941, in do_execute
    cursor.execute(statement, parameters)
  File "C:\Users\a046829713\Desktop\program\RLTrading\lib\site-packages\pymysql\cursors.py", line 153, in execute
    result = self._query(query)
  File "C:\Users\a046829713\Desktop\program\RLTrading\lib\site-packages\pymysql\cursors.py", line 322, in _query
    conn.query(q)
  File "C:\Users\a046829713\Desktop\program\RLTrading\lib\site-packages\pymysql\connections.py", line 563, in query
    self._affected_rows = self._read_query_result(unbuffered=unbuffered)
  File "C:\Users\a046829713\Desktop\program\RLTrading\lib\site-packages\pymysql\connections.py", line 825, in _read_query_result
    result.read()
  File "C:\Users\a046829713\Desktop\program\RLTrading\lib\site-packages\pymysql\connections.py", line 1199, in read
    first_packet = self.connection._read_packet()
  File "C:\Users\a046829713\Desktop\program\RLTrading\lib\site-packages\pymysql\connections.py", line 775, in _read_packet
    packet.raise_for_error()
  File "C:\Users\a046829713\Desktop\program\RLTrading\lib\site-packages\pymysql\protocol.py", line 219, in raise_for_error
    err.raise_mysql_exception(self._data)
  File "C:\Users\a046829713\Desktop\program\RLTrading\lib\site-packages\pymysql\err.py", line 150, in raise_mysql_exception
    raise errorclass(errno, errval)
sqlalchemy.exc.ProgrammingError: (pymysql.err.ProgrammingError) (1064, "You have an error in your SQL syntax; check the manual that corresponds to your MySQL server version for the right syntax to use near 'lumiausdt-f-d' at line 1")
[SQL: lumiausdt-f-d]
(Background on this error at: https://sqlalche.me/e/20/f405)

2024-12-21 11:55 ERROR Traceback (most recent call last):
  File "C:\Users\a046829713\Desktop\program\RLTrading\lib\site-packages\sqlalchemy\engine\base.py", line 1967, in _exec_single_context
    self.dialect.do_execute(
  File "C:\Users\a046829713\Desktop\program\RLTrading\lib\site-packages\sqlalchemy\engine\default.py", line 941, in do_execute
    cursor.execute(statement, parameters)
  File "C:\Users\a046829713\Desktop\program\RLTrading\lib\site-packages\pymysql\cursors.py", line 153, in execute
    result = self._query(query)
  File "C:\Users\a046829713\Desktop\program\RLTrading\lib\site-packages\pymysql\cursors.py", line 322, in _query
    conn.query(q)
  File "C:\Users\a046829713\Desktop\program\RLTrading\lib\site-packages\pymysql\connections.py", line 563, in query
    self._affected_rows = self._read_query_result(unbuffered=unbuffered)
  File "C:\Users\a046829713\Desktop\program\RLTrading\lib\site-packages\pymysql\connections.py", line 825, in _read_query_result
    result.read()
  File "C:\Users\a046829713\Desktop\program\RLTrading\lib\site-packages\pymysql\connections.py", line 1199, in read
    first_packet = self.connection._read_packet()
  File "C:\Users\a046829713\Desktop\program\RLTrading\lib\site-packages\pymysql\connections.py", line 775, in _read_packet
    packet.raise_for_error()
  File "C:\Users\a046829713\Desktop\program\RLTrading\lib\site-packages\pymysql\protocol.py", line 219, in raise_for_error
    err.raise_mysql_exception(self._data)
  File "C:\Users\a046829713\Desktop\program\RLTrading\lib\site-packages\pymysql\err.py", line 150, in raise_mysql_exception
    raise errorclass(errno, errval)
pymysql.err.ProgrammingError: (1064, "You have an error in your SQL syntax; check the manual that corresponds to your MySQL server version for the right syntax to use near 'usualusdt-f-d' at line 1")

The above exception was the direct cause of the following exception:

Traceback (most recent call last):
  File "C:\Users\a046829713\Desktop\program\RLTrading\SynapseX\Database\SQL_operate.py", line 48, in read_Dateframe
    return pd.read_sql(text_msg, con=conn)
  File "C:\Users\a046829713\Desktop\program\RLTrading\lib\site-packages\pandas\io\sql.py", line 734, in read_sql
    return pandas_sql.read_query(
  File "C:\Users\a046829713\Desktop\program\RLTrading\lib\site-packages\pandas\io\sql.py", line 1836, in read_query
    result = self.execute(sql, params)
  File "C:\Users\a046829713\Desktop\program\RLTrading\lib\site-packages\pandas\io\sql.py", line 1659, in execute
    return self.con.exec_driver_sql(sql, *args)
  File "C:\Users\a046829713\Desktop\program\RLTrading\lib\site-packages\sqlalchemy\engine\base.py", line 1779, in exec_driver_sql
    ret = self._execute_context(
  File "C:\Users\a046829713\Desktop\program\RLTrading\lib\site-packages\sqlalchemy\engine\base.py", line 1846, in _execute_context
    return self._exec_single_context(
  File "C:\Users\a046829713\Desktop\program\RLTrading\lib\site-packages\sqlalchemy\engine\base.py", line 1986, in _exec_single_context
    self._handle_dbapi_exception(
  File "C:\Users\a046829713\Desktop\program\RLTrading\lib\site-packages\sqlalchemy\engine\base.py", line 2355, in _handle_dbapi_exception
    raise sqlalchemy_exception.with_traceback(exc_info[2]) from e
  File "C:\Users\a046829713\Desktop\program\RLTrading\lib\site-packages\sqlalchemy\engine\base.py", line 1967, in _exec_single_context
    self.dialect.do_execute(
  File "C:\Users\a046829713\Desktop\program\RLTrading\lib\site-packages\sqlalchemy\engine\default.py", line 941, in do_execute
    cursor.execute(statement, parameters)
  File "C:\Users\a046829713\Desktop\program\RLTrading\lib\site-packages\pymysql\cursors.py", line 153, in execute
    result = self._query(query)
  File "C:\Users\a046829713\Desktop\program\RLTrading\lib\site-packages\pymysql\cursors.py", line 322, in _query
    conn.query(q)
  File "C:\Users\a046829713\Desktop\program\RLTrading\lib\site-packages\pymysql\connections.py", line 563, in query
    self._affected_rows = self._read_query_result(unbuffered=unbuffered)
  File "C:\Users\a046829713\Desktop\program\RLTrading\lib\site-packages\pymysql\connections.py", line 825, in _read_query_result
    result.read()
  File "C:\Users\a046829713\Desktop\program\RLTrading\lib\site-packages\pymysql\connections.py", line 1199, in read
    first_packet = self.connection._read_packet()
  File "C:\Users\a046829713\Desktop\program\RLTrading\lib\site-packages\pymysql\connections.py", line 775, in _read_packet
    packet.raise_for_error()
  File "C:\Users\a046829713\Desktop\program\RLTrading\lib\site-packages\pymysql\protocol.py", line 219, in raise_for_error
    err.raise_mysql_exception(self._data)
  File "C:\Users\a046829713\Desktop\program\RLTrading\lib\site-packages\pymysql\err.py", line 150, in raise_mysql_exception
    raise errorclass(errno, errval)
sqlalchemy.exc.ProgrammingError: (pymysql.err.ProgrammingError) (1064, "You have an error in your SQL syntax; check the manual that corresponds to your MySQL server version for the right syntax to use near 'usualusdt-f-d' at line 1")
[SQL: usualusdt-f-d]
(Background on this error at: https://sqlalche.me/e/20/f405)

2024-12-21 11:55 ERROR Traceback (most recent call last):
  File "C:\Users\a046829713\Desktop\program\RLTrading\lib\site-packages\sqlalchemy\engine\base.py", line 1967, in _exec_single_context
    self.dialect.do_execute(
  File "C:\Users\a046829713\Desktop\program\RLTrading\lib\site-packages\sqlalchemy\engine\default.py", line 941, in do_execute
    cursor.execute(statement, parameters)
  File "C:\Users\a046829713\Desktop\program\RLTrading\lib\site-packages\pymysql\cursors.py", line 153, in execute
    result = self._query(query)
  File "C:\Users\a046829713\Desktop\program\RLTrading\lib\site-packages\pymysql\cursors.py", line 322, in _query
    conn.query(q)
  File "C:\Users\a046829713\Desktop\program\RLTrading\lib\site-packages\pymysql\connections.py", line 563, in query
    self._affected_rows = self._read_query_result(unbuffered=unbuffered)
  File "C:\Users\a046829713\Desktop\program\RLTrading\lib\site-packages\pymysql\connections.py", line 825, in _read_query_result
    result.read()
  File "C:\Users\a046829713\Desktop\program\RLTrading\lib\site-packages\pymysql\connections.py", line 1199, in read
    first_packet = self.connection._read_packet()
  File "C:\Users\a046829713\Desktop\program\RLTrading\lib\site-packages\pymysql\connections.py", line 775, in _read_packet
    packet.raise_for_error()
  File "C:\Users\a046829713\Desktop\program\RLTrading\lib\site-packages\pymysql\protocol.py", line 219, in raise_for_error
    err.raise_mysql_exception(self._data)
  File "C:\Users\a046829713\Desktop\program\RLTrading\lib\site-packages\pymysql\err.py", line 150, in raise_mysql_exception
    raise errorclass(errno, errval)
pymysql.err.ProgrammingError: (1064, "You have an error in your SQL syntax; check the manual that corresponds to your MySQL server version for the right syntax to use near 'aixbtusdt-f-d' at line 1")

The above exception was the direct cause of the following exception:

Traceback (most recent call last):
  File "C:\Users\a046829713\Desktop\program\RLTrading\SynapseX\Database\SQL_operate.py", line 48, in read_Dateframe
    return pd.read_sql(text_msg, con=conn)
  File "C:\Users\a046829713\Desktop\program\RLTrading\lib\site-packages\pandas\io\sql.py", line 734, in read_sql
    return pandas_sql.read_query(
  File "C:\Users\a046829713\Desktop\program\RLTrading\lib\site-packages\pandas\io\sql.py", line 1836, in read_query
    result = self.execute(sql, params)
  File "C:\Users\a046829713\Desktop\program\RLTrading\lib\site-packages\pandas\io\sql.py", line 1659, in execute
    return self.con.exec_driver_sql(sql, *args)
  File "C:\Users\a046829713\Desktop\program\RLTrading\lib\site-packages\sqlalchemy\engine\base.py", line 1779, in exec_driver_sql
    ret = self._execute_context(
  File "C:\Users\a046829713\Desktop\program\RLTrading\lib\site-packages\sqlalchemy\engine\base.py", line 1846, in _execute_context
    return self._exec_single_context(
  File "C:\Users\a046829713\Desktop\program\RLTrading\lib\site-packages\sqlalchemy\engine\base.py", line 1986, in _exec_single_context
    self._handle_dbapi_exception(
  File "C:\Users\a046829713\Desktop\program\RLTrading\lib\site-packages\sqlalchemy\engine\base.py", line 2355, in _handle_dbapi_exception
    raise sqlalchemy_exception.with_traceback(exc_info[2]) from e
  File "C:\Users\a046829713\Desktop\program\RLTrading\lib\site-packages\sqlalchemy\engine\base.py", line 1967, in _exec_single_context
    self.dialect.do_execute(
  File "C:\Users\a046829713\Desktop\program\RLTrading\lib\site-packages\sqlalchemy\engine\default.py", line 941, in do_execute
    cursor.execute(statement, parameters)
  File "C:\Users\a046829713\Desktop\program\RLTrading\lib\site-packages\pymysql\cursors.py", line 153, in execute
    result = self._query(query)
  File "C:\Users\a046829713\Desktop\program\RLTrading\lib\site-packages\pymysql\cursors.py", line 322, in _query
    conn.query(q)
  File "C:\Users\a046829713\Desktop\program\RLTrading\lib\site-packages\pymysql\connections.py", line 563, in query
    self._affected_rows = self._read_query_result(unbuffered=unbuffered)
  File "C:\Users\a046829713\Desktop\program\RLTrading\lib\site-packages\pymysql\connections.py", line 825, in _read_query_result
    result.read()
  File "C:\Users\a046829713\Desktop\program\RLTrading\lib\site-packages\pymysql\connections.py", line 1199, in read
    first_packet = self.connection._read_packet()
  File "C:\Users\a046829713\Desktop\program\RLTrading\lib\site-packages\pymysql\connections.py", line 775, in _read_packet
    packet.raise_for_error()
  File "C:\Users\a046829713\Desktop\program\RLTrading\lib\site-packages\pymysql\protocol.py", line 219, in raise_for_error
    err.raise_mysql_exception(self._data)
  File "C:\Users\a046829713\Desktop\program\RLTrading\lib\site-packages\pymysql\err.py", line 150, in raise_mysql_exception
    raise errorclass(errno, errval)
sqlalchemy.exc.ProgrammingError: (pymysql.err.ProgrammingError) (1064, "You have an error in your SQL syntax; check the manual that corresponds to your MySQL server version for the right syntax to use near 'aixbtusdt-f-d' at line 1")
[SQL: aixbtusdt-f-d]
(Background on this error at: https://sqlalche.me/e/20/f405)

2024-12-21 11:55 ERROR Traceback (most recent call last):
  File "C:\Users\a046829713\Desktop\program\RLTrading\lib\site-packages\sqlalchemy\engine\base.py", line 1967, in _exec_single_context
    self.dialect.do_execute(
  File "C:\Users\a046829713\Desktop\program\RLTrading\lib\site-packages\sqlalchemy\engine\default.py", line 941, in do_execute
    cursor.execute(statement, parameters)
  File "C:\Users\a046829713\Desktop\program\RLTrading\lib\site-packages\pymysql\cursors.py", line 153, in execute
    result = self._query(query)
  File "C:\Users\a046829713\Desktop\program\RLTrading\lib\site-packages\pymysql\cursors.py", line 322, in _query
    conn.query(q)
  File "C:\Users\a046829713\Desktop\program\RLTrading\lib\site-packages\pymysql\connections.py", line 563, in query
    self._affected_rows = self._read_query_result(unbuffered=unbuffered)
  File "C:\Users\a046829713\Desktop\program\RLTrading\lib\site-packages\pymysql\connections.py", line 825, in _read_query_result
    result.read()
  File "C:\Users\a046829713\Desktop\program\RLTrading\lib\site-packages\pymysql\connections.py", line 1199, in read
    first_packet = self.connection._read_packet()
  File "C:\Users\a046829713\Desktop\program\RLTrading\lib\site-packages\pymysql\connections.py", line 775, in _read_packet
    packet.raise_for_error()
  File "C:\Users\a046829713\Desktop\program\RLTrading\lib\site-packages\pymysql\protocol.py", line 219, in raise_for_error
    err.raise_mysql_exception(self._data)
  File "C:\Users\a046829713\Desktop\program\RLTrading\lib\site-packages\pymysql\err.py", line 150, in raise_mysql_exception
    raise errorclass(errno, errval)
pymysql.err.ProgrammingError: (1064, "You have an error in your SQL syntax; check the manual that corresponds to your MySQL server version for the right syntax to use near 'fartcoinusdt-f-d' at line 1")

The above exception was the direct cause of the following exception:

Traceback (most recent call last):
  File "C:\Users\a046829713\Desktop\program\RLTrading\SynapseX\Database\SQL_operate.py", line 48, in read_Dateframe
    return pd.read_sql(text_msg, con=conn)
  File "C:\Users\a046829713\Desktop\program\RLTrading\lib\site-packages\pandas\io\sql.py", line 734, in read_sql
    return pandas_sql.read_query(
  File "C:\Users\a046829713\Desktop\program\RLTrading\lib\site-packages\pandas\io\sql.py", line 1836, in read_query
    result = self.execute(sql, params)
  File "C:\Users\a046829713\Desktop\program\RLTrading\lib\site-packages\pandas\io\sql.py", line 1659, in execute
    return self.con.exec_driver_sql(sql, *args)
  File "C:\Users\a046829713\Desktop\program\RLTrading\lib\site-packages\sqlalchemy\engine\base.py", line 1779, in exec_driver_sql
    ret = self._execute_context(
  File "C:\Users\a046829713\Desktop\program\RLTrading\lib\site-packages\sqlalchemy\engine\base.py", line 1846, in _execute_context
    return self._exec_single_context(
  File "C:\Users\a046829713\Desktop\program\RLTrading\lib\site-packages\sqlalchemy\engine\base.py", line 1986, in _exec_single_context
    self._handle_dbapi_exception(
  File "C:\Users\a046829713\Desktop\program\RLTrading\lib\site-packages\sqlalchemy\engine\base.py", line 2355, in _handle_dbapi_exception
    raise sqlalchemy_exception.with_traceback(exc_info[2]) from e
  File "C:\Users\a046829713\Desktop\program\RLTrading\lib\site-packages\sqlalchemy\engine\base.py", line 1967, in _exec_single_context
    self.dialect.do_execute(
  File "C:\Users\a046829713\Desktop\program\RLTrading\lib\site-packages\sqlalchemy\engine\default.py", line 941, in do_execute
    cursor.execute(statement, parameters)
  File "C:\Users\a046829713\Desktop\program\RLTrading\lib\site-packages\pymysql\cursors.py", line 153, in execute
    result = self._query(query)
  File "C:\Users\a046829713\Desktop\program\RLTrading\lib\site-packages\pymysql\cursors.py", line 322, in _query
    conn.query(q)
  File "C:\Users\a046829713\Desktop\program\RLTrading\lib\site-packages\pymysql\connections.py", line 563, in query
    self._affected_rows = self._read_query_result(unbuffered=unbuffered)
  File "C:\Users\a046829713\Desktop\program\RLTrading\lib\site-packages\pymysql\connections.py", line 825, in _read_query_result
    result.read()
  File "C:\Users\a046829713\Desktop\program\RLTrading\lib\site-packages\pymysql\connections.py", line 1199, in read
    first_packet = self.connection._read_packet()
  File "C:\Users\a046829713\Desktop\program\RLTrading\lib\site-packages\pymysql\connections.py", line 775, in _read_packet
    packet.raise_for_error()
  File "C:\Users\a046829713\Desktop\program\RLTrading\lib\site-packages\pymysql\protocol.py", line 219, in raise_for_error
    err.raise_mysql_exception(self._data)
  File "C:\Users\a046829713\Desktop\program\RLTrading\lib\site-packages\pymysql\err.py", line 150, in raise_mysql_exception
    raise errorclass(errno, errval)
sqlalchemy.exc.ProgrammingError: (pymysql.err.ProgrammingError) (1064, "You have an error in your SQL syntax; check the manual that corresponds to your MySQL server version for the right syntax to use near 'fartcoinusdt-f-d' at line 1")
[SQL: fartcoinusdt-f-d]
(Background on this error at: https://sqlalche.me/e/20/f405)

2024-12-21 11:55 ERROR Traceback (most recent call last):
  File "C:\Users\a046829713\Desktop\program\RLTrading\lib\site-packages\sqlalchemy\engine\base.py", line 1967, in _exec_single_context
    self.dialect.do_execute(
  File "C:\Users\a046829713\Desktop\program\RLTrading\lib\site-packages\sqlalchemy\engine\default.py", line 941, in do_execute
    cursor.execute(statement, parameters)
  File "C:\Users\a046829713\Desktop\program\RLTrading\lib\site-packages\pymysql\cursors.py", line 153, in execute
    result = self._query(query)
  File "C:\Users\a046829713\Desktop\program\RLTrading\lib\site-packages\pymysql\cursors.py", line 322, in _query
    conn.query(q)
  File "C:\Users\a046829713\Desktop\program\RLTrading\lib\site-packages\pymysql\connections.py", line 563, in query
    self._affected_rows = self._read_query_result(unbuffered=unbuffered)
  File "C:\Users\a046829713\Desktop\program\RLTrading\lib\site-packages\pymysql\connections.py", line 825, in _read_query_result
    result.read()
  File "C:\Users\a046829713\Desktop\program\RLTrading\lib\site-packages\pymysql\connections.py", line 1199, in read
    first_packet = self.connection._read_packet()
  File "C:\Users\a046829713\Desktop\program\RLTrading\lib\site-packages\pymysql\connections.py", line 775, in _read_packet
    packet.raise_for_error()
  File "C:\Users\a046829713\Desktop\program\RLTrading\lib\site-packages\pymysql\protocol.py", line 219, in raise_for_error
    err.raise_mysql_exception(self._data)
  File "C:\Users\a046829713\Desktop\program\RLTrading\lib\site-packages\pymysql\err.py", line 150, in raise_mysql_exception
    raise errorclass(errno, errval)
pymysql.err.ProgrammingError: (1064, "You have an error in your SQL syntax; check the manual that corresponds to your MySQL server version for the right syntax to use near 'kmnousdt-f-d' at line 1")

The above exception was the direct cause of the following exception:

Traceback (most recent call last):
  File "C:\Users\a046829713\Desktop\program\RLTrading\SynapseX\Database\SQL_operate.py", line 48, in read_Dateframe
    return pd.read_sql(text_msg, con=conn)
  File "C:\Users\a046829713\Desktop\program\RLTrading\lib\site-packages\pandas\io\sql.py", line 734, in read_sql
    return pandas_sql.read_query(
  File "C:\Users\a046829713\Desktop\program\RLTrading\lib\site-packages\pandas\io\sql.py", line 1836, in read_query
    result = self.execute(sql, params)
  File "C:\Users\a046829713\Desktop\program\RLTrading\lib\site-packages\pandas\io\sql.py", line 1659, in execute
    return self.con.exec_driver_sql(sql, *args)
  File "C:\Users\a046829713\Desktop\program\RLTrading\lib\site-packages\sqlalchemy\engine\base.py", line 1779, in exec_driver_sql
    ret = self._execute_context(
  File "C:\Users\a046829713\Desktop\program\RLTrading\lib\site-packages\sqlalchemy\engine\base.py", line 1846, in _execute_context
    return self._exec_single_context(
  File "C:\Users\a046829713\Desktop\program\RLTrading\lib\site-packages\sqlalchemy\engine\base.py", line 1986, in _exec_single_context
    self._handle_dbapi_exception(
  File "C:\Users\a046829713\Desktop\program\RLTrading\lib\site-packages\sqlalchemy\engine\base.py", line 2355, in _handle_dbapi_exception
    raise sqlalchemy_exception.with_traceback(exc_info[2]) from e
  File "C:\Users\a046829713\Desktop\program\RLTrading\lib\site-packages\sqlalchemy\engine\base.py", line 1967, in _exec_single_context
    self.dialect.do_execute(
  File "C:\Users\a046829713\Desktop\program\RLTrading\lib\site-packages\sqlalchemy\engine\default.py", line 941, in do_execute
    cursor.execute(statement, parameters)
  File "C:\Users\a046829713\Desktop\program\RLTrading\lib\site-packages\pymysql\cursors.py", line 153, in execute
    result = self._query(query)
  File "C:\Users\a046829713\Desktop\program\RLTrading\lib\site-packages\pymysql\cursors.py", line 322, in _query
    conn.query(q)
  File "C:\Users\a046829713\Desktop\program\RLTrading\lib\site-packages\pymysql\connections.py", line 563, in query
    self._affected_rows = self._read_query_result(unbuffered=unbuffered)
  File "C:\Users\a046829713\Desktop\program\RLTrading\lib\site-packages\pymysql\connections.py", line 825, in _read_query_result
    result.read()
  File "C:\Users\a046829713\Desktop\program\RLTrading\lib\site-packages\pymysql\connections.py", line 1199, in read
    first_packet = self.connection._read_packet()
  File "C:\Users\a046829713\Desktop\program\RLTrading\lib\site-packages\pymysql\connections.py", line 775, in _read_packet
    packet.raise_for_error()
  File "C:\Users\a046829713\Desktop\program\RLTrading\lib\site-packages\pymysql\protocol.py", line 219, in raise_for_error
    err.raise_mysql_exception(self._data)
  File "C:\Users\a046829713\Desktop\program\RLTrading\lib\site-packages\pymysql\err.py", line 150, in raise_mysql_exception
    raise errorclass(errno, errval)
sqlalchemy.exc.ProgrammingError: (pymysql.err.ProgrammingError) (1064, "You have an error in your SQL syntax; check the manual that corresponds to your MySQL server version for the right syntax to use near 'kmnousdt-f-d' at line 1")
[SQL: kmnousdt-f-d]
(Background on this error at: https://sqlalche.me/e/20/f405)

2024-12-21 11:55 ERROR Traceback (most recent call last):
  File "C:\Users\a046829713\Desktop\program\RLTrading\lib\site-packages\sqlalchemy\engine\base.py", line 1967, in _exec_single_context
    self.dialect.do_execute(
  File "C:\Users\a046829713\Desktop\program\RLTrading\lib\site-packages\sqlalchemy\engine\default.py", line 941, in do_execute
    cursor.execute(statement, parameters)
  File "C:\Users\a046829713\Desktop\program\RLTrading\lib\site-packages\pymysql\cursors.py", line 153, in execute
    result = self._query(query)
  File "C:\Users\a046829713\Desktop\program\RLTrading\lib\site-packages\pymysql\cursors.py", line 322, in _query
    conn.query(q)
  File "C:\Users\a046829713\Desktop\program\RLTrading\lib\site-packages\pymysql\connections.py", line 563, in query
    self._affected_rows = self._read_query_result(unbuffered=unbuffered)
  File "C:\Users\a046829713\Desktop\program\RLTrading\lib\site-packages\pymysql\connections.py", line 825, in _read_query_result
    result.read()
  File "C:\Users\a046829713\Desktop\program\RLTrading\lib\site-packages\pymysql\connections.py", line 1199, in read
    first_packet = self.connection._read_packet()
  File "C:\Users\a046829713\Desktop\program\RLTrading\lib\site-packages\pymysql\connections.py", line 775, in _read_packet
    packet.raise_for_error()
  File "C:\Users\a046829713\Desktop\program\RLTrading\lib\site-packages\pymysql\protocol.py", line 219, in raise_for_error
    err.raise_mysql_exception(self._data)
  File "C:\Users\a046829713\Desktop\program\RLTrading\lib\site-packages\pymysql\err.py", line 150, in raise_mysql_exception
    raise errorclass(errno, errval)
pymysql.err.ProgrammingError: (1064, "You have an error in your SQL syntax; check the manual that corresponds to your MySQL server version for the right syntax to use near 'cgptusdt-f-d' at line 1")

The above exception was the direct cause of the following exception:

Traceback (most recent call last):
  File "C:\Users\a046829713\Desktop\program\RLTrading\SynapseX\Database\SQL_operate.py", line 48, in read_Dateframe
    return pd.read_sql(text_msg, con=conn)
  File "C:\Users\a046829713\Desktop\program\RLTrading\lib\site-packages\pandas\io\sql.py", line 734, in read_sql
    return pandas_sql.read_query(
  File "C:\Users\a046829713\Desktop\program\RLTrading\lib\site-packages\pandas\io\sql.py", line 1836, in read_query
    result = self.execute(sql, params)
  File "C:\Users\a046829713\Desktop\program\RLTrading\lib\site-packages\pandas\io\sql.py", line 1659, in execute
    return self.con.exec_driver_sql(sql, *args)
  File "C:\Users\a046829713\Desktop\program\RLTrading\lib\site-packages\sqlalchemy\engine\base.py", line 1779, in exec_driver_sql
    ret = self._execute_context(
  File "C:\Users\a046829713\Desktop\program\RLTrading\lib\site-packages\sqlalchemy\engine\base.py", line 1846, in _execute_context
    return self._exec_single_context(
  File "C:\Users\a046829713\Desktop\program\RLTrading\lib\site-packages\sqlalchemy\engine\base.py", line 1986, in _exec_single_context
    self._handle_dbapi_exception(
  File "C:\Users\a046829713\Desktop\program\RLTrading\lib\site-packages\sqlalchemy\engine\base.py", line 2355, in _handle_dbapi_exception
    raise sqlalchemy_exception.with_traceback(exc_info[2]) from e
  File "C:\Users\a046829713\Desktop\program\RLTrading\lib\site-packages\sqlalchemy\engine\base.py", line 1967, in _exec_single_context
    self.dialect.do_execute(
  File "C:\Users\a046829713\Desktop\program\RLTrading\lib\site-packages\sqlalchemy\engine\default.py", line 941, in do_execute
    cursor.execute(statement, parameters)
  File "C:\Users\a046829713\Desktop\program\RLTrading\lib\site-packages\pymysql\cursors.py", line 153, in execute
    result = self._query(query)
  File "C:\Users\a046829713\Desktop\program\RLTrading\lib\site-packages\pymysql\cursors.py", line 322, in _query
    conn.query(q)
  File "C:\Users\a046829713\Desktop\program\RLTrading\lib\site-packages\pymysql\connections.py", line 563, in query
    self._affected_rows = self._read_query_result(unbuffered=unbuffered)
  File "C:\Users\a046829713\Desktop\program\RLTrading\lib\site-packages\pymysql\connections.py", line 825, in _read_query_result
    result.read()
  File "C:\Users\a046829713\Desktop\program\RLTrading\lib\site-packages\pymysql\connections.py", line 1199, in read
    first_packet = self.connection._read_packet()
  File "C:\Users\a046829713\Desktop\program\RLTrading\lib\site-packages\pymysql\connections.py", line 775, in _read_packet
    packet.raise_for_error()
  File "C:\Users\a046829713\Desktop\program\RLTrading\lib\site-packages\pymysql\protocol.py", line 219, in raise_for_error
    err.raise_mysql_exception(self._data)
  File "C:\Users\a046829713\Desktop\program\RLTrading\lib\site-packages\pymysql\err.py", line 150, in raise_mysql_exception
    raise errorclass(errno, errval)
sqlalchemy.exc.ProgrammingError: (pymysql.err.ProgrammingError) (1064, "You have an error in your SQL syntax; check the manual that corresponds to your MySQL server version for the right syntax to use near 'cgptusdt-f-d' at line 1")
[SQL: cgptusdt-f-d]
(Background on this error at: https://sqlalche.me/e/20/f405)

2024-12-21 11:57 ERROR Traceback (most recent call last):
  File "C:\Users\a046829713\Desktop\program\RLTrading\lib\site-packages\sqlalchemy\engine\base.py", line 1967, in _exec_single_context
    self.dialect.do_execute(
  File "C:\Users\a046829713\Desktop\program\RLTrading\lib\site-packages\sqlalchemy\engine\default.py", line 941, in do_execute
    cursor.execute(statement, parameters)
  File "C:\Users\a046829713\Desktop\program\RLTrading\lib\site-packages\pymysql\cursors.py", line 153, in execute
    result = self._query(query)
  File "C:\Users\a046829713\Desktop\program\RLTrading\lib\site-packages\pymysql\cursors.py", line 322, in _query
    conn.query(q)
  File "C:\Users\a046829713\Desktop\program\RLTrading\lib\site-packages\pymysql\connections.py", line 563, in query
    self._affected_rows = self._read_query_result(unbuffered=unbuffered)
  File "C:\Users\a046829713\Desktop\program\RLTrading\lib\site-packages\pymysql\connections.py", line 825, in _read_query_result
    result.read()
  File "C:\Users\a046829713\Desktop\program\RLTrading\lib\site-packages\pymysql\connections.py", line 1199, in read
    first_packet = self.connection._read_packet()
  File "C:\Users\a046829713\Desktop\program\RLTrading\lib\site-packages\pymysql\connections.py", line 775, in _read_packet
    packet.raise_for_error()
  File "C:\Users\a046829713\Desktop\program\RLTrading\lib\site-packages\pymysql\protocol.py", line 219, in raise_for_error
    err.raise_mysql_exception(self._data)
  File "C:\Users\a046829713\Desktop\program\RLTrading\lib\site-packages\pymysql\err.py", line 150, in raise_mysql_exception
    raise errorclass(errno, errval)
pymysql.err.ProgrammingError: (1064, "You have an error in your SQL syntax; check the manual that corresponds to your MySQL server version for the right syntax to use near 'moveusdt-f-d' at line 1")

The above exception was the direct cause of the following exception:

Traceback (most recent call last):
  File "C:\Users\a046829713\Desktop\program\RLTrading\SynapseX\Database\SQL_operate.py", line 48, in read_Dateframe
    return pd.read_sql(text_msg, con=conn)
  File "C:\Users\a046829713\Desktop\program\RLTrading\lib\site-packages\pandas\io\sql.py", line 734, in read_sql
    return pandas_sql.read_query(
  File "C:\Users\a046829713\Desktop\program\RLTrading\lib\site-packages\pandas\io\sql.py", line 1836, in read_query
    result = self.execute(sql, params)
  File "C:\Users\a046829713\Desktop\program\RLTrading\lib\site-packages\pandas\io\sql.py", line 1659, in execute
    return self.con.exec_driver_sql(sql, *args)
  File "C:\Users\a046829713\Desktop\program\RLTrading\lib\site-packages\sqlalchemy\engine\base.py", line 1779, in exec_driver_sql
    ret = self._execute_context(
  File "C:\Users\a046829713\Desktop\program\RLTrading\lib\site-packages\sqlalchemy\engine\base.py", line 1846, in _execute_context
    return self._exec_single_context(
  File "C:\Users\a046829713\Desktop\program\RLTrading\lib\site-packages\sqlalchemy\engine\base.py", line 1986, in _exec_single_context
    self._handle_dbapi_exception(
  File "C:\Users\a046829713\Desktop\program\RLTrading\lib\site-packages\sqlalchemy\engine\base.py", line 2355, in _handle_dbapi_exception
    raise sqlalchemy_exception.with_traceback(exc_info[2]) from e
  File "C:\Users\a046829713\Desktop\program\RLTrading\lib\site-packages\sqlalchemy\engine\base.py", line 1967, in _exec_single_context
    self.dialect.do_execute(
  File "C:\Users\a046829713\Desktop\program\RLTrading\lib\site-packages\sqlalchemy\engine\default.py", line 941, in do_execute
    cursor.execute(statement, parameters)
  File "C:\Users\a046829713\Desktop\program\RLTrading\lib\site-packages\pymysql\cursors.py", line 153, in execute
    result = self._query(query)
  File "C:\Users\a046829713\Desktop\program\RLTrading\lib\site-packages\pymysql\cursors.py", line 322, in _query
    conn.query(q)
  File "C:\Users\a046829713\Desktop\program\RLTrading\lib\site-packages\pymysql\connections.py", line 563, in query
    self._affected_rows = self._read_query_result(unbuffered=unbuffered)
  File "C:\Users\a046829713\Desktop\program\RLTrading\lib\site-packages\pymysql\connections.py", line 825, in _read_query_result
    result.read()
  File "C:\Users\a046829713\Desktop\program\RLTrading\lib\site-packages\pymysql\connections.py", line 1199, in read
    first_packet = self.connection._read_packet()
  File "C:\Users\a046829713\Desktop\program\RLTrading\lib\site-packages\pymysql\connections.py", line 775, in _read_packet
    packet.raise_for_error()
  File "C:\Users\a046829713\Desktop\program\RLTrading\lib\site-packages\pymysql\protocol.py", line 219, in raise_for_error
    err.raise_mysql_exception(self._data)
  File "C:\Users\a046829713\Desktop\program\RLTrading\lib\site-packages\pymysql\err.py", line 150, in raise_mysql_exception
    raise errorclass(errno, errval)
sqlalchemy.exc.ProgrammingError: (pymysql.err.ProgrammingError) (1064, "You have an error in your SQL syntax; check the manual that corresponds to your MySQL server version for the right syntax to use near 'moveusdt-f-d' at line 1")
[SQL: moveusdt-f-d]
(Background on this error at: https://sqlalche.me/e/20/f405)

2024-12-21 11:57 ERROR Traceback (most recent call last):
  File "C:\Users\a046829713\Desktop\program\RLTrading\lib\site-packages\sqlalchemy\engine\base.py", line 1967, in _exec_single_context
    self.dialect.do_execute(
  File "C:\Users\a046829713\Desktop\program\RLTrading\lib\site-packages\sqlalchemy\engine\default.py", line 941, in do_execute
    cursor.execute(statement, parameters)
  File "C:\Users\a046829713\Desktop\program\RLTrading\lib\site-packages\pymysql\cursors.py", line 153, in execute
    result = self._query(query)
  File "C:\Users\a046829713\Desktop\program\RLTrading\lib\site-packages\pymysql\cursors.py", line 322, in _query
    conn.query(q)
  File "C:\Users\a046829713\Desktop\program\RLTrading\lib\site-packages\pymysql\connections.py", line 563, in query
    self._affected_rows = self._read_query_result(unbuffered=unbuffered)
  File "C:\Users\a046829713\Desktop\program\RLTrading\lib\site-packages\pymysql\connections.py", line 825, in _read_query_result
    result.read()
  File "C:\Users\a046829713\Desktop\program\RLTrading\lib\site-packages\pymysql\connections.py", line 1199, in read
    first_packet = self.connection._read_packet()
  File "C:\Users\a046829713\Desktop\program\RLTrading\lib\site-packages\pymysql\connections.py", line 775, in _read_packet
    packet.raise_for_error()
  File "C:\Users\a046829713\Desktop\program\RLTrading\lib\site-packages\pymysql\protocol.py", line 219, in raise_for_error
    err.raise_mysql_exception(self._data)
  File "C:\Users\a046829713\Desktop\program\RLTrading\lib\site-packages\pymysql\err.py", line 150, in raise_mysql_exception
    raise errorclass(errno, errval)
pymysql.err.ProgrammingError: (1064, "You have an error in your SQL syntax; check the manual that corresponds to your MySQL server version for the right syntax to use near 'raysolusdt-f-d' at line 1")

The above exception was the direct cause of the following exception:

Traceback (most recent call last):
  File "C:\Users\a046829713\Desktop\program\RLTrading\SynapseX\Database\SQL_operate.py", line 48, in read_Dateframe
    return pd.read_sql(text_msg, con=conn)
  File "C:\Users\a046829713\Desktop\program\RLTrading\lib\site-packages\pandas\io\sql.py", line 734, in read_sql
    return pandas_sql.read_query(
  File "C:\Users\a046829713\Desktop\program\RLTrading\lib\site-packages\pandas\io\sql.py", line 1836, in read_query
    result = self.execute(sql, params)
  File "C:\Users\a046829713\Desktop\program\RLTrading\lib\site-packages\pandas\io\sql.py", line 1659, in execute
    return self.con.exec_driver_sql(sql, *args)
  File "C:\Users\a046829713\Desktop\program\RLTrading\lib\site-packages\sqlalchemy\engine\base.py", line 1779, in exec_driver_sql
    ret = self._execute_context(
  File "C:\Users\a046829713\Desktop\program\RLTrading\lib\site-packages\sqlalchemy\engine\base.py", line 1846, in _execute_context
    return self._exec_single_context(
  File "C:\Users\a046829713\Desktop\program\RLTrading\lib\site-packages\sqlalchemy\engine\base.py", line 1986, in _exec_single_context
    self._handle_dbapi_exception(
  File "C:\Users\a046829713\Desktop\program\RLTrading\lib\site-packages\sqlalchemy\engine\base.py", line 2355, in _handle_dbapi_exception
    raise sqlalchemy_exception.with_traceback(exc_info[2]) from e
  File "C:\Users\a046829713\Desktop\program\RLTrading\lib\site-packages\sqlalchemy\engine\base.py", line 1967, in _exec_single_context
    self.dialect.do_execute(
  File "C:\Users\a046829713\Desktop\program\RLTrading\lib\site-packages\sqlalchemy\engine\default.py", line 941, in do_execute
    cursor.execute(statement, parameters)
  File "C:\Users\a046829713\Desktop\program\RLTrading\lib\site-packages\pymysql\cursors.py", line 153, in execute
    result = self._query(query)
  File "C:\Users\a046829713\Desktop\program\RLTrading\lib\site-packages\pymysql\cursors.py", line 322, in _query
    conn.query(q)
  File "C:\Users\a046829713\Desktop\program\RLTrading\lib\site-packages\pymysql\connections.py", line 563, in query
    self._affected_rows = self._read_query_result(unbuffered=unbuffered)
  File "C:\Users\a046829713\Desktop\program\RLTrading\lib\site-packages\pymysql\connections.py", line 825, in _read_query_result
    result.read()
  File "C:\Users\a046829713\Desktop\program\RLTrading\lib\site-packages\pymysql\connections.py", line 1199, in read
    first_packet = self.connection._read_packet()
  File "C:\Users\a046829713\Desktop\program\RLTrading\lib\site-packages\pymysql\connections.py", line 775, in _read_packet
    packet.raise_for_error()
  File "C:\Users\a046829713\Desktop\program\RLTrading\lib\site-packages\pymysql\protocol.py", line 219, in raise_for_error
    err.raise_mysql_exception(self._data)
  File "C:\Users\a046829713\Desktop\program\RLTrading\lib\site-packages\pymysql\err.py", line 150, in raise_mysql_exception
    raise errorclass(errno, errval)
sqlalchemy.exc.ProgrammingError: (pymysql.err.ProgrammingError) (1064, "You have an error in your SQL syntax; check the manual that corresponds to your MySQL server version for the right syntax to use near 'raysolusdt-f-d' at line 1")
[SQL: raysolusdt-f-d]
(Background on this error at: https://sqlalche.me/e/20/f405)

2024-12-21 11:57 ERROR Traceback (most recent call last):
  File "C:\Users\a046829713\Desktop\program\RLTrading\lib\site-packages\sqlalchemy\engine\base.py", line 1967, in _exec_single_context
    self.dialect.do_execute(
  File "C:\Users\a046829713\Desktop\program\RLTrading\lib\site-packages\sqlalchemy\engine\default.py", line 941, in do_execute
    cursor.execute(statement, parameters)
  File "C:\Users\a046829713\Desktop\program\RLTrading\lib\site-packages\pymysql\cursors.py", line 153, in execute
    result = self._query(query)
  File "C:\Users\a046829713\Desktop\program\RLTrading\lib\site-packages\pymysql\cursors.py", line 322, in _query
    conn.query(q)
  File "C:\Users\a046829713\Desktop\program\RLTrading\lib\site-packages\pymysql\connections.py", line 563, in query
    self._affected_rows = self._read_query_result(unbuffered=unbuffered)
  File "C:\Users\a046829713\Desktop\program\RLTrading\lib\site-packages\pymysql\connections.py", line 825, in _read_query_result
    result.read()
  File "C:\Users\a046829713\Desktop\program\RLTrading\lib\site-packages\pymysql\connections.py", line 1199, in read
    first_packet = self.connection._read_packet()
  File "C:\Users\a046829713\Desktop\program\RLTrading\lib\site-packages\pymysql\connections.py", line 775, in _read_packet
    packet.raise_for_error()
  File "C:\Users\a046829713\Desktop\program\RLTrading\lib\site-packages\pymysql\protocol.py", line 219, in raise_for_error
    err.raise_mysql_exception(self._data)
  File "C:\Users\a046829713\Desktop\program\RLTrading\lib\site-packages\pymysql\err.py", line 150, in raise_mysql_exception
    raise errorclass(errno, errval)
pymysql.err.ProgrammingError: (1064, "You have an error in your SQL syntax; check the manual that corresponds to your MySQL server version for the right syntax to use near 'komausdt-f-d' at line 1")

The above exception was the direct cause of the following exception:

Traceback (most recent call last):
  File "C:\Users\a046829713\Desktop\program\RLTrading\SynapseX\Database\SQL_operate.py", line 48, in read_Dateframe
    return pd.read_sql(text_msg, con=conn)
  File "C:\Users\a046829713\Desktop\program\RLTrading\lib\site-packages\pandas\io\sql.py", line 734, in read_sql
    return pandas_sql.read_query(
  File "C:\Users\a046829713\Desktop\program\RLTrading\lib\site-packages\pandas\io\sql.py", line 1836, in read_query
    result = self.execute(sql, params)
  File "C:\Users\a046829713\Desktop\program\RLTrading\lib\site-packages\pandas\io\sql.py", line 1659, in execute
    return self.con.exec_driver_sql(sql, *args)
  File "C:\Users\a046829713\Desktop\program\RLTrading\lib\site-packages\sqlalchemy\engine\base.py", line 1779, in exec_driver_sql
    ret = self._execute_context(
  File "C:\Users\a046829713\Desktop\program\RLTrading\lib\site-packages\sqlalchemy\engine\base.py", line 1846, in _execute_context
    return self._exec_single_context(
  File "C:\Users\a046829713\Desktop\program\RLTrading\lib\site-packages\sqlalchemy\engine\base.py", line 1986, in _exec_single_context
    self._handle_dbapi_exception(
  File "C:\Users\a046829713\Desktop\program\RLTrading\lib\site-packages\sqlalchemy\engine\base.py", line 2355, in _handle_dbapi_exception
    raise sqlalchemy_exception.with_traceback(exc_info[2]) from e
  File "C:\Users\a046829713\Desktop\program\RLTrading\lib\site-packages\sqlalchemy\engine\base.py", line 1967, in _exec_single_context
    self.dialect.do_execute(
  File "C:\Users\a046829713\Desktop\program\RLTrading\lib\site-packages\sqlalchemy\engine\default.py", line 941, in do_execute
    cursor.execute(statement, parameters)
  File "C:\Users\a046829713\Desktop\program\RLTrading\lib\site-packages\pymysql\cursors.py", line 153, in execute
    result = self._query(query)
  File "C:\Users\a046829713\Desktop\program\RLTrading\lib\site-packages\pymysql\cursors.py", line 322, in _query
    conn.query(q)
  File "C:\Users\a046829713\Desktop\program\RLTrading\lib\site-packages\pymysql\connections.py", line 563, in query
    self._affected_rows = self._read_query_result(unbuffered=unbuffered)
  File "C:\Users\a046829713\Desktop\program\RLTrading\lib\site-packages\pymysql\connections.py", line 825, in _read_query_result
    result.read()
  File "C:\Users\a046829713\Desktop\program\RLTrading\lib\site-packages\pymysql\connections.py", line 1199, in read
    first_packet = self.connection._read_packet()
  File "C:\Users\a046829713\Desktop\program\RLTrading\lib\site-packages\pymysql\connections.py", line 775, in _read_packet
    packet.raise_for_error()
  File "C:\Users\a046829713\Desktop\program\RLTrading\lib\site-packages\pymysql\protocol.py", line 219, in raise_for_error
    err.raise_mysql_exception(self._data)
  File "C:\Users\a046829713\Desktop\program\RLTrading\lib\site-packages\pymysql\err.py", line 150, in raise_mysql_exception
    raise errorclass(errno, errval)
sqlalchemy.exc.ProgrammingError: (pymysql.err.ProgrammingError) (1064, "You have an error in your SQL syntax; check the manual that corresponds to your MySQL server version for the right syntax to use near 'komausdt-f-d' at line 1")
[SQL: komausdt-f-d]
(Background on this error at: https://sqlalche.me/e/20/f405)

2024-12-21 11:57 ERROR Traceback (most recent call last):
  File "C:\Users\a046829713\Desktop\program\RLTrading\lib\site-packages\sqlalchemy\engine\base.py", line 1967, in _exec_single_context
    self.dialect.do_execute(
  File "C:\Users\a046829713\Desktop\program\RLTrading\lib\site-packages\sqlalchemy\engine\default.py", line 941, in do_execute
    cursor.execute(statement, parameters)
  File "C:\Users\a046829713\Desktop\program\RLTrading\lib\site-packages\pymysql\cursors.py", line 153, in execute
    result = self._query(query)
  File "C:\Users\a046829713\Desktop\program\RLTrading\lib\site-packages\pymysql\cursors.py", line 322, in _query
    conn.query(q)
  File "C:\Users\a046829713\Desktop\program\RLTrading\lib\site-packages\pymysql\connections.py", line 563, in query
    self._affected_rows = self._read_query_result(unbuffered=unbuffered)
  File "C:\Users\a046829713\Desktop\program\RLTrading\lib\site-packages\pymysql\connections.py", line 825, in _read_query_result
    result.read()
  File "C:\Users\a046829713\Desktop\program\RLTrading\lib\site-packages\pymysql\connections.py", line 1199, in read
    first_packet = self.connection._read_packet()
  File "C:\Users\a046829713\Desktop\program\RLTrading\lib\site-packages\pymysql\connections.py", line 775, in _read_packet
    packet.raise_for_error()
  File "C:\Users\a046829713\Desktop\program\RLTrading\lib\site-packages\pymysql\protocol.py", line 219, in raise_for_error
    err.raise_mysql_exception(self._data)
  File "C:\Users\a046829713\Desktop\program\RLTrading\lib\site-packages\pymysql\err.py", line 150, in raise_mysql_exception
    raise errorclass(errno, errval)
pymysql.err.ProgrammingError: (1064, "You have an error in your SQL syntax; check the manual that corresponds to your MySQL server version for the right syntax to use near 'virtualusdt-f-d' at line 1")

The above exception was the direct cause of the following exception:

Traceback (most recent call last):
  File "C:\Users\a046829713\Desktop\program\RLTrading\SynapseX\Database\SQL_operate.py", line 48, in read_Dateframe
    return pd.read_sql(text_msg, con=conn)
  File "C:\Users\a046829713\Desktop\program\RLTrading\lib\site-packages\pandas\io\sql.py", line 734, in read_sql
    return pandas_sql.read_query(
  File "C:\Users\a046829713\Desktop\program\RLTrading\lib\site-packages\pandas\io\sql.py", line 1836, in read_query
    result = self.execute(sql, params)
  File "C:\Users\a046829713\Desktop\program\RLTrading\lib\site-packages\pandas\io\sql.py", line 1659, in execute
    return self.con.exec_driver_sql(sql, *args)
  File "C:\Users\a046829713\Desktop\program\RLTrading\lib\site-packages\sqlalchemy\engine\base.py", line 1779, in exec_driver_sql
    ret = self._execute_context(
  File "C:\Users\a046829713\Desktop\program\RLTrading\lib\site-packages\sqlalchemy\engine\base.py", line 1846, in _execute_context
    return self._exec_single_context(
  File "C:\Users\a046829713\Desktop\program\RLTrading\lib\site-packages\sqlalchemy\engine\base.py", line 1986, in _exec_single_context
    self._handle_dbapi_exception(
  File "C:\Users\a046829713\Desktop\program\RLTrading\lib\site-packages\sqlalchemy\engine\base.py", line 2355, in _handle_dbapi_exception
    raise sqlalchemy_exception.with_traceback(exc_info[2]) from e
  File "C:\Users\a046829713\Desktop\program\RLTrading\lib\site-packages\sqlalchemy\engine\base.py", line 1967, in _exec_single_context
    self.dialect.do_execute(
  File "C:\Users\a046829713\Desktop\program\RLTrading\lib\site-packages\sqlalchemy\engine\default.py", line 941, in do_execute
    cursor.execute(statement, parameters)
  File "C:\Users\a046829713\Desktop\program\RLTrading\lib\site-packages\pymysql\cursors.py", line 153, in execute
    result = self._query(query)
  File "C:\Users\a046829713\Desktop\program\RLTrading\lib\site-packages\pymysql\cursors.py", line 322, in _query
    conn.query(q)
  File "C:\Users\a046829713\Desktop\program\RLTrading\lib\site-packages\pymysql\connections.py", line 563, in query
    self._affected_rows = self._read_query_result(unbuffered=unbuffered)
  File "C:\Users\a046829713\Desktop\program\RLTrading\lib\site-packages\pymysql\connections.py", line 825, in _read_query_result
    result.read()
  File "C:\Users\a046829713\Desktop\program\RLTrading\lib\site-packages\pymysql\connections.py", line 1199, in read
    first_packet = self.connection._read_packet()
  File "C:\Users\a046829713\Desktop\program\RLTrading\lib\site-packages\pymysql\connections.py", line 775, in _read_packet
    packet.raise_for_error()
  File "C:\Users\a046829713\Desktop\program\RLTrading\lib\site-packages\pymysql\protocol.py", line 219, in raise_for_error
    err.raise_mysql_exception(self._data)
  File "C:\Users\a046829713\Desktop\program\RLTrading\lib\site-packages\pymysql\err.py", line 150, in raise_mysql_exception
    raise errorclass(errno, errval)
sqlalchemy.exc.ProgrammingError: (pymysql.err.ProgrammingError) (1064, "You have an error in your SQL syntax; check the manual that corresponds to your MySQL server version for the right syntax to use near 'virtualusdt-f-d' at line 1")
[SQL: virtualusdt-f-d]
(Background on this error at: https://sqlalche.me/e/20/f405)

2024-12-21 11:57 ERROR Traceback (most recent call last):
  File "C:\Users\a046829713\Desktop\program\RLTrading\lib\site-packages\sqlalchemy\engine\base.py", line 1967, in _exec_single_context
    self.dialect.do_execute(
  File "C:\Users\a046829713\Desktop\program\RLTrading\lib\site-packages\sqlalchemy\engine\default.py", line 941, in do_execute
    cursor.execute(statement, parameters)
  File "C:\Users\a046829713\Desktop\program\RLTrading\lib\site-packages\pymysql\cursors.py", line 153, in execute
    result = self._query(query)
  File "C:\Users\a046829713\Desktop\program\RLTrading\lib\site-packages\pymysql\cursors.py", line 322, in _query
    conn.query(q)
  File "C:\Users\a046829713\Desktop\program\RLTrading\lib\site-packages\pymysql\connections.py", line 563, in query
    self._affected_rows = self._read_query_result(unbuffered=unbuffered)
  File "C:\Users\a046829713\Desktop\program\RLTrading\lib\site-packages\pymysql\connections.py", line 825, in _read_query_result
    result.read()
  File "C:\Users\a046829713\Desktop\program\RLTrading\lib\site-packages\pymysql\connections.py", line 1199, in read
    first_packet = self.connection._read_packet()
  File "C:\Users\a046829713\Desktop\program\RLTrading\lib\site-packages\pymysql\connections.py", line 775, in _read_packet
    packet.raise_for_error()
  File "C:\Users\a046829713\Desktop\program\RLTrading\lib\site-packages\pymysql\protocol.py", line 219, in raise_for_error
    err.raise_mysql_exception(self._data)
  File "C:\Users\a046829713\Desktop\program\RLTrading\lib\site-packages\pymysql\err.py", line 150, in raise_mysql_exception
    raise errorclass(errno, errval)
pymysql.err.ProgrammingError: (1064, "You have an error in your SQL syntax; check the manual that corresponds to your MySQL server version for the right syntax to use near 'spxusdt-f-d' at line 1")

The above exception was the direct cause of the following exception:

Traceback (most recent call last):
  File "C:\Users\a046829713\Desktop\program\RLTrading\SynapseX\Database\SQL_operate.py", line 48, in read_Dateframe
    return pd.read_sql(text_msg, con=conn)
  File "C:\Users\a046829713\Desktop\program\RLTrading\lib\site-packages\pandas\io\sql.py", line 734, in read_sql
    return pandas_sql.read_query(
  File "C:\Users\a046829713\Desktop\program\RLTrading\lib\site-packages\pandas\io\sql.py", line 1836, in read_query
    result = self.execute(sql, params)
  File "C:\Users\a046829713\Desktop\program\RLTrading\lib\site-packages\pandas\io\sql.py", line 1659, in execute
    return self.con.exec_driver_sql(sql, *args)
  File "C:\Users\a046829713\Desktop\program\RLTrading\lib\site-packages\sqlalchemy\engine\base.py", line 1779, in exec_driver_sql
    ret = self._execute_context(
  File "C:\Users\a046829713\Desktop\program\RLTrading\lib\site-packages\sqlalchemy\engine\base.py", line 1846, in _execute_context
    return self._exec_single_context(
  File "C:\Users\a046829713\Desktop\program\RLTrading\lib\site-packages\sqlalchemy\engine\base.py", line 1986, in _exec_single_context
    self._handle_dbapi_exception(
  File "C:\Users\a046829713\Desktop\program\RLTrading\lib\site-packages\sqlalchemy\engine\base.py", line 2355, in _handle_dbapi_exception
    raise sqlalchemy_exception.with_traceback(exc_info[2]) from e
  File "C:\Users\a046829713\Desktop\program\RLTrading\lib\site-packages\sqlalchemy\engine\base.py", line 1967, in _exec_single_context
    self.dialect.do_execute(
  File "C:\Users\a046829713\Desktop\program\RLTrading\lib\site-packages\sqlalchemy\engine\default.py", line 941, in do_execute
    cursor.execute(statement, parameters)
  File "C:\Users\a046829713\Desktop\program\RLTrading\lib\site-packages\pymysql\cursors.py", line 153, in execute
    result = self._query(query)
  File "C:\Users\a046829713\Desktop\program\RLTrading\lib\site-packages\pymysql\cursors.py", line 322, in _query
    conn.query(q)
  File "C:\Users\a046829713\Desktop\program\RLTrading\lib\site-packages\pymysql\connections.py", line 563, in query
    self._affected_rows = self._read_query_result(unbuffered=unbuffered)
  File "C:\Users\a046829713\Desktop\program\RLTrading\lib\site-packages\pymysql\connections.py", line 825, in _read_query_result
    result.read()
  File "C:\Users\a046829713\Desktop\program\RLTrading\lib\site-packages\pymysql\connections.py", line 1199, in read
    first_packet = self.connection._read_packet()
  File "C:\Users\a046829713\Desktop\program\RLTrading\lib\site-packages\pymysql\connections.py", line 775, in _read_packet
    packet.raise_for_error()
  File "C:\Users\a046829713\Desktop\program\RLTrading\lib\site-packages\pymysql\protocol.py", line 219, in raise_for_error
    err.raise_mysql_exception(self._data)
  File "C:\Users\a046829713\Desktop\program\RLTrading\lib\site-packages\pymysql\err.py", line 150, in raise_mysql_exception
    raise errorclass(errno, errval)
sqlalchemy.exc.ProgrammingError: (pymysql.err.ProgrammingError) (1064, "You have an error in your SQL syntax; check the manual that corresponds to your MySQL server version for the right syntax to use near 'spxusdt-f-d' at line 1")
[SQL: spxusdt-f-d]
(Background on this error at: https://sqlalche.me/e/20/f405)

2024-12-21 11:57 ERROR Traceback (most recent call last):
  File "C:\Users\a046829713\Desktop\program\RLTrading\lib\site-packages\sqlalchemy\engine\base.py", line 1967, in _exec_single_context
    self.dialect.do_execute(
  File "C:\Users\a046829713\Desktop\program\RLTrading\lib\site-packages\sqlalchemy\engine\default.py", line 941, in do_execute
    cursor.execute(statement, parameters)
  File "C:\Users\a046829713\Desktop\program\RLTrading\lib\site-packages\pymysql\cursors.py", line 153, in execute
    result = self._query(query)
  File "C:\Users\a046829713\Desktop\program\RLTrading\lib\site-packages\pymysql\cursors.py", line 322, in _query
    conn.query(q)
  File "C:\Users\a046829713\Desktop\program\RLTrading\lib\site-packages\pymysql\connections.py", line 563, in query
    self._affected_rows = self._read_query_result(unbuffered=unbuffered)
  File "C:\Users\a046829713\Desktop\program\RLTrading\lib\site-packages\pymysql\connections.py", line 825, in _read_query_result
    result.read()
  File "C:\Users\a046829713\Desktop\program\RLTrading\lib\site-packages\pymysql\connections.py", line 1199, in read
    first_packet = self.connection._read_packet()
  File "C:\Users\a046829713\Desktop\program\RLTrading\lib\site-packages\pymysql\connections.py", line 775, in _read_packet
    packet.raise_for_error()
  File "C:\Users\a046829713\Desktop\program\RLTrading\lib\site-packages\pymysql\protocol.py", line 219, in raise_for_error
    err.raise_mysql_exception(self._data)
  File "C:\Users\a046829713\Desktop\program\RLTrading\lib\site-packages\pymysql\err.py", line 150, in raise_mysql_exception
    raise errorclass(errno, errval)
pymysql.err.ProgrammingError: (1064, "You have an error in your SQL syntax; check the manual that corresponds to your MySQL server version for the right syntax to use near 'meusdt-f-d' at line 1")

The above exception was the direct cause of the following exception:

Traceback (most recent call last):
  File "C:\Users\a046829713\Desktop\program\RLTrading\SynapseX\Database\SQL_operate.py", line 48, in read_Dateframe
    return pd.read_sql(text_msg, con=conn)
  File "C:\Users\a046829713\Desktop\program\RLTrading\lib\site-packages\pandas\io\sql.py", line 734, in read_sql
    return pandas_sql.read_query(
  File "C:\Users\a046829713\Desktop\program\RLTrading\lib\site-packages\pandas\io\sql.py", line 1836, in read_query
    result = self.execute(sql, params)
  File "C:\Users\a046829713\Desktop\program\RLTrading\lib\site-packages\pandas\io\sql.py", line 1659, in execute
    return self.con.exec_driver_sql(sql, *args)
  File "C:\Users\a046829713\Desktop\program\RLTrading\lib\site-packages\sqlalchemy\engine\base.py", line 1779, in exec_driver_sql
    ret = self._execute_context(
  File "C:\Users\a046829713\Desktop\program\RLTrading\lib\site-packages\sqlalchemy\engine\base.py", line 1846, in _execute_context
    return self._exec_single_context(
  File "C:\Users\a046829713\Desktop\program\RLTrading\lib\site-packages\sqlalchemy\engine\base.py", line 1986, in _exec_single_context
    self._handle_dbapi_exception(
  File "C:\Users\a046829713\Desktop\program\RLTrading\lib\site-packages\sqlalchemy\engine\base.py", line 2355, in _handle_dbapi_exception
    raise sqlalchemy_exception.with_traceback(exc_info[2]) from e
  File "C:\Users\a046829713\Desktop\program\RLTrading\lib\site-packages\sqlalchemy\engine\base.py", line 1967, in _exec_single_context
    self.dialect.do_execute(
  File "C:\Users\a046829713\Desktop\program\RLTrading\lib\site-packages\sqlalchemy\engine\default.py", line 941, in do_execute
    cursor.execute(statement, parameters)
  File "C:\Users\a046829713\Desktop\program\RLTrading\lib\site-packages\pymysql\cursors.py", line 153, in execute
    result = self._query(query)
  File "C:\Users\a046829713\Desktop\program\RLTrading\lib\site-packages\pymysql\cursors.py", line 322, in _query
    conn.query(q)
  File "C:\Users\a046829713\Desktop\program\RLTrading\lib\site-packages\pymysql\connections.py", line 563, in query
    self._affected_rows = self._read_query_result(unbuffered=unbuffered)
  File "C:\Users\a046829713\Desktop\program\RLTrading\lib\site-packages\pymysql\connections.py", line 825, in _read_query_result
    result.read()
  File "C:\Users\a046829713\Desktop\program\RLTrading\lib\site-packages\pymysql\connections.py", line 1199, in read
    first_packet = self.connection._read_packet()
  File "C:\Users\a046829713\Desktop\program\RLTrading\lib\site-packages\pymysql\connections.py", line 775, in _read_packet
    packet.raise_for_error()
  File "C:\Users\a046829713\Desktop\program\RLTrading\lib\site-packages\pymysql\protocol.py", line 219, in raise_for_error
    err.raise_mysql_exception(self._data)
  File "C:\Users\a046829713\Desktop\program\RLTrading\lib\site-packages\pymysql\err.py", line 150, in raise_mysql_exception
    raise errorclass(errno, errval)
sqlalchemy.exc.ProgrammingError: (pymysql.err.ProgrammingError) (1064, "You have an error in your SQL syntax; check the manual that corresponds to your MySQL server version for the right syntax to use near 'meusdt-f-d' at line 1")
[SQL: meusdt-f-d]
(Background on this error at: https://sqlalche.me/e/20/f405)

2024-12-21 11:57 ERROR Traceback (most recent call last):
  File "C:\Users\a046829713\Desktop\program\RLTrading\lib\site-packages\sqlalchemy\engine\base.py", line 1967, in _exec_single_context
    self.dialect.do_execute(
  File "C:\Users\a046829713\Desktop\program\RLTrading\lib\site-packages\sqlalchemy\engine\default.py", line 941, in do_execute
    cursor.execute(statement, parameters)
  File "C:\Users\a046829713\Desktop\program\RLTrading\lib\site-packages\pymysql\cursors.py", line 153, in execute
    result = self._query(query)
  File "C:\Users\a046829713\Desktop\program\RLTrading\lib\site-packages\pymysql\cursors.py", line 322, in _query
    conn.query(q)
  File "C:\Users\a046829713\Desktop\program\RLTrading\lib\site-packages\pymysql\connections.py", line 563, in query
    self._affected_rows = self._read_query_result(unbuffered=unbuffered)
  File "C:\Users\a046829713\Desktop\program\RLTrading\lib\site-packages\pymysql\connections.py", line 825, in _read_query_result
    result.read()
  File "C:\Users\a046829713\Desktop\program\RLTrading\lib\site-packages\pymysql\connections.py", line 1199, in read
    first_packet = self.connection._read_packet()
  File "C:\Users\a046829713\Desktop\program\RLTrading\lib\site-packages\pymysql\connections.py", line 775, in _read_packet
    packet.raise_for_error()
  File "C:\Users\a046829713\Desktop\program\RLTrading\lib\site-packages\pymysql\protocol.py", line 219, in raise_for_error
    err.raise_mysql_exception(self._data)
  File "C:\Users\a046829713\Desktop\program\RLTrading\lib\site-packages\pymysql\err.py", line 150, in raise_mysql_exception
    raise errorclass(errno, errval)
pymysql.err.ProgrammingError: (1064, "You have an error in your SQL syntax; check the manual that corresponds to your MySQL server version for the right syntax to use near 'avausdt-f-d' at line 1")

The above exception was the direct cause of the following exception:

Traceback (most recent call last):
  File "C:\Users\a046829713\Desktop\program\RLTrading\SynapseX\Database\SQL_operate.py", line 48, in read_Dateframe
    return pd.read_sql(text_msg, con=conn)
  File "C:\Users\a046829713\Desktop\program\RLTrading\lib\site-packages\pandas\io\sql.py", line 734, in read_sql
    return pandas_sql.read_query(
  File "C:\Users\a046829713\Desktop\program\RLTrading\lib\site-packages\pandas\io\sql.py", line 1836, in read_query
    result = self.execute(sql, params)
  File "C:\Users\a046829713\Desktop\program\RLTrading\lib\site-packages\pandas\io\sql.py", line 1659, in execute
    return self.con.exec_driver_sql(sql, *args)
  File "C:\Users\a046829713\Desktop\program\RLTrading\lib\site-packages\sqlalchemy\engine\base.py", line 1779, in exec_driver_sql
    ret = self._execute_context(
  File "C:\Users\a046829713\Desktop\program\RLTrading\lib\site-packages\sqlalchemy\engine\base.py", line 1846, in _execute_context
    return self._exec_single_context(
  File "C:\Users\a046829713\Desktop\program\RLTrading\lib\site-packages\sqlalchemy\engine\base.py", line 1986, in _exec_single_context
    self._handle_dbapi_exception(
  File "C:\Users\a046829713\Desktop\program\RLTrading\lib\site-packages\sqlalchemy\engine\base.py", line 2355, in _handle_dbapi_exception
    raise sqlalchemy_exception.with_traceback(exc_info[2]) from e
  File "C:\Users\a046829713\Desktop\program\RLTrading\lib\site-packages\sqlalchemy\engine\base.py", line 1967, in _exec_single_context
    self.dialect.do_execute(
  File "C:\Users\a046829713\Desktop\program\RLTrading\lib\site-packages\sqlalchemy\engine\default.py", line 941, in do_execute
    cursor.execute(statement, parameters)
  File "C:\Users\a046829713\Desktop\program\RLTrading\lib\site-packages\pymysql\cursors.py", line 153, in execute
    result = self._query(query)
  File "C:\Users\a046829713\Desktop\program\RLTrading\lib\site-packages\pymysql\cursors.py", line 322, in _query
    conn.query(q)
  File "C:\Users\a046829713\Desktop\program\RLTrading\lib\site-packages\pymysql\connections.py", line 563, in query
    self._affected_rows = self._read_query_result(unbuffered=unbuffered)
  File "C:\Users\a046829713\Desktop\program\RLTrading\lib\site-packages\pymysql\connections.py", line 825, in _read_query_result
    result.read()
  File "C:\Users\a046829713\Desktop\program\RLTrading\lib\site-packages\pymysql\connections.py", line 1199, in read
    first_packet = self.connection._read_packet()
  File "C:\Users\a046829713\Desktop\program\RLTrading\lib\site-packages\pymysql\connections.py", line 775, in _read_packet
    packet.raise_for_error()
  File "C:\Users\a046829713\Desktop\program\RLTrading\lib\site-packages\pymysql\protocol.py", line 219, in raise_for_error
    err.raise_mysql_exception(self._data)
  File "C:\Users\a046829713\Desktop\program\RLTrading\lib\site-packages\pymysql\err.py", line 150, in raise_mysql_exception
    raise errorclass(errno, errval)
sqlalchemy.exc.ProgrammingError: (pymysql.err.ProgrammingError) (1064, "You have an error in your SQL syntax; check the manual that corresponds to your MySQL server version for the right syntax to use near 'avausdt-f-d' at line 1")
[SQL: avausdt-f-d]
(Background on this error at: https://sqlalche.me/e/20/f405)

2024-12-21 11:57 ERROR Traceback (most recent call last):
  File "C:\Users\a046829713\Desktop\program\RLTrading\lib\site-packages\sqlalchemy\engine\base.py", line 1967, in _exec_single_context
    self.dialect.do_execute(
  File "C:\Users\a046829713\Desktop\program\RLTrading\lib\site-packages\sqlalchemy\engine\default.py", line 941, in do_execute
    cursor.execute(statement, parameters)
  File "C:\Users\a046829713\Desktop\program\RLTrading\lib\site-packages\pymysql\cursors.py", line 153, in execute
    result = self._query(query)
  File "C:\Users\a046829713\Desktop\program\RLTrading\lib\site-packages\pymysql\cursors.py", line 322, in _query
    conn.query(q)
  File "C:\Users\a046829713\Desktop\program\RLTrading\lib\site-packages\pymysql\connections.py", line 563, in query
    self._affected_rows = self._read_query_result(unbuffered=unbuffered)
  File "C:\Users\a046829713\Desktop\program\RLTrading\lib\site-packages\pymysql\connections.py", line 825, in _read_query_result
    result.read()
  File "C:\Users\a046829713\Desktop\program\RLTrading\lib\site-packages\pymysql\connections.py", line 1199, in read
    first_packet = self.connection._read_packet()
  File "C:\Users\a046829713\Desktop\program\RLTrading\lib\site-packages\pymysql\connections.py", line 775, in _read_packet
    packet.raise_for_error()
  File "C:\Users\a046829713\Desktop\program\RLTrading\lib\site-packages\pymysql\protocol.py", line 219, in raise_for_error
    err.raise_mysql_exception(self._data)
  File "C:\Users\a046829713\Desktop\program\RLTrading\lib\site-packages\pymysql\err.py", line 150, in raise_mysql_exception
    raise errorclass(errno, errval)
pymysql.err.ProgrammingError: (1064, "You have an error in your SQL syntax; check the manual that corresponds to your MySQL server version for the right syntax to use near 'degousdt-f-d' at line 1")

The above exception was the direct cause of the following exception:

Traceback (most recent call last):
  File "C:\Users\a046829713\Desktop\program\RLTrading\SynapseX\Database\SQL_operate.py", line 48, in read_Dateframe
    return pd.read_sql(text_msg, con=conn)
  File "C:\Users\a046829713\Desktop\program\RLTrading\lib\site-packages\pandas\io\sql.py", line 734, in read_sql
    return pandas_sql.read_query(
  File "C:\Users\a046829713\Desktop\program\RLTrading\lib\site-packages\pandas\io\sql.py", line 1836, in read_query
    result = self.execute(sql, params)
  File "C:\Users\a046829713\Desktop\program\RLTrading\lib\site-packages\pandas\io\sql.py", line 1659, in execute
    return self.con.exec_driver_sql(sql, *args)
  File "C:\Users\a046829713\Desktop\program\RLTrading\lib\site-packages\sqlalchemy\engine\base.py", line 1779, in exec_driver_sql
    ret = self._execute_context(
  File "C:\Users\a046829713\Desktop\program\RLTrading\lib\site-packages\sqlalchemy\engine\base.py", line 1846, in _execute_context
    return self._exec_single_context(
  File "C:\Users\a046829713\Desktop\program\RLTrading\lib\site-packages\sqlalchemy\engine\base.py", line 1986, in _exec_single_context
    self._handle_dbapi_exception(
  File "C:\Users\a046829713\Desktop\program\RLTrading\lib\site-packages\sqlalchemy\engine\base.py", line 2355, in _handle_dbapi_exception
    raise sqlalchemy_exception.with_traceback(exc_info[2]) from e
  File "C:\Users\a046829713\Desktop\program\RLTrading\lib\site-packages\sqlalchemy\engine\base.py", line 1967, in _exec_single_context
    self.dialect.do_execute(
  File "C:\Users\a046829713\Desktop\program\RLTrading\lib\site-packages\sqlalchemy\engine\default.py", line 941, in do_execute
    cursor.execute(statement, parameters)
  File "C:\Users\a046829713\Desktop\program\RLTrading\lib\site-packages\pymysql\cursors.py", line 153, in execute
    result = self._query(query)
  File "C:\Users\a046829713\Desktop\program\RLTrading\lib\site-packages\pymysql\cursors.py", line 322, in _query
    conn.query(q)
  File "C:\Users\a046829713\Desktop\program\RLTrading\lib\site-packages\pymysql\connections.py", line 563, in query
    self._affected_rows = self._read_query_result(unbuffered=unbuffered)
  File "C:\Users\a046829713\Desktop\program\RLTrading\lib\site-packages\pymysql\connections.py", line 825, in _read_query_result
    result.read()
  File "C:\Users\a046829713\Desktop\program\RLTrading\lib\site-packages\pymysql\connections.py", line 1199, in read
    first_packet = self.connection._read_packet()
  File "C:\Users\a046829713\Desktop\program\RLTrading\lib\site-packages\pymysql\connections.py", line 775, in _read_packet
    packet.raise_for_error()
  File "C:\Users\a046829713\Desktop\program\RLTrading\lib\site-packages\pymysql\protocol.py", line 219, in raise_for_error
    err.raise_mysql_exception(self._data)
  File "C:\Users\a046829713\Desktop\program\RLTrading\lib\site-packages\pymysql\err.py", line 150, in raise_mysql_exception
    raise errorclass(errno, errval)
sqlalchemy.exc.ProgrammingError: (pymysql.err.ProgrammingError) (1064, "You have an error in your SQL syntax; check the manual that corresponds to your MySQL server version for the right syntax to use near 'degousdt-f-d' at line 1")
[SQL: degousdt-f-d]
(Background on this error at: https://sqlalche.me/e/20/f405)

2024-12-21 11:57 ERROR Traceback (most recent call last):
  File "C:\Users\a046829713\Desktop\program\RLTrading\lib\site-packages\sqlalchemy\engine\base.py", line 1967, in _exec_single_context
    self.dialect.do_execute(
  File "C:\Users\a046829713\Desktop\program\RLTrading\lib\site-packages\sqlalchemy\engine\default.py", line 941, in do_execute
    cursor.execute(statement, parameters)
  File "C:\Users\a046829713\Desktop\program\RLTrading\lib\site-packages\pymysql\cursors.py", line 153, in execute
    result = self._query(query)
  File "C:\Users\a046829713\Desktop\program\RLTrading\lib\site-packages\pymysql\cursors.py", line 322, in _query
    conn.query(q)
  File "C:\Users\a046829713\Desktop\program\RLTrading\lib\site-packages\pymysql\connections.py", line 563, in query
    self._affected_rows = self._read_query_result(unbuffered=unbuffered)
  File "C:\Users\a046829713\Desktop\program\RLTrading\lib\site-packages\pymysql\connections.py", line 825, in _read_query_result
    result.read()
  File "C:\Users\a046829713\Desktop\program\RLTrading\lib\site-packages\pymysql\connections.py", line 1199, in read
    first_packet = self.connection._read_packet()
  File "C:\Users\a046829713\Desktop\program\RLTrading\lib\site-packages\pymysql\connections.py", line 775, in _read_packet
    packet.raise_for_error()
  File "C:\Users\a046829713\Desktop\program\RLTrading\lib\site-packages\pymysql\protocol.py", line 219, in raise_for_error
    err.raise_mysql_exception(self._data)
  File "C:\Users\a046829713\Desktop\program\RLTrading\lib\site-packages\pymysql\err.py", line 150, in raise_mysql_exception
    raise errorclass(errno, errval)
pymysql.err.ProgrammingError: (1064, "You have an error in your SQL syntax; check the manual that corresponds to your MySQL server version for the right syntax to use near 'velodromeusdt-f-d' at line 1")

The above exception was the direct cause of the following exception:

Traceback (most recent call last):
  File "C:\Users\a046829713\Desktop\program\RLTrading\SynapseX\Database\SQL_operate.py", line 48, in read_Dateframe
    return pd.read_sql(text_msg, con=conn)
  File "C:\Users\a046829713\Desktop\program\RLTrading\lib\site-packages\pandas\io\sql.py", line 734, in read_sql
    return pandas_sql.read_query(
  File "C:\Users\a046829713\Desktop\program\RLTrading\lib\site-packages\pandas\io\sql.py", line 1836, in read_query
    result = self.execute(sql, params)
  File "C:\Users\a046829713\Desktop\program\RLTrading\lib\site-packages\pandas\io\sql.py", line 1659, in execute
    return self.con.exec_driver_sql(sql, *args)
  File "C:\Users\a046829713\Desktop\program\RLTrading\lib\site-packages\sqlalchemy\engine\base.py", line 1779, in exec_driver_sql
    ret = self._execute_context(
  File "C:\Users\a046829713\Desktop\program\RLTrading\lib\site-packages\sqlalchemy\engine\base.py", line 1846, in _execute_context
    return self._exec_single_context(
  File "C:\Users\a046829713\Desktop\program\RLTrading\lib\site-packages\sqlalchemy\engine\base.py", line 1986, in _exec_single_context
    self._handle_dbapi_exception(
  File "C:\Users\a046829713\Desktop\program\RLTrading\lib\site-packages\sqlalchemy\engine\base.py", line 2355, in _handle_dbapi_exception
    raise sqlalchemy_exception.with_traceback(exc_info[2]) from e
  File "C:\Users\a046829713\Desktop\program\RLTrading\lib\site-packages\sqlalchemy\engine\base.py", line 1967, in _exec_single_context
    self.dialect.do_execute(
  File "C:\Users\a046829713\Desktop\program\RLTrading\lib\site-packages\sqlalchemy\engine\default.py", line 941, in do_execute
    cursor.execute(statement, parameters)
  File "C:\Users\a046829713\Desktop\program\RLTrading\lib\site-packages\pymysql\cursors.py", line 153, in execute
    result = self._query(query)
  File "C:\Users\a046829713\Desktop\program\RLTrading\lib\site-packages\pymysql\cursors.py", line 322, in _query
    conn.query(q)
  File "C:\Users\a046829713\Desktop\program\RLTrading\lib\site-packages\pymysql\connections.py", line 563, in query
    self._affected_rows = self._read_query_result(unbuffered=unbuffered)
  File "C:\Users\a046829713\Desktop\program\RLTrading\lib\site-packages\pymysql\connections.py", line 825, in _read_query_result
    result.read()
  File "C:\Users\a046829713\Desktop\program\RLTrading\lib\site-packages\pymysql\connections.py", line 1199, in read
    first_packet = self.connection._read_packet()
  File "C:\Users\a046829713\Desktop\program\RLTrading\lib\site-packages\pymysql\connections.py", line 775, in _read_packet
    packet.raise_for_error()
  File "C:\Users\a046829713\Desktop\program\RLTrading\lib\site-packages\pymysql\protocol.py", line 219, in raise_for_error
    err.raise_mysql_exception(self._data)
  File "C:\Users\a046829713\Desktop\program\RLTrading\lib\site-packages\pymysql\err.py", line 150, in raise_mysql_exception
    raise errorclass(errno, errval)
sqlalchemy.exc.ProgrammingError: (pymysql.err.ProgrammingError) (1064, "You have an error in your SQL syntax; check the manual that corresponds to your MySQL server version for the right syntax to use near 'velodromeusdt-f-d' at line 1")
[SQL: velodromeusdt-f-d]
(Background on this error at: https://sqlalche.me/e/20/f405)

2024-12-21 11:57 ERROR Traceback (most recent call last):
  File "C:\Users\a046829713\Desktop\program\RLTrading\lib\site-packages\sqlalchemy\engine\base.py", line 1967, in _exec_single_context
    self.dialect.do_execute(
  File "C:\Users\a046829713\Desktop\program\RLTrading\lib\site-packages\sqlalchemy\engine\default.py", line 941, in do_execute
    cursor.execute(statement, parameters)
  File "C:\Users\a046829713\Desktop\program\RLTrading\lib\site-packages\pymysql\cursors.py", line 153, in execute
    result = self._query(query)
  File "C:\Users\a046829713\Desktop\program\RLTrading\lib\site-packages\pymysql\cursors.py", line 322, in _query
    conn.query(q)
  File "C:\Users\a046829713\Desktop\program\RLTrading\lib\site-packages\pymysql\connections.py", line 563, in query
    self._affected_rows = self._read_query_result(unbuffered=unbuffered)
  File "C:\Users\a046829713\Desktop\program\RLTrading\lib\site-packages\pymysql\connections.py", line 825, in _read_query_result
    result.read()
  File "C:\Users\a046829713\Desktop\program\RLTrading\lib\site-packages\pymysql\connections.py", line 1199, in read
    first_packet = self.connection._read_packet()
  File "C:\Users\a046829713\Desktop\program\RLTrading\lib\site-packages\pymysql\connections.py", line 775, in _read_packet
    packet.raise_for_error()
  File "C:\Users\a046829713\Desktop\program\RLTrading\lib\site-packages\pymysql\protocol.py", line 219, in raise_for_error
    err.raise_mysql_exception(self._data)
  File "C:\Users\a046829713\Desktop\program\RLTrading\lib\site-packages\pymysql\err.py", line 150, in raise_mysql_exception
    raise errorclass(errno, errval)
pymysql.err.ProgrammingError: (1064, "You have an error in your SQL syntax; check the manual that corresponds to your MySQL server version for the right syntax to use near 'mocausdt-f-d' at line 1")

The above exception was the direct cause of the following exception:

Traceback (most recent call last):
  File "C:\Users\a046829713\Desktop\program\RLTrading\SynapseX\Database\SQL_operate.py", line 48, in read_Dateframe
    return pd.read_sql(text_msg, con=conn)
  File "C:\Users\a046829713\Desktop\program\RLTrading\lib\site-packages\pandas\io\sql.py", line 734, in read_sql
    return pandas_sql.read_query(
  File "C:\Users\a046829713\Desktop\program\RLTrading\lib\site-packages\pandas\io\sql.py", line 1836, in read_query
    result = self.execute(sql, params)
  File "C:\Users\a046829713\Desktop\program\RLTrading\lib\site-packages\pandas\io\sql.py", line 1659, in execute
    return self.con.exec_driver_sql(sql, *args)
  File "C:\Users\a046829713\Desktop\program\RLTrading\lib\site-packages\sqlalchemy\engine\base.py", line 1779, in exec_driver_sql
    ret = self._execute_context(
  File "C:\Users\a046829713\Desktop\program\RLTrading\lib\site-packages\sqlalchemy\engine\base.py", line 1846, in _execute_context
    return self._exec_single_context(
  File "C:\Users\a046829713\Desktop\program\RLTrading\lib\site-packages\sqlalchemy\engine\base.py", line 1986, in _exec_single_context
    self._handle_dbapi_exception(
  File "C:\Users\a046829713\Desktop\program\RLTrading\lib\site-packages\sqlalchemy\engine\base.py", line 2355, in _handle_dbapi_exception
    raise sqlalchemy_exception.with_traceback(exc_info[2]) from e
  File "C:\Users\a046829713\Desktop\program\RLTrading\lib\site-packages\sqlalchemy\engine\base.py", line 1967, in _exec_single_context
    self.dialect.do_execute(
  File "C:\Users\a046829713\Desktop\program\RLTrading\lib\site-packages\sqlalchemy\engine\default.py", line 941, in do_execute
    cursor.execute(statement, parameters)
  File "C:\Users\a046829713\Desktop\program\RLTrading\lib\site-packages\pymysql\cursors.py", line 153, in execute
    result = self._query(query)
  File "C:\Users\a046829713\Desktop\program\RLTrading\lib\site-packages\pymysql\cursors.py", line 322, in _query
    conn.query(q)
  File "C:\Users\a046829713\Desktop\program\RLTrading\lib\site-packages\pymysql\connections.py", line 563, in query
    self._affected_rows = self._read_query_result(unbuffered=unbuffered)
  File "C:\Users\a046829713\Desktop\program\RLTrading\lib\site-packages\pymysql\connections.py", line 825, in _read_query_result
    result.read()
  File "C:\Users\a046829713\Desktop\program\RLTrading\lib\site-packages\pymysql\connections.py", line 1199, in read
    first_packet = self.connection._read_packet()
  File "C:\Users\a046829713\Desktop\program\RLTrading\lib\site-packages\pymysql\connections.py", line 775, in _read_packet
    packet.raise_for_error()
  File "C:\Users\a046829713\Desktop\program\RLTrading\lib\site-packages\pymysql\protocol.py", line 219, in raise_for_error
    err.raise_mysql_exception(self._data)
  File "C:\Users\a046829713\Desktop\program\RLTrading\lib\site-packages\pymysql\err.py", line 150, in raise_mysql_exception
    raise errorclass(errno, errval)
sqlalchemy.exc.ProgrammingError: (pymysql.err.ProgrammingError) (1064, "You have an error in your SQL syntax; check the manual that corresponds to your MySQL server version for the right syntax to use near 'mocausdt-f-d' at line 1")
[SQL: mocausdt-f-d]
(Background on this error at: https://sqlalche.me/e/20/f405)

2024-12-21 11:57 ERROR Traceback (most recent call last):
  File "C:\Users\a046829713\Desktop\program\RLTrading\lib\site-packages\sqlalchemy\engine\base.py", line 1967, in _exec_single_context
    self.dialect.do_execute(
  File "C:\Users\a046829713\Desktop\program\RLTrading\lib\site-packages\sqlalchemy\engine\default.py", line 941, in do_execute
    cursor.execute(statement, parameters)
  File "C:\Users\a046829713\Desktop\program\RLTrading\lib\site-packages\pymysql\cursors.py", line 153, in execute
    result = self._query(query)
  File "C:\Users\a046829713\Desktop\program\RLTrading\lib\site-packages\pymysql\cursors.py", line 322, in _query
    conn.query(q)
  File "C:\Users\a046829713\Desktop\program\RLTrading\lib\site-packages\pymysql\connections.py", line 563, in query
    self._affected_rows = self._read_query_result(unbuffered=unbuffered)
  File "C:\Users\a046829713\Desktop\program\RLTrading\lib\site-packages\pymysql\connections.py", line 825, in _read_query_result
    result.read()
  File "C:\Users\a046829713\Desktop\program\RLTrading\lib\site-packages\pymysql\connections.py", line 1199, in read
    first_packet = self.connection._read_packet()
  File "C:\Users\a046829713\Desktop\program\RLTrading\lib\site-packages\pymysql\connections.py", line 775, in _read_packet
    packet.raise_for_error()
  File "C:\Users\a046829713\Desktop\program\RLTrading\lib\site-packages\pymysql\protocol.py", line 219, in raise_for_error
    err.raise_mysql_exception(self._data)
  File "C:\Users\a046829713\Desktop\program\RLTrading\lib\site-packages\pymysql\err.py", line 150, in raise_mysql_exception
    raise errorclass(errno, errval)
pymysql.err.ProgrammingError: (1064, "You have an error in your SQL syntax; check the manual that corresponds to your MySQL server version for the right syntax to use near 'vanausdt-f-d' at line 1")

The above exception was the direct cause of the following exception:

Traceback (most recent call last):
  File "C:\Users\a046829713\Desktop\program\RLTrading\SynapseX\Database\SQL_operate.py", line 48, in read_Dateframe
    return pd.read_sql(text_msg, con=conn)
  File "C:\Users\a046829713\Desktop\program\RLTrading\lib\site-packages\pandas\io\sql.py", line 734, in read_sql
    return pandas_sql.read_query(
  File "C:\Users\a046829713\Desktop\program\RLTrading\lib\site-packages\pandas\io\sql.py", line 1836, in read_query
    result = self.execute(sql, params)
  File "C:\Users\a046829713\Desktop\program\RLTrading\lib\site-packages\pandas\io\sql.py", line 1659, in execute
    return self.con.exec_driver_sql(sql, *args)
  File "C:\Users\a046829713\Desktop\program\RLTrading\lib\site-packages\sqlalchemy\engine\base.py", line 1779, in exec_driver_sql
    ret = self._execute_context(
  File "C:\Users\a046829713\Desktop\program\RLTrading\lib\site-packages\sqlalchemy\engine\base.py", line 1846, in _execute_context
    return self._exec_single_context(
  File "C:\Users\a046829713\Desktop\program\RLTrading\lib\site-packages\sqlalchemy\engine\base.py", line 1986, in _exec_single_context
    self._handle_dbapi_exception(
  File "C:\Users\a046829713\Desktop\program\RLTrading\lib\site-packages\sqlalchemy\engine\base.py", line 2355, in _handle_dbapi_exception
    raise sqlalchemy_exception.with_traceback(exc_info[2]) from e
  File "C:\Users\a046829713\Desktop\program\RLTrading\lib\site-packages\sqlalchemy\engine\base.py", line 1967, in _exec_single_context
    self.dialect.do_execute(
  File "C:\Users\a046829713\Desktop\program\RLTrading\lib\site-packages\sqlalchemy\engine\default.py", line 941, in do_execute
    cursor.execute(statement, parameters)
  File "C:\Users\a046829713\Desktop\program\RLTrading\lib\site-packages\pymysql\cursors.py", line 153, in execute
    result = self._query(query)
  File "C:\Users\a046829713\Desktop\program\RLTrading\lib\site-packages\pymysql\cursors.py", line 322, in _query
    conn.query(q)
  File "C:\Users\a046829713\Desktop\program\RLTrading\lib\site-packages\pymysql\connections.py", line 563, in query
    self._affected_rows = self._read_query_result(unbuffered=unbuffered)
  File "C:\Users\a046829713\Desktop\program\RLTrading\lib\site-packages\pymysql\connections.py", line 825, in _read_query_result
    result.read()
  File "C:\Users\a046829713\Desktop\program\RLTrading\lib\site-packages\pymysql\connections.py", line 1199, in read
    first_packet = self.connection._read_packet()
  File "C:\Users\a046829713\Desktop\program\RLTrading\lib\site-packages\pymysql\connections.py", line 775, in _read_packet
    packet.raise_for_error()
  File "C:\Users\a046829713\Desktop\program\RLTrading\lib\site-packages\pymysql\protocol.py", line 219, in raise_for_error
    err.raise_mysql_exception(self._data)
  File "C:\Users\a046829713\Desktop\program\RLTrading\lib\site-packages\pymysql\err.py", line 150, in raise_mysql_exception
    raise errorclass(errno, errval)
sqlalchemy.exc.ProgrammingError: (pymysql.err.ProgrammingError) (1064, "You have an error in your SQL syntax; check the manual that corresponds to your MySQL server version for the right syntax to use near 'vanausdt-f-d' at line 1")
[SQL: vanausdt-f-d]
(Background on this error at: https://sqlalche.me/e/20/f405)

2024-12-21 11:57 ERROR Traceback (most recent call last):
  File "C:\Users\a046829713\Desktop\program\RLTrading\lib\site-packages\sqlalchemy\engine\base.py", line 1967, in _exec_single_context
    self.dialect.do_execute(
  File "C:\Users\a046829713\Desktop\program\RLTrading\lib\site-packages\sqlalchemy\engine\default.py", line 941, in do_execute
    cursor.execute(statement, parameters)
  File "C:\Users\a046829713\Desktop\program\RLTrading\lib\site-packages\pymysql\cursors.py", line 153, in execute
    result = self._query(query)
  File "C:\Users\a046829713\Desktop\program\RLTrading\lib\site-packages\pymysql\cursors.py", line 322, in _query
    conn.query(q)
  File "C:\Users\a046829713\Desktop\program\RLTrading\lib\site-packages\pymysql\connections.py", line 563, in query
    self._affected_rows = self._read_query_result(unbuffered=unbuffered)
  File "C:\Users\a046829713\Desktop\program\RLTrading\lib\site-packages\pymysql\connections.py", line 825, in _read_query_result
    result.read()
  File "C:\Users\a046829713\Desktop\program\RLTrading\lib\site-packages\pymysql\connections.py", line 1199, in read
    first_packet = self.connection._read_packet()
  File "C:\Users\a046829713\Desktop\program\RLTrading\lib\site-packages\pymysql\connections.py", line 775, in _read_packet
    packet.raise_for_error()
  File "C:\Users\a046829713\Desktop\program\RLTrading\lib\site-packages\pymysql\protocol.py", line 219, in raise_for_error
    err.raise_mysql_exception(self._data)
  File "C:\Users\a046829713\Desktop\program\RLTrading\lib\site-packages\pymysql\err.py", line 150, in raise_mysql_exception
    raise errorclass(errno, errval)
pymysql.err.ProgrammingError: (1064, "You have an error in your SQL syntax; check the manual that corresponds to your MySQL server version for the right syntax to use near 'penguusdt-f-d' at line 1")

The above exception was the direct cause of the following exception:

Traceback (most recent call last):
  File "C:\Users\a046829713\Desktop\program\RLTrading\SynapseX\Database\SQL_operate.py", line 48, in read_Dateframe
    return pd.read_sql(text_msg, con=conn)
  File "C:\Users\a046829713\Desktop\program\RLTrading\lib\site-packages\pandas\io\sql.py", line 734, in read_sql
    return pandas_sql.read_query(
  File "C:\Users\a046829713\Desktop\program\RLTrading\lib\site-packages\pandas\io\sql.py", line 1836, in read_query
    result = self.execute(sql, params)
  File "C:\Users\a046829713\Desktop\program\RLTrading\lib\site-packages\pandas\io\sql.py", line 1659, in execute
    return self.con.exec_driver_sql(sql, *args)
  File "C:\Users\a046829713\Desktop\program\RLTrading\lib\site-packages\sqlalchemy\engine\base.py", line 1779, in exec_driver_sql
    ret = self._execute_context(
  File "C:\Users\a046829713\Desktop\program\RLTrading\lib\site-packages\sqlalchemy\engine\base.py", line 1846, in _execute_context
    return self._exec_single_context(
  File "C:\Users\a046829713\Desktop\program\RLTrading\lib\site-packages\sqlalchemy\engine\base.py", line 1986, in _exec_single_context
    self._handle_dbapi_exception(
  File "C:\Users\a046829713\Desktop\program\RLTrading\lib\site-packages\sqlalchemy\engine\base.py", line 2355, in _handle_dbapi_exception
    raise sqlalchemy_exception.with_traceback(exc_info[2]) from e
  File "C:\Users\a046829713\Desktop\program\RLTrading\lib\site-packages\sqlalchemy\engine\base.py", line 1967, in _exec_single_context
    self.dialect.do_execute(
  File "C:\Users\a046829713\Desktop\program\RLTrading\lib\site-packages\sqlalchemy\engine\default.py", line 941, in do_execute
    cursor.execute(statement, parameters)
  File "C:\Users\a046829713\Desktop\program\RLTrading\lib\site-packages\pymysql\cursors.py", line 153, in execute
    result = self._query(query)
  File "C:\Users\a046829713\Desktop\program\RLTrading\lib\site-packages\pymysql\cursors.py", line 322, in _query
    conn.query(q)
  File "C:\Users\a046829713\Desktop\program\RLTrading\lib\site-packages\pymysql\connections.py", line 563, in query
    self._affected_rows = self._read_query_result(unbuffered=unbuffered)
  File "C:\Users\a046829713\Desktop\program\RLTrading\lib\site-packages\pymysql\connections.py", line 825, in _read_query_result
    result.read()
  File "C:\Users\a046829713\Desktop\program\RLTrading\lib\site-packages\pymysql\connections.py", line 1199, in read
    first_packet = self.connection._read_packet()
  File "C:\Users\a046829713\Desktop\program\RLTrading\lib\site-packages\pymysql\connections.py", line 775, in _read_packet
    packet.raise_for_error()
  File "C:\Users\a046829713\Desktop\program\RLTrading\lib\site-packages\pymysql\protocol.py", line 219, in raise_for_error
    err.raise_mysql_exception(self._data)
  File "C:\Users\a046829713\Desktop\program\RLTrading\lib\site-packages\pymysql\err.py", line 150, in raise_mysql_exception
    raise errorclass(errno, errval)
sqlalchemy.exc.ProgrammingError: (pymysql.err.ProgrammingError) (1064, "You have an error in your SQL syntax; check the manual that corresponds to your MySQL server version for the right syntax to use near 'penguusdt-f-d' at line 1")
[SQL: penguusdt-f-d]
(Background on this error at: https://sqlalche.me/e/20/f405)

2024-12-21 11:57 ERROR Traceback (most recent call last):
  File "C:\Users\a046829713\Desktop\program\RLTrading\lib\site-packages\sqlalchemy\engine\base.py", line 1967, in _exec_single_context
    self.dialect.do_execute(
  File "C:\Users\a046829713\Desktop\program\RLTrading\lib\site-packages\sqlalchemy\engine\default.py", line 941, in do_execute
    cursor.execute(statement, parameters)
  File "C:\Users\a046829713\Desktop\program\RLTrading\lib\site-packages\pymysql\cursors.py", line 153, in execute
    result = self._query(query)
  File "C:\Users\a046829713\Desktop\program\RLTrading\lib\site-packages\pymysql\cursors.py", line 322, in _query
    conn.query(q)
  File "C:\Users\a046829713\Desktop\program\RLTrading\lib\site-packages\pymysql\connections.py", line 563, in query
    self._affected_rows = self._read_query_result(unbuffered=unbuffered)
  File "C:\Users\a046829713\Desktop\program\RLTrading\lib\site-packages\pymysql\connections.py", line 825, in _read_query_result
    result.read()
  File "C:\Users\a046829713\Desktop\program\RLTrading\lib\site-packages\pymysql\connections.py", line 1199, in read
    first_packet = self.connection._read_packet()
  File "C:\Users\a046829713\Desktop\program\RLTrading\lib\site-packages\pymysql\connections.py", line 775, in _read_packet
    packet.raise_for_error()
  File "C:\Users\a046829713\Desktop\program\RLTrading\lib\site-packages\pymysql\protocol.py", line 219, in raise_for_error
    err.raise_mysql_exception(self._data)
  File "C:\Users\a046829713\Desktop\program\RLTrading\lib\site-packages\pymysql\err.py", line 150, in raise_mysql_exception
    raise errorclass(errno, errval)
pymysql.err.ProgrammingError: (1064, "You have an error in your SQL syntax; check the manual that corresponds to your MySQL server version for the right syntax to use near 'lumiausdt-f-d' at line 1")

The above exception was the direct cause of the following exception:

Traceback (most recent call last):
  File "C:\Users\a046829713\Desktop\program\RLTrading\SynapseX\Database\SQL_operate.py", line 48, in read_Dateframe
    return pd.read_sql(text_msg, con=conn)
  File "C:\Users\a046829713\Desktop\program\RLTrading\lib\site-packages\pandas\io\sql.py", line 734, in read_sql
    return pandas_sql.read_query(
  File "C:\Users\a046829713\Desktop\program\RLTrading\lib\site-packages\pandas\io\sql.py", line 1836, in read_query
    result = self.execute(sql, params)
  File "C:\Users\a046829713\Desktop\program\RLTrading\lib\site-packages\pandas\io\sql.py", line 1659, in execute
    return self.con.exec_driver_sql(sql, *args)
  File "C:\Users\a046829713\Desktop\program\RLTrading\lib\site-packages\sqlalchemy\engine\base.py", line 1779, in exec_driver_sql
    ret = self._execute_context(
  File "C:\Users\a046829713\Desktop\program\RLTrading\lib\site-packages\sqlalchemy\engine\base.py", line 1846, in _execute_context
    return self._exec_single_context(
  File "C:\Users\a046829713\Desktop\program\RLTrading\lib\site-packages\sqlalchemy\engine\base.py", line 1986, in _exec_single_context
    self._handle_dbapi_exception(
  File "C:\Users\a046829713\Desktop\program\RLTrading\lib\site-packages\sqlalchemy\engine\base.py", line 2355, in _handle_dbapi_exception
    raise sqlalchemy_exception.with_traceback(exc_info[2]) from e
  File "C:\Users\a046829713\Desktop\program\RLTrading\lib\site-packages\sqlalchemy\engine\base.py", line 1967, in _exec_single_context
    self.dialect.do_execute(
  File "C:\Users\a046829713\Desktop\program\RLTrading\lib\site-packages\sqlalchemy\engine\default.py", line 941, in do_execute
    cursor.execute(statement, parameters)
  File "C:\Users\a046829713\Desktop\program\RLTrading\lib\site-packages\pymysql\cursors.py", line 153, in execute
    result = self._query(query)
  File "C:\Users\a046829713\Desktop\program\RLTrading\lib\site-packages\pymysql\cursors.py", line 322, in _query
    conn.query(q)
  File "C:\Users\a046829713\Desktop\program\RLTrading\lib\site-packages\pymysql\connections.py", line 563, in query
    self._affected_rows = self._read_query_result(unbuffered=unbuffered)
  File "C:\Users\a046829713\Desktop\program\RLTrading\lib\site-packages\pymysql\connections.py", line 825, in _read_query_result
    result.read()
  File "C:\Users\a046829713\Desktop\program\RLTrading\lib\site-packages\pymysql\connections.py", line 1199, in read
    first_packet = self.connection._read_packet()
  File "C:\Users\a046829713\Desktop\program\RLTrading\lib\site-packages\pymysql\connections.py", line 775, in _read_packet
    packet.raise_for_error()
  File "C:\Users\a046829713\Desktop\program\RLTrading\lib\site-packages\pymysql\protocol.py", line 219, in raise_for_error
    err.raise_mysql_exception(self._data)
  File "C:\Users\a046829713\Desktop\program\RLTrading\lib\site-packages\pymysql\err.py", line 150, in raise_mysql_exception
    raise errorclass(errno, errval)
sqlalchemy.exc.ProgrammingError: (pymysql.err.ProgrammingError) (1064, "You have an error in your SQL syntax; check the manual that corresponds to your MySQL server version for the right syntax to use near 'lumiausdt-f-d' at line 1")
[SQL: lumiausdt-f-d]
(Background on this error at: https://sqlalche.me/e/20/f405)

2024-12-21 11:57 ERROR Traceback (most recent call last):
  File "C:\Users\a046829713\Desktop\program\RLTrading\lib\site-packages\sqlalchemy\engine\base.py", line 1967, in _exec_single_context
    self.dialect.do_execute(
  File "C:\Users\a046829713\Desktop\program\RLTrading\lib\site-packages\sqlalchemy\engine\default.py", line 941, in do_execute
    cursor.execute(statement, parameters)
  File "C:\Users\a046829713\Desktop\program\RLTrading\lib\site-packages\pymysql\cursors.py", line 153, in execute
    result = self._query(query)
  File "C:\Users\a046829713\Desktop\program\RLTrading\lib\site-packages\pymysql\cursors.py", line 322, in _query
    conn.query(q)
  File "C:\Users\a046829713\Desktop\program\RLTrading\lib\site-packages\pymysql\connections.py", line 563, in query
    self._affected_rows = self._read_query_result(unbuffered=unbuffered)
  File "C:\Users\a046829713\Desktop\program\RLTrading\lib\site-packages\pymysql\connections.py", line 825, in _read_query_result
    result.read()
  File "C:\Users\a046829713\Desktop\program\RLTrading\lib\site-packages\pymysql\connections.py", line 1199, in read
    first_packet = self.connection._read_packet()
  File "C:\Users\a046829713\Desktop\program\RLTrading\lib\site-packages\pymysql\connections.py", line 775, in _read_packet
    packet.raise_for_error()
  File "C:\Users\a046829713\Desktop\program\RLTrading\lib\site-packages\pymysql\protocol.py", line 219, in raise_for_error
    err.raise_mysql_exception(self._data)
  File "C:\Users\a046829713\Desktop\program\RLTrading\lib\site-packages\pymysql\err.py", line 150, in raise_mysql_exception
    raise errorclass(errno, errval)
pymysql.err.ProgrammingError: (1064, "You have an error in your SQL syntax; check the manual that corresponds to your MySQL server version for the right syntax to use near 'usualusdt-f-d' at line 1")

The above exception was the direct cause of the following exception:

Traceback (most recent call last):
  File "C:\Users\a046829713\Desktop\program\RLTrading\SynapseX\Database\SQL_operate.py", line 48, in read_Dateframe
    return pd.read_sql(text_msg, con=conn)
  File "C:\Users\a046829713\Desktop\program\RLTrading\lib\site-packages\pandas\io\sql.py", line 734, in read_sql
    return pandas_sql.read_query(
  File "C:\Users\a046829713\Desktop\program\RLTrading\lib\site-packages\pandas\io\sql.py", line 1836, in read_query
    result = self.execute(sql, params)
  File "C:\Users\a046829713\Desktop\program\RLTrading\lib\site-packages\pandas\io\sql.py", line 1659, in execute
    return self.con.exec_driver_sql(sql, *args)
  File "C:\Users\a046829713\Desktop\program\RLTrading\lib\site-packages\sqlalchemy\engine\base.py", line 1779, in exec_driver_sql
    ret = self._execute_context(
  File "C:\Users\a046829713\Desktop\program\RLTrading\lib\site-packages\sqlalchemy\engine\base.py", line 1846, in _execute_context
    return self._exec_single_context(
  File "C:\Users\a046829713\Desktop\program\RLTrading\lib\site-packages\sqlalchemy\engine\base.py", line 1986, in _exec_single_context
    self._handle_dbapi_exception(
  File "C:\Users\a046829713\Desktop\program\RLTrading\lib\site-packages\sqlalchemy\engine\base.py", line 2355, in _handle_dbapi_exception
    raise sqlalchemy_exception.with_traceback(exc_info[2]) from e
  File "C:\Users\a046829713\Desktop\program\RLTrading\lib\site-packages\sqlalchemy\engine\base.py", line 1967, in _exec_single_context
    self.dialect.do_execute(
  File "C:\Users\a046829713\Desktop\program\RLTrading\lib\site-packages\sqlalchemy\engine\default.py", line 941, in do_execute
    cursor.execute(statement, parameters)
  File "C:\Users\a046829713\Desktop\program\RLTrading\lib\site-packages\pymysql\cursors.py", line 153, in execute
    result = self._query(query)
  File "C:\Users\a046829713\Desktop\program\RLTrading\lib\site-packages\pymysql\cursors.py", line 322, in _query
    conn.query(q)
  File "C:\Users\a046829713\Desktop\program\RLTrading\lib\site-packages\pymysql\connections.py", line 563, in query
    self._affected_rows = self._read_query_result(unbuffered=unbuffered)
  File "C:\Users\a046829713\Desktop\program\RLTrading\lib\site-packages\pymysql\connections.py", line 825, in _read_query_result
    result.read()
  File "C:\Users\a046829713\Desktop\program\RLTrading\lib\site-packages\pymysql\connections.py", line 1199, in read
    first_packet = self.connection._read_packet()
  File "C:\Users\a046829713\Desktop\program\RLTrading\lib\site-packages\pymysql\connections.py", line 775, in _read_packet
    packet.raise_for_error()
  File "C:\Users\a046829713\Desktop\program\RLTrading\lib\site-packages\pymysql\protocol.py", line 219, in raise_for_error
    err.raise_mysql_exception(self._data)
  File "C:\Users\a046829713\Desktop\program\RLTrading\lib\site-packages\pymysql\err.py", line 150, in raise_mysql_exception
    raise errorclass(errno, errval)
sqlalchemy.exc.ProgrammingError: (pymysql.err.ProgrammingError) (1064, "You have an error in your SQL syntax; check the manual that corresponds to your MySQL server version for the right syntax to use near 'usualusdt-f-d' at line 1")
[SQL: usualusdt-f-d]
(Background on this error at: https://sqlalche.me/e/20/f405)

2024-12-21 11:57 ERROR Traceback (most recent call last):
  File "C:\Users\a046829713\Desktop\program\RLTrading\lib\site-packages\sqlalchemy\engine\base.py", line 1967, in _exec_single_context
    self.dialect.do_execute(
  File "C:\Users\a046829713\Desktop\program\RLTrading\lib\site-packages\sqlalchemy\engine\default.py", line 941, in do_execute
    cursor.execute(statement, parameters)
  File "C:\Users\a046829713\Desktop\program\RLTrading\lib\site-packages\pymysql\cursors.py", line 153, in execute
    result = self._query(query)
  File "C:\Users\a046829713\Desktop\program\RLTrading\lib\site-packages\pymysql\cursors.py", line 322, in _query
    conn.query(q)
  File "C:\Users\a046829713\Desktop\program\RLTrading\lib\site-packages\pymysql\connections.py", line 563, in query
    self._affected_rows = self._read_query_result(unbuffered=unbuffered)
  File "C:\Users\a046829713\Desktop\program\RLTrading\lib\site-packages\pymysql\connections.py", line 825, in _read_query_result
    result.read()
  File "C:\Users\a046829713\Desktop\program\RLTrading\lib\site-packages\pymysql\connections.py", line 1199, in read
    first_packet = self.connection._read_packet()
  File "C:\Users\a046829713\Desktop\program\RLTrading\lib\site-packages\pymysql\connections.py", line 775, in _read_packet
    packet.raise_for_error()
  File "C:\Users\a046829713\Desktop\program\RLTrading\lib\site-packages\pymysql\protocol.py", line 219, in raise_for_error
    err.raise_mysql_exception(self._data)
  File "C:\Users\a046829713\Desktop\program\RLTrading\lib\site-packages\pymysql\err.py", line 150, in raise_mysql_exception
    raise errorclass(errno, errval)
pymysql.err.ProgrammingError: (1064, "You have an error in your SQL syntax; check the manual that corresponds to your MySQL server version for the right syntax to use near 'aixbtusdt-f-d' at line 1")

The above exception was the direct cause of the following exception:

Traceback (most recent call last):
  File "C:\Users\a046829713\Desktop\program\RLTrading\SynapseX\Database\SQL_operate.py", line 48, in read_Dateframe
    return pd.read_sql(text_msg, con=conn)
  File "C:\Users\a046829713\Desktop\program\RLTrading\lib\site-packages\pandas\io\sql.py", line 734, in read_sql
    return pandas_sql.read_query(
  File "C:\Users\a046829713\Desktop\program\RLTrading\lib\site-packages\pandas\io\sql.py", line 1836, in read_query
    result = self.execute(sql, params)
  File "C:\Users\a046829713\Desktop\program\RLTrading\lib\site-packages\pandas\io\sql.py", line 1659, in execute
    return self.con.exec_driver_sql(sql, *args)
  File "C:\Users\a046829713\Desktop\program\RLTrading\lib\site-packages\sqlalchemy\engine\base.py", line 1779, in exec_driver_sql
    ret = self._execute_context(
  File "C:\Users\a046829713\Desktop\program\RLTrading\lib\site-packages\sqlalchemy\engine\base.py", line 1846, in _execute_context
    return self._exec_single_context(
  File "C:\Users\a046829713\Desktop\program\RLTrading\lib\site-packages\sqlalchemy\engine\base.py", line 1986, in _exec_single_context
    self._handle_dbapi_exception(
  File "C:\Users\a046829713\Desktop\program\RLTrading\lib\site-packages\sqlalchemy\engine\base.py", line 2355, in _handle_dbapi_exception
    raise sqlalchemy_exception.with_traceback(exc_info[2]) from e
  File "C:\Users\a046829713\Desktop\program\RLTrading\lib\site-packages\sqlalchemy\engine\base.py", line 1967, in _exec_single_context
    self.dialect.do_execute(
  File "C:\Users\a046829713\Desktop\program\RLTrading\lib\site-packages\sqlalchemy\engine\default.py", line 941, in do_execute
    cursor.execute(statement, parameters)
  File "C:\Users\a046829713\Desktop\program\RLTrading\lib\site-packages\pymysql\cursors.py", line 153, in execute
    result = self._query(query)
  File "C:\Users\a046829713\Desktop\program\RLTrading\lib\site-packages\pymysql\cursors.py", line 322, in _query
    conn.query(q)
  File "C:\Users\a046829713\Desktop\program\RLTrading\lib\site-packages\pymysql\connections.py", line 563, in query
    self._affected_rows = self._read_query_result(unbuffered=unbuffered)
  File "C:\Users\a046829713\Desktop\program\RLTrading\lib\site-packages\pymysql\connections.py", line 825, in _read_query_result
    result.read()
  File "C:\Users\a046829713\Desktop\program\RLTrading\lib\site-packages\pymysql\connections.py", line 1199, in read
    first_packet = self.connection._read_packet()
  File "C:\Users\a046829713\Desktop\program\RLTrading\lib\site-packages\pymysql\connections.py", line 775, in _read_packet
    packet.raise_for_error()
  File "C:\Users\a046829713\Desktop\program\RLTrading\lib\site-packages\pymysql\protocol.py", line 219, in raise_for_error
    err.raise_mysql_exception(self._data)
  File "C:\Users\a046829713\Desktop\program\RLTrading\lib\site-packages\pymysql\err.py", line 150, in raise_mysql_exception
    raise errorclass(errno, errval)
sqlalchemy.exc.ProgrammingError: (pymysql.err.ProgrammingError) (1064, "You have an error in your SQL syntax; check the manual that corresponds to your MySQL server version for the right syntax to use near 'aixbtusdt-f-d' at line 1")
[SQL: aixbtusdt-f-d]
(Background on this error at: https://sqlalche.me/e/20/f405)

2024-12-21 11:57 ERROR Traceback (most recent call last):
  File "C:\Users\a046829713\Desktop\program\RLTrading\lib\site-packages\sqlalchemy\engine\base.py", line 1967, in _exec_single_context
    self.dialect.do_execute(
  File "C:\Users\a046829713\Desktop\program\RLTrading\lib\site-packages\sqlalchemy\engine\default.py", line 941, in do_execute
    cursor.execute(statement, parameters)
  File "C:\Users\a046829713\Desktop\program\RLTrading\lib\site-packages\pymysql\cursors.py", line 153, in execute
    result = self._query(query)
  File "C:\Users\a046829713\Desktop\program\RLTrading\lib\site-packages\pymysql\cursors.py", line 322, in _query
    conn.query(q)
  File "C:\Users\a046829713\Desktop\program\RLTrading\lib\site-packages\pymysql\connections.py", line 563, in query
    self._affected_rows = self._read_query_result(unbuffered=unbuffered)
  File "C:\Users\a046829713\Desktop\program\RLTrading\lib\site-packages\pymysql\connections.py", line 825, in _read_query_result
    result.read()
  File "C:\Users\a046829713\Desktop\program\RLTrading\lib\site-packages\pymysql\connections.py", line 1199, in read
    first_packet = self.connection._read_packet()
  File "C:\Users\a046829713\Desktop\program\RLTrading\lib\site-packages\pymysql\connections.py", line 775, in _read_packet
    packet.raise_for_error()
  File "C:\Users\a046829713\Desktop\program\RLTrading\lib\site-packages\pymysql\protocol.py", line 219, in raise_for_error
    err.raise_mysql_exception(self._data)
  File "C:\Users\a046829713\Desktop\program\RLTrading\lib\site-packages\pymysql\err.py", line 150, in raise_mysql_exception
    raise errorclass(errno, errval)
pymysql.err.ProgrammingError: (1064, "You have an error in your SQL syntax; check the manual that corresponds to your MySQL server version for the right syntax to use near 'fartcoinusdt-f-d' at line 1")

The above exception was the direct cause of the following exception:

Traceback (most recent call last):
  File "C:\Users\a046829713\Desktop\program\RLTrading\SynapseX\Database\SQL_operate.py", line 48, in read_Dateframe
    return pd.read_sql(text_msg, con=conn)
  File "C:\Users\a046829713\Desktop\program\RLTrading\lib\site-packages\pandas\io\sql.py", line 734, in read_sql
    return pandas_sql.read_query(
  File "C:\Users\a046829713\Desktop\program\RLTrading\lib\site-packages\pandas\io\sql.py", line 1836, in read_query
    result = self.execute(sql, params)
  File "C:\Users\a046829713\Desktop\program\RLTrading\lib\site-packages\pandas\io\sql.py", line 1659, in execute
    return self.con.exec_driver_sql(sql, *args)
  File "C:\Users\a046829713\Desktop\program\RLTrading\lib\site-packages\sqlalchemy\engine\base.py", line 1779, in exec_driver_sql
    ret = self._execute_context(
  File "C:\Users\a046829713\Desktop\program\RLTrading\lib\site-packages\sqlalchemy\engine\base.py", line 1846, in _execute_context
    return self._exec_single_context(
  File "C:\Users\a046829713\Desktop\program\RLTrading\lib\site-packages\sqlalchemy\engine\base.py", line 1986, in _exec_single_context
    self._handle_dbapi_exception(
  File "C:\Users\a046829713\Desktop\program\RLTrading\lib\site-packages\sqlalchemy\engine\base.py", line 2355, in _handle_dbapi_exception
    raise sqlalchemy_exception.with_traceback(exc_info[2]) from e
  File "C:\Users\a046829713\Desktop\program\RLTrading\lib\site-packages\sqlalchemy\engine\base.py", line 1967, in _exec_single_context
    self.dialect.do_execute(
  File "C:\Users\a046829713\Desktop\program\RLTrading\lib\site-packages\sqlalchemy\engine\default.py", line 941, in do_execute
    cursor.execute(statement, parameters)
  File "C:\Users\a046829713\Desktop\program\RLTrading\lib\site-packages\pymysql\cursors.py", line 153, in execute
    result = self._query(query)
  File "C:\Users\a046829713\Desktop\program\RLTrading\lib\site-packages\pymysql\cursors.py", line 322, in _query
    conn.query(q)
  File "C:\Users\a046829713\Desktop\program\RLTrading\lib\site-packages\pymysql\connections.py", line 563, in query
    self._affected_rows = self._read_query_result(unbuffered=unbuffered)
  File "C:\Users\a046829713\Desktop\program\RLTrading\lib\site-packages\pymysql\connections.py", line 825, in _read_query_result
    result.read()
  File "C:\Users\a046829713\Desktop\program\RLTrading\lib\site-packages\pymysql\connections.py", line 1199, in read
    first_packet = self.connection._read_packet()
  File "C:\Users\a046829713\Desktop\program\RLTrading\lib\site-packages\pymysql\connections.py", line 775, in _read_packet
    packet.raise_for_error()
  File "C:\Users\a046829713\Desktop\program\RLTrading\lib\site-packages\pymysql\protocol.py", line 219, in raise_for_error
    err.raise_mysql_exception(self._data)
  File "C:\Users\a046829713\Desktop\program\RLTrading\lib\site-packages\pymysql\err.py", line 150, in raise_mysql_exception
    raise errorclass(errno, errval)
sqlalchemy.exc.ProgrammingError: (pymysql.err.ProgrammingError) (1064, "You have an error in your SQL syntax; check the manual that corresponds to your MySQL server version for the right syntax to use near 'fartcoinusdt-f-d' at line 1")
[SQL: fartcoinusdt-f-d]
(Background on this error at: https://sqlalche.me/e/20/f405)

2024-12-21 11:57 ERROR Traceback (most recent call last):
  File "C:\Users\a046829713\Desktop\program\RLTrading\lib\site-packages\sqlalchemy\engine\base.py", line 1967, in _exec_single_context
    self.dialect.do_execute(
  File "C:\Users\a046829713\Desktop\program\RLTrading\lib\site-packages\sqlalchemy\engine\default.py", line 941, in do_execute
    cursor.execute(statement, parameters)
  File "C:\Users\a046829713\Desktop\program\RLTrading\lib\site-packages\pymysql\cursors.py", line 153, in execute
    result = self._query(query)
  File "C:\Users\a046829713\Desktop\program\RLTrading\lib\site-packages\pymysql\cursors.py", line 322, in _query
    conn.query(q)
  File "C:\Users\a046829713\Desktop\program\RLTrading\lib\site-packages\pymysql\connections.py", line 563, in query
    self._affected_rows = self._read_query_result(unbuffered=unbuffered)
  File "C:\Users\a046829713\Desktop\program\RLTrading\lib\site-packages\pymysql\connections.py", line 825, in _read_query_result
    result.read()
  File "C:\Users\a046829713\Desktop\program\RLTrading\lib\site-packages\pymysql\connections.py", line 1199, in read
    first_packet = self.connection._read_packet()
  File "C:\Users\a046829713\Desktop\program\RLTrading\lib\site-packages\pymysql\connections.py", line 775, in _read_packet
    packet.raise_for_error()
  File "C:\Users\a046829713\Desktop\program\RLTrading\lib\site-packages\pymysql\protocol.py", line 219, in raise_for_error
    err.raise_mysql_exception(self._data)
  File "C:\Users\a046829713\Desktop\program\RLTrading\lib\site-packages\pymysql\err.py", line 150, in raise_mysql_exception
    raise errorclass(errno, errval)
pymysql.err.ProgrammingError: (1064, "You have an error in your SQL syntax; check the manual that corresponds to your MySQL server version for the right syntax to use near 'kmnousdt-f-d' at line 1")

The above exception was the direct cause of the following exception:

Traceback (most recent call last):
  File "C:\Users\a046829713\Desktop\program\RLTrading\SynapseX\Database\SQL_operate.py", line 48, in read_Dateframe
    return pd.read_sql(text_msg, con=conn)
  File "C:\Users\a046829713\Desktop\program\RLTrading\lib\site-packages\pandas\io\sql.py", line 734, in read_sql
    return pandas_sql.read_query(
  File "C:\Users\a046829713\Desktop\program\RLTrading\lib\site-packages\pandas\io\sql.py", line 1836, in read_query
    result = self.execute(sql, params)
  File "C:\Users\a046829713\Desktop\program\RLTrading\lib\site-packages\pandas\io\sql.py", line 1659, in execute
    return self.con.exec_driver_sql(sql, *args)
  File "C:\Users\a046829713\Desktop\program\RLTrading\lib\site-packages\sqlalchemy\engine\base.py", line 1779, in exec_driver_sql
    ret = self._execute_context(
  File "C:\Users\a046829713\Desktop\program\RLTrading\lib\site-packages\sqlalchemy\engine\base.py", line 1846, in _execute_context
    return self._exec_single_context(
  File "C:\Users\a046829713\Desktop\program\RLTrading\lib\site-packages\sqlalchemy\engine\base.py", line 1986, in _exec_single_context
    self._handle_dbapi_exception(
  File "C:\Users\a046829713\Desktop\program\RLTrading\lib\site-packages\sqlalchemy\engine\base.py", line 2355, in _handle_dbapi_exception
    raise sqlalchemy_exception.with_traceback(exc_info[2]) from e
  File "C:\Users\a046829713\Desktop\program\RLTrading\lib\site-packages\sqlalchemy\engine\base.py", line 1967, in _exec_single_context
    self.dialect.do_execute(
  File "C:\Users\a046829713\Desktop\program\RLTrading\lib\site-packages\sqlalchemy\engine\default.py", line 941, in do_execute
    cursor.execute(statement, parameters)
  File "C:\Users\a046829713\Desktop\program\RLTrading\lib\site-packages\pymysql\cursors.py", line 153, in execute
    result = self._query(query)
  File "C:\Users\a046829713\Desktop\program\RLTrading\lib\site-packages\pymysql\cursors.py", line 322, in _query
    conn.query(q)
  File "C:\Users\a046829713\Desktop\program\RLTrading\lib\site-packages\pymysql\connections.py", line 563, in query
    self._affected_rows = self._read_query_result(unbuffered=unbuffered)
  File "C:\Users\a046829713\Desktop\program\RLTrading\lib\site-packages\pymysql\connections.py", line 825, in _read_query_result
    result.read()
  File "C:\Users\a046829713\Desktop\program\RLTrading\lib\site-packages\pymysql\connections.py", line 1199, in read
    first_packet = self.connection._read_packet()
  File "C:\Users\a046829713\Desktop\program\RLTrading\lib\site-packages\pymysql\connections.py", line 775, in _read_packet
    packet.raise_for_error()
  File "C:\Users\a046829713\Desktop\program\RLTrading\lib\site-packages\pymysql\protocol.py", line 219, in raise_for_error
    err.raise_mysql_exception(self._data)
  File "C:\Users\a046829713\Desktop\program\RLTrading\lib\site-packages\pymysql\err.py", line 150, in raise_mysql_exception
    raise errorclass(errno, errval)
sqlalchemy.exc.ProgrammingError: (pymysql.err.ProgrammingError) (1064, "You have an error in your SQL syntax; check the manual that corresponds to your MySQL server version for the right syntax to use near 'kmnousdt-f-d' at line 1")
[SQL: kmnousdt-f-d]
(Background on this error at: https://sqlalche.me/e/20/f405)

2024-12-21 11:57 ERROR Traceback (most recent call last):
  File "C:\Users\a046829713\Desktop\program\RLTrading\lib\site-packages\sqlalchemy\engine\base.py", line 1967, in _exec_single_context
    self.dialect.do_execute(
  File "C:\Users\a046829713\Desktop\program\RLTrading\lib\site-packages\sqlalchemy\engine\default.py", line 941, in do_execute
    cursor.execute(statement, parameters)
  File "C:\Users\a046829713\Desktop\program\RLTrading\lib\site-packages\pymysql\cursors.py", line 153, in execute
    result = self._query(query)
  File "C:\Users\a046829713\Desktop\program\RLTrading\lib\site-packages\pymysql\cursors.py", line 322, in _query
    conn.query(q)
  File "C:\Users\a046829713\Desktop\program\RLTrading\lib\site-packages\pymysql\connections.py", line 563, in query
    self._affected_rows = self._read_query_result(unbuffered=unbuffered)
  File "C:\Users\a046829713\Desktop\program\RLTrading\lib\site-packages\pymysql\connections.py", line 825, in _read_query_result
    result.read()
  File "C:\Users\a046829713\Desktop\program\RLTrading\lib\site-packages\pymysql\connections.py", line 1199, in read
    first_packet = self.connection._read_packet()
  File "C:\Users\a046829713\Desktop\program\RLTrading\lib\site-packages\pymysql\connections.py", line 775, in _read_packet
    packet.raise_for_error()
  File "C:\Users\a046829713\Desktop\program\RLTrading\lib\site-packages\pymysql\protocol.py", line 219, in raise_for_error
    err.raise_mysql_exception(self._data)
  File "C:\Users\a046829713\Desktop\program\RLTrading\lib\site-packages\pymysql\err.py", line 150, in raise_mysql_exception
    raise errorclass(errno, errval)
pymysql.err.ProgrammingError: (1064, "You have an error in your SQL syntax; check the manual that corresponds to your MySQL server version for the right syntax to use near 'cgptusdt-f-d' at line 1")

The above exception was the direct cause of the following exception:

Traceback (most recent call last):
  File "C:\Users\a046829713\Desktop\program\RLTrading\SynapseX\Database\SQL_operate.py", line 48, in read_Dateframe
    return pd.read_sql(text_msg, con=conn)
  File "C:\Users\a046829713\Desktop\program\RLTrading\lib\site-packages\pandas\io\sql.py", line 734, in read_sql
    return pandas_sql.read_query(
  File "C:\Users\a046829713\Desktop\program\RLTrading\lib\site-packages\pandas\io\sql.py", line 1836, in read_query
    result = self.execute(sql, params)
  File "C:\Users\a046829713\Desktop\program\RLTrading\lib\site-packages\pandas\io\sql.py", line 1659, in execute
    return self.con.exec_driver_sql(sql, *args)
  File "C:\Users\a046829713\Desktop\program\RLTrading\lib\site-packages\sqlalchemy\engine\base.py", line 1779, in exec_driver_sql
    ret = self._execute_context(
  File "C:\Users\a046829713\Desktop\program\RLTrading\lib\site-packages\sqlalchemy\engine\base.py", line 1846, in _execute_context
    return self._exec_single_context(
  File "C:\Users\a046829713\Desktop\program\RLTrading\lib\site-packages\sqlalchemy\engine\base.py", line 1986, in _exec_single_context
    self._handle_dbapi_exception(
  File "C:\Users\a046829713\Desktop\program\RLTrading\lib\site-packages\sqlalchemy\engine\base.py", line 2355, in _handle_dbapi_exception
    raise sqlalchemy_exception.with_traceback(exc_info[2]) from e
  File "C:\Users\a046829713\Desktop\program\RLTrading\lib\site-packages\sqlalchemy\engine\base.py", line 1967, in _exec_single_context
    self.dialect.do_execute(
  File "C:\Users\a046829713\Desktop\program\RLTrading\lib\site-packages\sqlalchemy\engine\default.py", line 941, in do_execute
    cursor.execute(statement, parameters)
  File "C:\Users\a046829713\Desktop\program\RLTrading\lib\site-packages\pymysql\cursors.py", line 153, in execute
    result = self._query(query)
  File "C:\Users\a046829713\Desktop\program\RLTrading\lib\site-packages\pymysql\cursors.py", line 322, in _query
    conn.query(q)
  File "C:\Users\a046829713\Desktop\program\RLTrading\lib\site-packages\pymysql\connections.py", line 563, in query
    self._affected_rows = self._read_query_result(unbuffered=unbuffered)
  File "C:\Users\a046829713\Desktop\program\RLTrading\lib\site-packages\pymysql\connections.py", line 825, in _read_query_result
    result.read()
  File "C:\Users\a046829713\Desktop\program\RLTrading\lib\site-packages\pymysql\connections.py", line 1199, in read
    first_packet = self.connection._read_packet()
  File "C:\Users\a046829713\Desktop\program\RLTrading\lib\site-packages\pymysql\connections.py", line 775, in _read_packet
    packet.raise_for_error()
  File "C:\Users\a046829713\Desktop\program\RLTrading\lib\site-packages\pymysql\protocol.py", line 219, in raise_for_error
    err.raise_mysql_exception(self._data)
  File "C:\Users\a046829713\Desktop\program\RLTrading\lib\site-packages\pymysql\err.py", line 150, in raise_mysql_exception
    raise errorclass(errno, errval)
sqlalchemy.exc.ProgrammingError: (pymysql.err.ProgrammingError) (1064, "You have an error in your SQL syntax; check the manual that corresponds to your MySQL server version for the right syntax to use near 'cgptusdt-f-d' at line 1")
[SQL: cgptusdt-f-d]
(Background on this error at: https://sqlalche.me/e/20/f405)

