2024-10-06 21:32 ERROR Traceback (most recent call last):
  File "C:\Users\a046829713\Desktop\program\RL_trading\lib\site-packages\sqlalchemy\engine\base.py", line 1967, in _exec_single_context
    self.dialect.do_execute(
  File "C:\Users\a046829713\Desktop\program\RL_trading\lib\site-packages\sqlalchemy\engine\default.py", line 941, in do_execute
    cursor.execute(statement, parameters)
  File "C:\Users\a046829713\Desktop\program\RL_trading\lib\site-packages\pymysql\cursors.py", line 153, in execute
    result = self._query(query)
  File "C:\Users\a046829713\Desktop\program\RL_trading\lib\site-packages\pymysql\cursors.py", line 322, in _query
    conn.query(q)
  File "C:\Users\a046829713\Desktop\program\RL_trading\lib\site-packages\pymysql\connections.py", line 563, in query
    self._affected_rows = self._read_query_result(unbuffered=unbuffered)
  File "C:\Users\a046829713\Desktop\program\RL_trading\lib\site-packages\pymysql\connections.py", line 825, in _read_query_result
    result.read()
  File "C:\Users\a046829713\Desktop\program\RL_trading\lib\site-packages\pymysql\connections.py", line 1199, in read
    first_packet = self.connection._read_packet()
  File "C:\Users\a046829713\Desktop\program\RL_trading\lib\site-packages\pymysql\connections.py", line 775, in _read_packet
    packet.raise_for_error()
  File "C:\Users\a046829713\Desktop\program\RL_trading\lib\site-packages\pymysql\protocol.py", line 219, in raise_for_error
    err.raise_mysql_exception(self._data)
  File "C:\Users\a046829713\Desktop\program\RL_trading\lib\site-packages\pymysql\err.py", line 150, in raise_mysql_exception
    raise errorclass(errno, errval)
pymysql.err.ProgrammingError: (1146, "Table 'crypto_data.btcusdt-f-d' doesn't exist")

The above exception was the direct cause of the following exception:

Traceback (most recent call last):
  File "c:\Users\a046829713\Desktop\program\RL_trading\SynapseX\Database\SQL_operate.py", line 16, in get_db_data
    result = conn.execute(
  File "C:\Users\a046829713\Desktop\program\RL_trading\lib\site-packages\sqlalchemy\engine\base.py", line 1418, in execute
    return meth(
  File "C:\Users\a046829713\Desktop\program\RL_trading\lib\site-packages\sqlalchemy\sql\elements.py", line 515, in _execute_on_connection
    return connection._execute_clauseelement(
  File "C:\Users\a046829713\Desktop\program\RL_trading\lib\site-packages\sqlalchemy\engine\base.py", line 1640, in _execute_clauseelement
    ret = self._execute_context(
  File "C:\Users\a046829713\Desktop\program\RL_trading\lib\site-packages\sqlalchemy\engine\base.py", line 1846, in _execute_context
    return self._exec_single_context(
  File "C:\Users\a046829713\Desktop\program\RL_trading\lib\site-packages\sqlalchemy\engine\base.py", line 1986, in _exec_single_context
    self._handle_dbapi_exception(
  File "C:\Users\a046829713\Desktop\program\RL_trading\lib\site-packages\sqlalchemy\engine\base.py", line 2355, in _handle_dbapi_exception
    raise sqlalchemy_exception.with_traceback(exc_info[2]) from e
  File "C:\Users\a046829713\Desktop\program\RL_trading\lib\site-packages\sqlalchemy\engine\base.py", line 1967, in _exec_single_context
    self.dialect.do_execute(
  File "C:\Users\a046829713\Desktop\program\RL_trading\lib\site-packages\sqlalchemy\engine\default.py", line 941, in do_execute
    cursor.execute(statement, parameters)
  File "C:\Users\a046829713\Desktop\program\RL_trading\lib\site-packages\pymysql\cursors.py", line 153, in execute
    result = self._query(query)
  File "C:\Users\a046829713\Desktop\program\RL_trading\lib\site-packages\pymysql\cursors.py", line 322, in _query
    conn.query(q)
  File "C:\Users\a046829713\Desktop\program\RL_trading\lib\site-packages\pymysql\connections.py", line 563, in query
    self._affected_rows = self._read_query_result(unbuffered=unbuffered)
  File "C:\Users\a046829713\Desktop\program\RL_trading\lib\site-packages\pymysql\connections.py", line 825, in _read_query_result
    result.read()
  File "C:\Users\a046829713\Desktop\program\RL_trading\lib\site-packages\pymysql\connections.py", line 1199, in read
    first_packet = self.connection._read_packet()
  File "C:\Users\a046829713\Desktop\program\RL_trading\lib\site-packages\pymysql\connections.py", line 775, in _read_packet
    packet.raise_for_error()
  File "C:\Users\a046829713\Desktop\program\RL_trading\lib\site-packages\pymysql\protocol.py", line 219, in raise_for_error
    err.raise_mysql_exception(self._data)
  File "C:\Users\a046829713\Desktop\program\RL_trading\lib\site-packages\pymysql\err.py", line 150, in raise_mysql_exception
    raise errorclass(errno, errval)
sqlalchemy.exc.ProgrammingError: (pymysql.err.ProgrammingError) (1146, "Table 'crypto_data.btcusdt-f-d' doesn't exist")
[SQL: select *  from `btcusdt-f-d` order by Datetime desc limit 1]
(Background on this error at: https://sqlalche.me/e/20/f405)

2024-10-06 22:35 ERROR Traceback (most recent call last):
  File "c:\Users\a046829713\Desktop\program\RL_trading\SynapseX\TradingSysteam.py", line 307, in main
  File "c:\Users\a046829713\Desktop\program\RL_trading\SynapseX\TradingSysteam.py", line 253, in generate_order_map
    # 在底層(oderbacktest會將最後一個拋棄)
  File "c:\Users\a046829713\Desktop\program\RL_trading\SynapseX\Brain\DQN\lib\engine.py", line 29, in get_if_order_map
    re_evaluate = RL_evaluate(each_strategy)
  File "c:\Users\a046829713\Desktop\program\RL_trading\SynapseX\Brain\DQN\lib\Backtest.py", line 80, in __init__
    data = DataFeature().get_train_net_work_data_by_pd(symbol=strategy.symbol_name,
  File "c:\Users\a046829713\Desktop\program\RL_trading\SynapseX\Brain\Common\DataFeature.py", line 26, in get_train_net_work_data_by_pd
    out_dict.update({symbol: self.load_relative()})
  File "c:\Users\a046829713\Desktop\program\RL_trading\SynapseX\Brain\Common\DataFeature.py", line 91, in load_relative
    quote_av = self.calculate_current_change(np_data[:, 5])
IndexError: index 5 is out of bounds for axis 1 with size 5

2024-10-06 22:36 ERROR Traceback (most recent call last):
  File "c:\Users\a046829713\Desktop\program\RL_trading\SynapseX\TradingSysteam.py", line 308, in main
    last_status = self.generate_order_map()
  File "c:\Users\a046829713\Desktop\program\RL_trading\SynapseX\TradingSysteam.py", line 254, in generate_order_map
    if_order_map = self.DQN_engin.get_if_order_map(finally_df)
  File "c:\Users\a046829713\Desktop\program\RL_trading\SynapseX\Brain\DQN\lib\engine.py", line 29, in get_if_order_map
    re_evaluate = RL_evaluate(each_strategy)
  File "c:\Users\a046829713\Desktop\program\RL_trading\SynapseX\Brain\DQN\lib\Backtest.py", line 80, in __init__
    data = DataFeature().get_train_net_work_data_by_pd(symbol=strategy.symbol_name,
  File "c:\Users\a046829713\Desktop\program\RL_trading\SynapseX\Brain\Common\DataFeature.py", line 26, in get_train_net_work_data_by_pd
    out_dict.update({symbol: self.load_relative()})
  File "c:\Users\a046829713\Desktop\program\RL_trading\SynapseX\Brain\Common\DataFeature.py", line 91, in load_relative
    quote_av = self.calculate_current_change(np_data[:, 5])
IndexError: index 5 is out of bounds for axis 1 with size 5

2024-10-06 22:44 ERROR Traceback (most recent call last):
  File "c:\Users\a046829713\Desktop\program\RL_trading\SynapseX\TradingSysteam.py", line 308, in main
    last_status = self.generate_order_map()
  File "c:\Users\a046829713\Desktop\program\RL_trading\SynapseX\TradingSysteam.py", line 254, in generate_order_map
    if_order_map = self.DQN_engin.get_if_order_map(finally_df)
  File "c:\Users\a046829713\Desktop\program\RL_trading\SynapseX\Brain\DQN\lib\engine.py", line 29, in get_if_order_map
    re_evaluate = RL_evaluate(each_strategy)
  File "c:\Users\a046829713\Desktop\program\RL_trading\SynapseX\Brain\DQN\lib\Backtest.py", line 80, in __init__
    data = DataFeature().get_train_net_work_data_by_pd(symbol=strategy.symbol_name,
  File "c:\Users\a046829713\Desktop\program\RL_trading\SynapseX\Brain\Common\DataFeature.py", line 26, in get_train_net_work_data_by_pd
    out_dict.update({symbol: self.load_relative()})
  File "c:\Users\a046829713\Desktop\program\RL_trading\SynapseX\Brain\Common\DataFeature.py", line 91, in load_relative
    quote_av = self.calculate_current_change(np_data[:, 5])
IndexError: index 5 is out of bounds for axis 1 with size 5

2024-10-06 22:46 ERROR Traceback (most recent call last):
  File "c:\Users\a046829713\Desktop\program\RL_trading\SynapseX\TradingSysteam.py", line 308, in main
    last_status = self.generate_order_map()
  File "c:\Users\a046829713\Desktop\program\RL_trading\SynapseX\TradingSysteam.py", line 254, in generate_order_map
    if_order_map = self.DQN_engin.get_if_order_map(finally_df)
  File "c:\Users\a046829713\Desktop\program\RL_trading\SynapseX\Brain\DQN\lib\engine.py", line 29, in get_if_order_map
    re_evaluate = RL_evaluate(each_strategy)
  File "c:\Users\a046829713\Desktop\program\RL_trading\SynapseX\Brain\DQN\lib\Backtest.py", line 80, in __init__
    data = DataFeature().get_train_net_work_data_by_pd(symbol=strategy.symbol_name,
  File "c:\Users\a046829713\Desktop\program\RL_trading\SynapseX\Brain\Common\DataFeature.py", line 26, in get_train_net_work_data_by_pd
    out_dict.update({symbol: self.load_relative()})
  File "c:\Users\a046829713\Desktop\program\RL_trading\SynapseX\Brain\Common\DataFeature.py", line 91, in load_relative
    quote_av = self.calculate_current_change(np_data[:, 5])
IndexError: index 5 is out of bounds for axis 1 with size 5

2024-10-06 22:51 ERROR Unclosed client session
client_session: <aiohttp.client.ClientSession object at 0x000001C4D0DE6E00>
2024-10-06 22:51 ERROR Unclosed connector
connections: ['[(<aiohttp.client_proto.ResponseHandler object at 0x000001C4D0E1A680>, 1879568.609)]']
connector: <aiohttp.connector.TCPConnector object at 0x000001C4E47B9C60>
2024-10-06 22:51 ERROR Fatal error on SSL transport
protocol: <asyncio.sslproto.SSLProtocol object at 0x000001C4E47B9750>
transport: <_ProactorSocketTransport fd=-1 read=<_OverlappedFuture cancelled>>
Traceback (most recent call last):
  File "C:\Program Files\Python310\lib\asyncio\sslproto.py", line 690, in _process_write_backlog
    self._transport.write(chunk)
  File "C:\Program Files\Python310\lib\asyncio\proactor_events.py", line 365, in write
    self._loop_writing(data=bytes(data))
  File "C:\Program Files\Python310\lib\asyncio\proactor_events.py", line 401, in _loop_writing
    self._write_fut = self._loop._proactor.send(self._sock, data)
AttributeError: 'NoneType' object has no attribute 'send'
2024-10-06 22:56 ERROR Traceback (most recent call last):
  File "c:\Users\a046829713\Desktop\program\RL_trading\SynapseX\TradingSysteam.py", line 309, in main
    last_status = self.generate_order_map()
  File "c:\Users\a046829713\Desktop\program\RL_trading\SynapseX\TradingSysteam.py", line 255, in generate_order_map
    if_order_map = self.DQN_engin.get_if_order_map(finally_df)
  File "c:\Users\a046829713\Desktop\program\RL_trading\SynapseX\Brain\DQN\lib\engine.py", line 29, in get_if_order_map
    re_evaluate = RL_evaluate(each_strategy)
  File "c:\Users\a046829713\Desktop\program\RL_trading\SynapseX\Brain\DQN\lib\Backtest.py", line 80, in __init__
    data = DataFeature().get_train_net_work_data_by_pd(symbol=strategy.symbol_name,
  File "c:\Users\a046829713\Desktop\program\RL_trading\SynapseX\Brain\Common\DataFeature.py", line 26, in get_train_net_work_data_by_pd
    out_dict.update({symbol: self.load_relative()})
  File "c:\Users\a046829713\Desktop\program\RL_trading\SynapseX\Brain\Common\DataFeature.py", line 91, in load_relative
    quote_av = self.calculate_current_change(np_data[:, 5])
IndexError: index 5 is out of bounds for axis 1 with size 5

2024-10-06 23:01 ERROR Traceback (most recent call last):
  File "c:\Users\a046829713\Desktop\program\RL_trading\SynapseX\TradingSysteam.py", line 309, in main
    last_status = self.generate_order_map()
  File "c:\Users\a046829713\Desktop\program\RL_trading\SynapseX\TradingSysteam.py", line 255, in generate_order_map
    if_order_map = self.DQN_engin.get_if_order_map(finally_df)
  File "c:\Users\a046829713\Desktop\program\RL_trading\SynapseX\Brain\DQN\lib\engine.py", line 29, in get_if_order_map
    re_evaluate = RL_evaluate(each_strategy)
  File "c:\Users\a046829713\Desktop\program\RL_trading\SynapseX\Brain\DQN\lib\Backtest.py", line 80, in __init__
    data = DataFeature().get_train_net_work_data_by_pd(symbol=strategy.symbol_name,
  File "c:\Users\a046829713\Desktop\program\RL_trading\SynapseX\Brain\Common\DataFeature.py", line 29, in get_train_net_work_data_by_pd
    out_dict.update({symbol: self.load_relative()})
  File "c:\Users\a046829713\Desktop\program\RL_trading\SynapseX\Brain\Common\DataFeature.py", line 94, in load_relative
    quote_av = self.calculate_current_change(np_data[:, 5])
IndexError: index 5 is out of bounds for axis 1 with size 5

2024-10-06 23:03 ERROR Traceback (most recent call last):
  File "c:\Users\a046829713\Desktop\program\RL_trading\SynapseX\TradingSysteam.py", line 309, in main
    last_status = self.generate_order_map()
  File "c:\Users\a046829713\Desktop\program\RL_trading\SynapseX\TradingSysteam.py", line 255, in generate_order_map
    if_order_map = self.DQN_engin.get_if_order_map(finally_df)
  File "c:\Users\a046829713\Desktop\program\RL_trading\SynapseX\Brain\DQN\lib\engine.py", line 29, in get_if_order_map
    re_evaluate = RL_evaluate(each_strategy)
  File "c:\Users\a046829713\Desktop\program\RL_trading\SynapseX\Brain\DQN\lib\Backtest.py", line 80, in __init__
    data = DataFeature().get_train_net_work_data_by_pd(symbol=strategy.symbol_name,
  File "c:\Users\a046829713\Desktop\program\RL_trading\SynapseX\Brain\Common\DataFeature.py", line 29, in get_train_net_work_data_by_pd
    out_dict.update({symbol: self.load_relative()})
  File "c:\Users\a046829713\Desktop\program\RL_trading\SynapseX\Brain\Common\DataFeature.py", line 84, in load_relative
    np_data = np.array(self.df.values, dtype=np.float32)
ValueError: could not convert string to float: 'BTCUSDT'

2024-10-06 23:05 ERROR Traceback (most recent call last):
  File "c:\Users\a046829713\Desktop\program\RL_trading\SynapseX\TradingSysteam.py", line 309, in main
    last_status = self.generate_order_map()
  File "c:\Users\a046829713\Desktop\program\RL_trading\SynapseX\TradingSysteam.py", line 255, in generate_order_map
    if_order_map = self.DQN_engin.get_if_order_map(finally_df)
  File "c:\Users\a046829713\Desktop\program\RL_trading\SynapseX\Brain\DQN\lib\engine.py", line 26, in get_if_order_map
    each_strategy.load_Real_time_data(
  File "c:\Users\a046829713\Desktop\program\RL_trading\SynapseX\Brain\DQN\lib\Backtest.py", line 68, in load_Real_time_data
    self.df.set_index('Datetime', inplace=True)
  File "C:\Users\a046829713\Desktop\program\RL_trading\lib\site-packages\pandas\core\frame.py", line 6122, in set_index
    raise KeyError(f"None of {missing} are in the columns")
KeyError: "None of ['Datetime'] are in the columns"

2024-10-06 23:07 ERROR Traceback (most recent call last):
  File "c:\Users\a046829713\Desktop\program\RL_trading\SynapseX\TradingSysteam.py", line 309, in main
    last_status = self.generate_order_map()
  File "c:\Users\a046829713\Desktop\program\RL_trading\SynapseX\TradingSysteam.py", line 255, in generate_order_map
    if_order_map = self.DQN_engin.get_if_order_map(finally_df)
  File "c:\Users\a046829713\Desktop\program\RL_trading\SynapseX\Brain\DQN\lib\engine.py", line 29, in get_if_order_map
    re_evaluate = RL_evaluate(each_strategy)
  File "c:\Users\a046829713\Desktop\program\RL_trading\SynapseX\Brain\DQN\lib\Backtest.py", line 95, in __init__
    model_path=strategy.model_count_path)
  File "c:\Users\a046829713\Desktop\program\RL_trading\SynapseX\Brain\DQN\lib\Backtest.py", line 115, in load_model
    model_path, map_location=self.device, weights_only=True)
  File "C:\Users\a046829713\Desktop\program\RL_trading\lib\site-packages\torch\serialization.py", line 1065, in load
    with _open_file_like(f, 'rb') as opened_file:
  File "C:\Users\a046829713\Desktop\program\RL_trading\lib\site-packages\torch\serialization.py", line 468, in _open_file_like
    return _open_file(name_or_buffer, mode)
  File "C:\Users\a046829713\Desktop\program\RL_trading\lib\site-packages\torch\serialization.py", line 449, in __init__
    super().__init__(open(name, mode))
FileNotFoundError: [Errno 2] No such file or directory: 'DQN\\Meta\\Meta-300B-30K.pt'

2024-10-06 23:09 ERROR Traceback (most recent call last):
  File "c:\Users\a046829713\Desktop\program\RL_trading\SynapseX\TradingSysteam.py", line 309, in main
    last_status = self.generate_order_map()
  File "c:\Users\a046829713\Desktop\program\RL_trading\SynapseX\TradingSysteam.py", line 247, in generate_order_map
    self.DQN_engin.strategy_prepare(self.targetsymbols)
  File "c:\Users\a046829713\Desktop\program\RL_trading\SynapseX\Brain\DQN\lib\engine.py", line 61, in strategy_prepare
    self.strategys.append(self.create_strategy(Meta_model_path, symbol=symbol))
  File "c:\Users\a046829713\Desktop\program\RL_trading\SynapseX\Brain\DQN\lib\engine.py", line 42, in create_strategy
    strategytype, _, symbol_from_path = info.split(os.sep)
ValueError: too many values to unpack (expected 3)

2024-10-06 23:11 ERROR Traceback (most recent call last):
  File "c:\Users\a046829713\Desktop\program\RL_trading\SynapseX\TradingSysteam.py", line 309, in main
    last_status = self.generate_order_map()
  File "c:\Users\a046829713\Desktop\program\RL_trading\SynapseX\TradingSysteam.py", line 247, in generate_order_map
    self.DQN_engin.strategy_prepare(self.targetsymbols)
  File "c:\Users\a046829713\Desktop\program\RL_trading\SynapseX\Brain\DQN\lib\engine.py", line 62, in strategy_prepare
    self.strategys.append(self.create_strategy(Meta_model_path, symbol=symbol))
  File "c:\Users\a046829713\Desktop\program\RL_trading\SynapseX\Brain\DQN\lib\engine.py", line 43, in create_strategy
    strategytype, _, symbol_from_path = info.split(os.sep)
ValueError: too many values to unpack (expected 3)

2024-10-06 23:13 ERROR Traceback (most recent call last):
  File "c:\Users\a046829713\Desktop\program\RL_trading\SynapseX\TradingSysteam.py", line 309, in main
    last_status = self.generate_order_map()
  File "c:\Users\a046829713\Desktop\program\RL_trading\SynapseX\TradingSysteam.py", line 255, in generate_order_map
    if_order_map = self.DQN_engin.get_if_order_map(finally_df)
  File "c:\Users\a046829713\Desktop\program\RL_trading\SynapseX\Brain\DQN\lib\engine.py", line 29, in get_if_order_map
    re_evaluate = RL_evaluate(each_strategy)
  File "c:\Users\a046829713\Desktop\program\RL_trading\SynapseX\Brain\DQN\lib\Backtest.py", line 94, in __init__
    self.agent = self.load_model(
  File "c:\Users\a046829713\Desktop\program\RL_trading\SynapseX\Brain\DQN\lib\Backtest.py", line 117, in load_model
    model.load_state_dict(checkpoint['model_state_dict'])
  File "C:\Users\a046829713\Desktop\program\RL_trading\lib\site-packages\torch\nn\modules\module.py", line 2215, in load_state_dict
    raise RuntimeError('Error(s) in loading state_dict for {}:\n\t{}'.format(
RuntimeError: Error(s) in loading state_dict for TransformerDuelingModel:
	size mismatch for embedding.0.weight: copying a param with shape torch.Size([64, 15]) from checkpoint, the shape in current model is torch.Size([64, 16]).

2024-10-06 23:15 ERROR Traceback (most recent call last):
  File "c:\Users\a046829713\Desktop\program\RL_trading\SynapseX\TradingSysteam.py", line 309, in main
    last_status = self.generate_order_map()
  File "c:\Users\a046829713\Desktop\program\RL_trading\SynapseX\TradingSysteam.py", line 255, in generate_order_map
    if_order_map = self.DQN_engin.get_if_order_map(finally_df)
  File "c:\Users\a046829713\Desktop\program\RL_trading\SynapseX\Brain\DQN\lib\engine.py", line 30, in get_if_order_map
    info = Backtest(re_evaluate, each_strategy).order_becktest(
TypeError: Backtest.order_becktest() got multiple values for argument 'ifplot'

2024-10-06 23:20 ERROR Traceback (most recent call last):
  File "c:\Users\a046829713\Desktop\program\RL_trading\SynapseX\TradingSysteam.py", line 309, in main
    last_status = self.generate_order_map()
  File "c:\Users\a046829713\Desktop\program\RL_trading\SynapseX\TradingSysteam.py", line 255, in generate_order_map
    if_order_map = self.DQN_engin.get_if_order_map(finally_df)
  File "c:\Users\a046829713\Desktop\program\RL_trading\SynapseX\Brain\DQN\lib\engine.py", line 30, in get_if_order_map
    info = Backtest(re_evaluate, each_strategy).order_becktest(
TypeError: Backtest.order_becktest() got multiple values for argument 'ifplot'

2024-10-06 23:23 ERROR Traceback (most recent call last):
  File "c:\Users\a046829713\Desktop\program\RL_trading\SynapseX\TradingSysteam.py", line 309, in main
    last_status = self.generate_order_map()
  File "c:\Users\a046829713\Desktop\program\RL_trading\SynapseX\TradingSysteam.py", line 255, in generate_order_map
    if_order_map = self.DQN_engin.get_if_order_map(finally_df)
  File "c:\Users\a046829713\Desktop\program\RL_trading\SynapseX\Brain\DQN\lib\engine.py", line 33, in get_if_order_map
    info = Backtest(re_evaluate, each_strategy).order_becktest(
TypeError: Backtest.order_becktest() got multiple values for argument 'ifplot'

2024-10-06 23:25 ERROR Traceback (most recent call last):
  File "c:\Users\a046829713\Desktop\program\RL_trading\SynapseX\TradingSysteam.py", line 325, in main
    self.dataprovider.Binanceapp.execute_orders(
  File "c:\Users\a046829713\Desktop\program\RL_trading\SynapseX\Major\custom.py", line 59, in wrapper
    result = func(self, client, *new_args, **new_kwargs)
  File "c:\Users\a046829713\Desktop\program\RL_trading\SynapseX\Major\custom.py", line 500, in execute_orders
    if (float(current_size[each_symbol]) + ready_to_order_size) * symbol_map[each_symbol]['Close'].iloc[-1] < float(Response['maxNotionalValue']):
KeyError: 'SOLUSDT'

