2025-09-08 23:12 ERROR Traceback (most recent call last):
  File "/home/b0457812963/MambaRL/lib/python3.12/site-packages/sqlalchemy/engine/base.py", line 1967, in _exec_single_context
    self.dialect.do_execute(
  File "/home/b0457812963/MambaRL/lib/python3.12/site-packages/sqlalchemy/engine/default.py", line 941, in do_execute
    cursor.execute(statement, parameters)
  File "/home/b0457812963/MambaRL/lib/python3.12/site-packages/pymysql/cursors.py", line 153, in execute
    result = self._query(query)
             ^^^^^^^^^^^^^^^^^^
  File "/home/b0457812963/MambaRL/lib/python3.12/site-packages/pymysql/cursors.py", line 322, in _query
    conn.query(q)
  File "/home/b0457812963/MambaRL/lib/python3.12/site-packages/pymysql/connections.py", line 563, in query
    self._affected_rows = self._read_query_result(unbuffered=unbuffered)
                          ^^^^^^^^^^^^^^^^^^^^^^^^^^^^^^^^^^^^^^^^^^^^^^
  File "/home/b0457812963/MambaRL/lib/python3.12/site-packages/pymysql/connections.py", line 825, in _read_query_result
    result.read()
  File "/home/b0457812963/MambaRL/lib/python3.12/site-packages/pymysql/connections.py", line 1199, in read
    first_packet = self.connection._read_packet()
                   ^^^^^^^^^^^^^^^^^^^^^^^^^^^^^^
  File "/home/b0457812963/MambaRL/lib/python3.12/site-packages/pymysql/connections.py", line 775, in _read_packet
    packet.raise_for_error()
  File "/home/b0457812963/MambaRL/lib/python3.12/site-packages/pymysql/protocol.py", line 219, in raise_for_error
    err.raise_mysql_exception(self._data)
  File "/home/b0457812963/MambaRL/lib/python3.12/site-packages/pymysql/err.py", line 150, in raise_mysql_exception
    raise errorclass(errno, errval)
pymysql.err.ProgrammingError: (1064, "You have an error in your SQL syntax; check the manual that corresponds to your MySQL server version for the right syntax to use near 'xplusdt-f-d' at line 1")

The above exception was the direct cause of the following exception:

Traceback (most recent call last):
  File "/home/b0457812963/MambaRL/SynapseX/Database/SQL_operate.py", line 48, in read_Dateframe
    return pd.read_sql(text_msg, con=conn)
           ^^^^^^^^^^^^^^^^^^^^^^^^^^^^^^^
  File "/home/b0457812963/MambaRL/lib/python3.12/site-packages/pandas/io/sql.py", line 734, in read_sql
    return pandas_sql.read_query(
           ^^^^^^^^^^^^^^^^^^^^^^
  File "/home/b0457812963/MambaRL/lib/python3.12/site-packages/pandas/io/sql.py", line 1836, in read_query
    result = self.execute(sql, params)
             ^^^^^^^^^^^^^^^^^^^^^^^^^
  File "/home/b0457812963/MambaRL/lib/python3.12/site-packages/pandas/io/sql.py", line 1659, in execute
    return self.con.exec_driver_sql(sql, *args)
           ^^^^^^^^^^^^^^^^^^^^^^^^^^^^^^^^^^^^
  File "/home/b0457812963/MambaRL/lib/python3.12/site-packages/sqlalchemy/engine/base.py", line 1779, in exec_driver_sql
    ret = self._execute_context(
          ^^^^^^^^^^^^^^^^^^^^^^
  File "/home/b0457812963/MambaRL/lib/python3.12/site-packages/sqlalchemy/engine/base.py", line 1846, in _execute_context
    return self._exec_single_context(
           ^^^^^^^^^^^^^^^^^^^^^^^^^^
  File "/home/b0457812963/MambaRL/lib/python3.12/site-packages/sqlalchemy/engine/base.py", line 1986, in _exec_single_context
    self._handle_dbapi_exception(
  File "/home/b0457812963/MambaRL/lib/python3.12/site-packages/sqlalchemy/engine/base.py", line 2355, in _handle_dbapi_exception
    raise sqlalchemy_exception.with_traceback(exc_info[2]) from e
  File "/home/b0457812963/MambaRL/lib/python3.12/site-packages/sqlalchemy/engine/base.py", line 1967, in _exec_single_context
    self.dialect.do_execute(
  File "/home/b0457812963/MambaRL/lib/python3.12/site-packages/sqlalchemy/engine/default.py", line 941, in do_execute
    cursor.execute(statement, parameters)
  File "/home/b0457812963/MambaRL/lib/python3.12/site-packages/pymysql/cursors.py", line 153, in execute
    result = self._query(query)
             ^^^^^^^^^^^^^^^^^^
  File "/home/b0457812963/MambaRL/lib/python3.12/site-packages/pymysql/cursors.py", line 322, in _query
    conn.query(q)
  File "/home/b0457812963/MambaRL/lib/python3.12/site-packages/pymysql/connections.py", line 563, in query
    self._affected_rows = self._read_query_result(unbuffered=unbuffered)
                          ^^^^^^^^^^^^^^^^^^^^^^^^^^^^^^^^^^^^^^^^^^^^^^
  File "/home/b0457812963/MambaRL/lib/python3.12/site-packages/pymysql/connections.py", line 825, in _read_query_result
    result.read()
  File "/home/b0457812963/MambaRL/lib/python3.12/site-packages/pymysql/connections.py", line 1199, in read
    first_packet = self.connection._read_packet()
                   ^^^^^^^^^^^^^^^^^^^^^^^^^^^^^^
  File "/home/b0457812963/MambaRL/lib/python3.12/site-packages/pymysql/connections.py", line 775, in _read_packet
    packet.raise_for_error()
  File "/home/b0457812963/MambaRL/lib/python3.12/site-packages/pymysql/protocol.py", line 219, in raise_for_error
    err.raise_mysql_exception(self._data)
  File "/home/b0457812963/MambaRL/lib/python3.12/site-packages/pymysql/err.py", line 150, in raise_mysql_exception
    raise errorclass(errno, errval)
sqlalchemy.exc.ProgrammingError: (pymysql.err.ProgrammingError) (1064, "You have an error in your SQL syntax; check the manual that corresponds to your MySQL server version for the right syntax to use near 'xplusdt-f-d' at line 1")
[SQL: xplusdt-f-d]
(Background on this error at: https://sqlalche.me/e/20/f405)

2025-09-08 23:12 ERROR Traceback (most recent call last):
  File "/home/b0457812963/MambaRL/lib/python3.12/site-packages/sqlalchemy/engine/base.py", line 1967, in _exec_single_context
    self.dialect.do_execute(
  File "/home/b0457812963/MambaRL/lib/python3.12/site-packages/sqlalchemy/engine/default.py", line 941, in do_execute
    cursor.execute(statement, parameters)
  File "/home/b0457812963/MambaRL/lib/python3.12/site-packages/pymysql/cursors.py", line 153, in execute
    result = self._query(query)
             ^^^^^^^^^^^^^^^^^^
  File "/home/b0457812963/MambaRL/lib/python3.12/site-packages/pymysql/cursors.py", line 322, in _query
    conn.query(q)
  File "/home/b0457812963/MambaRL/lib/python3.12/site-packages/pymysql/connections.py", line 563, in query
    self._affected_rows = self._read_query_result(unbuffered=unbuffered)
                          ^^^^^^^^^^^^^^^^^^^^^^^^^^^^^^^^^^^^^^^^^^^^^^
  File "/home/b0457812963/MambaRL/lib/python3.12/site-packages/pymysql/connections.py", line 825, in _read_query_result
    result.read()
  File "/home/b0457812963/MambaRL/lib/python3.12/site-packages/pymysql/connections.py", line 1199, in read
    first_packet = self.connection._read_packet()
                   ^^^^^^^^^^^^^^^^^^^^^^^^^^^^^^
  File "/home/b0457812963/MambaRL/lib/python3.12/site-packages/pymysql/connections.py", line 775, in _read_packet
    packet.raise_for_error()
  File "/home/b0457812963/MambaRL/lib/python3.12/site-packages/pymysql/protocol.py", line 219, in raise_for_error
    err.raise_mysql_exception(self._data)
  File "/home/b0457812963/MambaRL/lib/python3.12/site-packages/pymysql/err.py", line 150, in raise_mysql_exception
    raise errorclass(errno, errval)
pymysql.err.ProgrammingError: (1064, "You have an error in your SQL syntax; check the manual that corresponds to your MySQL server version for the right syntax to use near 'wlfiusdt-f-d' at line 1")

The above exception was the direct cause of the following exception:

Traceback (most recent call last):
  File "/home/b0457812963/MambaRL/SynapseX/Database/SQL_operate.py", line 48, in read_Dateframe
    return pd.read_sql(text_msg, con=conn)
           ^^^^^^^^^^^^^^^^^^^^^^^^^^^^^^^
  File "/home/b0457812963/MambaRL/lib/python3.12/site-packages/pandas/io/sql.py", line 734, in read_sql
    return pandas_sql.read_query(
           ^^^^^^^^^^^^^^^^^^^^^^
  File "/home/b0457812963/MambaRL/lib/python3.12/site-packages/pandas/io/sql.py", line 1836, in read_query
    result = self.execute(sql, params)
             ^^^^^^^^^^^^^^^^^^^^^^^^^
  File "/home/b0457812963/MambaRL/lib/python3.12/site-packages/pandas/io/sql.py", line 1659, in execute
    return self.con.exec_driver_sql(sql, *args)
           ^^^^^^^^^^^^^^^^^^^^^^^^^^^^^^^^^^^^
  File "/home/b0457812963/MambaRL/lib/python3.12/site-packages/sqlalchemy/engine/base.py", line 1779, in exec_driver_sql
    ret = self._execute_context(
          ^^^^^^^^^^^^^^^^^^^^^^
  File "/home/b0457812963/MambaRL/lib/python3.12/site-packages/sqlalchemy/engine/base.py", line 1846, in _execute_context
    return self._exec_single_context(
           ^^^^^^^^^^^^^^^^^^^^^^^^^^
  File "/home/b0457812963/MambaRL/lib/python3.12/site-packages/sqlalchemy/engine/base.py", line 1986, in _exec_single_context
    self._handle_dbapi_exception(
  File "/home/b0457812963/MambaRL/lib/python3.12/site-packages/sqlalchemy/engine/base.py", line 2355, in _handle_dbapi_exception
    raise sqlalchemy_exception.with_traceback(exc_info[2]) from e
  File "/home/b0457812963/MambaRL/lib/python3.12/site-packages/sqlalchemy/engine/base.py", line 1967, in _exec_single_context
    self.dialect.do_execute(
  File "/home/b0457812963/MambaRL/lib/python3.12/site-packages/sqlalchemy/engine/default.py", line 941, in do_execute
    cursor.execute(statement, parameters)
  File "/home/b0457812963/MambaRL/lib/python3.12/site-packages/pymysql/cursors.py", line 153, in execute
    result = self._query(query)
             ^^^^^^^^^^^^^^^^^^
  File "/home/b0457812963/MambaRL/lib/python3.12/site-packages/pymysql/cursors.py", line 322, in _query
    conn.query(q)
  File "/home/b0457812963/MambaRL/lib/python3.12/site-packages/pymysql/connections.py", line 563, in query
    self._affected_rows = self._read_query_result(unbuffered=unbuffered)
                          ^^^^^^^^^^^^^^^^^^^^^^^^^^^^^^^^^^^^^^^^^^^^^^
  File "/home/b0457812963/MambaRL/lib/python3.12/site-packages/pymysql/connections.py", line 825, in _read_query_result
    result.read()
  File "/home/b0457812963/MambaRL/lib/python3.12/site-packages/pymysql/connections.py", line 1199, in read
    first_packet = self.connection._read_packet()
                   ^^^^^^^^^^^^^^^^^^^^^^^^^^^^^^
  File "/home/b0457812963/MambaRL/lib/python3.12/site-packages/pymysql/connections.py", line 775, in _read_packet
    packet.raise_for_error()
  File "/home/b0457812963/MambaRL/lib/python3.12/site-packages/pymysql/protocol.py", line 219, in raise_for_error
    err.raise_mysql_exception(self._data)
  File "/home/b0457812963/MambaRL/lib/python3.12/site-packages/pymysql/err.py", line 150, in raise_mysql_exception
    raise errorclass(errno, errval)
sqlalchemy.exc.ProgrammingError: (pymysql.err.ProgrammingError) (1064, "You have an error in your SQL syntax; check the manual that corresponds to your MySQL server version for the right syntax to use near 'wlfiusdt-f-d' at line 1")
[SQL: wlfiusdt-f-d]
(Background on this error at: https://sqlalche.me/e/20/f405)

2025-09-08 23:12 ERROR Traceback (most recent call last):
  File "/home/b0457812963/MambaRL/lib/python3.12/site-packages/sqlalchemy/engine/base.py", line 1967, in _exec_single_context
    self.dialect.do_execute(
  File "/home/b0457812963/MambaRL/lib/python3.12/site-packages/sqlalchemy/engine/default.py", line 941, in do_execute
    cursor.execute(statement, parameters)
  File "/home/b0457812963/MambaRL/lib/python3.12/site-packages/pymysql/cursors.py", line 153, in execute
    result = self._query(query)
             ^^^^^^^^^^^^^^^^^^
  File "/home/b0457812963/MambaRL/lib/python3.12/site-packages/pymysql/cursors.py", line 322, in _query
    conn.query(q)
  File "/home/b0457812963/MambaRL/lib/python3.12/site-packages/pymysql/connections.py", line 563, in query
    self._affected_rows = self._read_query_result(unbuffered=unbuffered)
                          ^^^^^^^^^^^^^^^^^^^^^^^^^^^^^^^^^^^^^^^^^^^^^^
  File "/home/b0457812963/MambaRL/lib/python3.12/site-packages/pymysql/connections.py", line 825, in _read_query_result
    result.read()
  File "/home/b0457812963/MambaRL/lib/python3.12/site-packages/pymysql/connections.py", line 1199, in read
    first_packet = self.connection._read_packet()
                   ^^^^^^^^^^^^^^^^^^^^^^^^^^^^^^
  File "/home/b0457812963/MambaRL/lib/python3.12/site-packages/pymysql/connections.py", line 775, in _read_packet
    packet.raise_for_error()
  File "/home/b0457812963/MambaRL/lib/python3.12/site-packages/pymysql/protocol.py", line 219, in raise_for_error
    err.raise_mysql_exception(self._data)
  File "/home/b0457812963/MambaRL/lib/python3.12/site-packages/pymysql/err.py", line 150, in raise_mysql_exception
    raise errorclass(errno, errval)
pymysql.err.ProgrammingError: (1064, "You have an error in your SQL syntax; check the manual that corresponds to your MySQL server version for the right syntax to use near 'somiusdt-f-d' at line 1")

The above exception was the direct cause of the following exception:

Traceback (most recent call last):
  File "/home/b0457812963/MambaRL/SynapseX/Database/SQL_operate.py", line 48, in read_Dateframe
    return pd.read_sql(text_msg, con=conn)
           ^^^^^^^^^^^^^^^^^^^^^^^^^^^^^^^
  File "/home/b0457812963/MambaRL/lib/python3.12/site-packages/pandas/io/sql.py", line 734, in read_sql
    return pandas_sql.read_query(
           ^^^^^^^^^^^^^^^^^^^^^^
  File "/home/b0457812963/MambaRL/lib/python3.12/site-packages/pandas/io/sql.py", line 1836, in read_query
    result = self.execute(sql, params)
             ^^^^^^^^^^^^^^^^^^^^^^^^^
  File "/home/b0457812963/MambaRL/lib/python3.12/site-packages/pandas/io/sql.py", line 1659, in execute
    return self.con.exec_driver_sql(sql, *args)
           ^^^^^^^^^^^^^^^^^^^^^^^^^^^^^^^^^^^^
  File "/home/b0457812963/MambaRL/lib/python3.12/site-packages/sqlalchemy/engine/base.py", line 1779, in exec_driver_sql
    ret = self._execute_context(
          ^^^^^^^^^^^^^^^^^^^^^^
  File "/home/b0457812963/MambaRL/lib/python3.12/site-packages/sqlalchemy/engine/base.py", line 1846, in _execute_context
    return self._exec_single_context(
           ^^^^^^^^^^^^^^^^^^^^^^^^^^
  File "/home/b0457812963/MambaRL/lib/python3.12/site-packages/sqlalchemy/engine/base.py", line 1986, in _exec_single_context
    self._handle_dbapi_exception(
  File "/home/b0457812963/MambaRL/lib/python3.12/site-packages/sqlalchemy/engine/base.py", line 2355, in _handle_dbapi_exception
    raise sqlalchemy_exception.with_traceback(exc_info[2]) from e
  File "/home/b0457812963/MambaRL/lib/python3.12/site-packages/sqlalchemy/engine/base.py", line 1967, in _exec_single_context
    self.dialect.do_execute(
  File "/home/b0457812963/MambaRL/lib/python3.12/site-packages/sqlalchemy/engine/default.py", line 941, in do_execute
    cursor.execute(statement, parameters)
  File "/home/b0457812963/MambaRL/lib/python3.12/site-packages/pymysql/cursors.py", line 153, in execute
    result = self._query(query)
             ^^^^^^^^^^^^^^^^^^
  File "/home/b0457812963/MambaRL/lib/python3.12/site-packages/pymysql/cursors.py", line 322, in _query
    conn.query(q)
  File "/home/b0457812963/MambaRL/lib/python3.12/site-packages/pymysql/connections.py", line 563, in query
    self._affected_rows = self._read_query_result(unbuffered=unbuffered)
                          ^^^^^^^^^^^^^^^^^^^^^^^^^^^^^^^^^^^^^^^^^^^^^^
  File "/home/b0457812963/MambaRL/lib/python3.12/site-packages/pymysql/connections.py", line 825, in _read_query_result
    result.read()
  File "/home/b0457812963/MambaRL/lib/python3.12/site-packages/pymysql/connections.py", line 1199, in read
    first_packet = self.connection._read_packet()
                   ^^^^^^^^^^^^^^^^^^^^^^^^^^^^^^
  File "/home/b0457812963/MambaRL/lib/python3.12/site-packages/pymysql/connections.py", line 775, in _read_packet
    packet.raise_for_error()
  File "/home/b0457812963/MambaRL/lib/python3.12/site-packages/pymysql/protocol.py", line 219, in raise_for_error
    err.raise_mysql_exception(self._data)
  File "/home/b0457812963/MambaRL/lib/python3.12/site-packages/pymysql/err.py", line 150, in raise_mysql_exception
    raise errorclass(errno, errval)
sqlalchemy.exc.ProgrammingError: (pymysql.err.ProgrammingError) (1064, "You have an error in your SQL syntax; check the manual that corresponds to your MySQL server version for the right syntax to use near 'somiusdt-f-d' at line 1")
[SQL: somiusdt-f-d]
(Background on this error at: https://sqlalche.me/e/20/f405)

2025-09-08 23:12 ERROR Traceback (most recent call last):
  File "/home/b0457812963/MambaRL/lib/python3.12/site-packages/sqlalchemy/engine/base.py", line 1967, in _exec_single_context
    self.dialect.do_execute(
  File "/home/b0457812963/MambaRL/lib/python3.12/site-packages/sqlalchemy/engine/default.py", line 941, in do_execute
    cursor.execute(statement, parameters)
  File "/home/b0457812963/MambaRL/lib/python3.12/site-packages/pymysql/cursors.py", line 153, in execute
    result = self._query(query)
             ^^^^^^^^^^^^^^^^^^
  File "/home/b0457812963/MambaRL/lib/python3.12/site-packages/pymysql/cursors.py", line 322, in _query
    conn.query(q)
  File "/home/b0457812963/MambaRL/lib/python3.12/site-packages/pymysql/connections.py", line 563, in query
    self._affected_rows = self._read_query_result(unbuffered=unbuffered)
                          ^^^^^^^^^^^^^^^^^^^^^^^^^^^^^^^^^^^^^^^^^^^^^^
  File "/home/b0457812963/MambaRL/lib/python3.12/site-packages/pymysql/connections.py", line 825, in _read_query_result
    result.read()
  File "/home/b0457812963/MambaRL/lib/python3.12/site-packages/pymysql/connections.py", line 1199, in read
    first_packet = self.connection._read_packet()
                   ^^^^^^^^^^^^^^^^^^^^^^^^^^^^^^
  File "/home/b0457812963/MambaRL/lib/python3.12/site-packages/pymysql/connections.py", line 775, in _read_packet
    packet.raise_for_error()
  File "/home/b0457812963/MambaRL/lib/python3.12/site-packages/pymysql/protocol.py", line 219, in raise_for_error
    err.raise_mysql_exception(self._data)
  File "/home/b0457812963/MambaRL/lib/python3.12/site-packages/pymysql/err.py", line 150, in raise_mysql_exception
    raise errorclass(errno, errval)
pymysql.err.ProgrammingError: (1064, "You have an error in your SQL syntax; check the manual that corresponds to your MySQL server version for the right syntax to use near 'basusdt-f-d' at line 1")

The above exception was the direct cause of the following exception:

Traceback (most recent call last):
  File "/home/b0457812963/MambaRL/SynapseX/Database/SQL_operate.py", line 48, in read_Dateframe
    return pd.read_sql(text_msg, con=conn)
           ^^^^^^^^^^^^^^^^^^^^^^^^^^^^^^^
  File "/home/b0457812963/MambaRL/lib/python3.12/site-packages/pandas/io/sql.py", line 734, in read_sql
    return pandas_sql.read_query(
           ^^^^^^^^^^^^^^^^^^^^^^
  File "/home/b0457812963/MambaRL/lib/python3.12/site-packages/pandas/io/sql.py", line 1836, in read_query
    result = self.execute(sql, params)
             ^^^^^^^^^^^^^^^^^^^^^^^^^
  File "/home/b0457812963/MambaRL/lib/python3.12/site-packages/pandas/io/sql.py", line 1659, in execute
    return self.con.exec_driver_sql(sql, *args)
           ^^^^^^^^^^^^^^^^^^^^^^^^^^^^^^^^^^^^
  File "/home/b0457812963/MambaRL/lib/python3.12/site-packages/sqlalchemy/engine/base.py", line 1779, in exec_driver_sql
    ret = self._execute_context(
          ^^^^^^^^^^^^^^^^^^^^^^
  File "/home/b0457812963/MambaRL/lib/python3.12/site-packages/sqlalchemy/engine/base.py", line 1846, in _execute_context
    return self._exec_single_context(
           ^^^^^^^^^^^^^^^^^^^^^^^^^^
  File "/home/b0457812963/MambaRL/lib/python3.12/site-packages/sqlalchemy/engine/base.py", line 1986, in _exec_single_context
    self._handle_dbapi_exception(
  File "/home/b0457812963/MambaRL/lib/python3.12/site-packages/sqlalchemy/engine/base.py", line 2355, in _handle_dbapi_exception
    raise sqlalchemy_exception.with_traceback(exc_info[2]) from e
  File "/home/b0457812963/MambaRL/lib/python3.12/site-packages/sqlalchemy/engine/base.py", line 1967, in _exec_single_context
    self.dialect.do_execute(
  File "/home/b0457812963/MambaRL/lib/python3.12/site-packages/sqlalchemy/engine/default.py", line 941, in do_execute
    cursor.execute(statement, parameters)
  File "/home/b0457812963/MambaRL/lib/python3.12/site-packages/pymysql/cursors.py", line 153, in execute
    result = self._query(query)
             ^^^^^^^^^^^^^^^^^^
  File "/home/b0457812963/MambaRL/lib/python3.12/site-packages/pymysql/cursors.py", line 322, in _query
    conn.query(q)
  File "/home/b0457812963/MambaRL/lib/python3.12/site-packages/pymysql/connections.py", line 563, in query
    self._affected_rows = self._read_query_result(unbuffered=unbuffered)
                          ^^^^^^^^^^^^^^^^^^^^^^^^^^^^^^^^^^^^^^^^^^^^^^
  File "/home/b0457812963/MambaRL/lib/python3.12/site-packages/pymysql/connections.py", line 825, in _read_query_result
    result.read()
  File "/home/b0457812963/MambaRL/lib/python3.12/site-packages/pymysql/connections.py", line 1199, in read
    first_packet = self.connection._read_packet()
                   ^^^^^^^^^^^^^^^^^^^^^^^^^^^^^^
  File "/home/b0457812963/MambaRL/lib/python3.12/site-packages/pymysql/connections.py", line 775, in _read_packet
    packet.raise_for_error()
  File "/home/b0457812963/MambaRL/lib/python3.12/site-packages/pymysql/protocol.py", line 219, in raise_for_error
    err.raise_mysql_exception(self._data)
  File "/home/b0457812963/MambaRL/lib/python3.12/site-packages/pymysql/err.py", line 150, in raise_mysql_exception
    raise errorclass(errno, errval)
sqlalchemy.exc.ProgrammingError: (pymysql.err.ProgrammingError) (1064, "You have an error in your SQL syntax; check the manual that corresponds to your MySQL server version for the right syntax to use near 'basusdt-f-d' at line 1")
[SQL: basusdt-f-d]
(Background on this error at: https://sqlalche.me/e/20/f405)

2025-09-08 23:12 ERROR Traceback (most recent call last):
  File "/home/b0457812963/MambaRL/lib/python3.12/site-packages/sqlalchemy/engine/base.py", line 1967, in _exec_single_context
    self.dialect.do_execute(
  File "/home/b0457812963/MambaRL/lib/python3.12/site-packages/sqlalchemy/engine/default.py", line 941, in do_execute
    cursor.execute(statement, parameters)
  File "/home/b0457812963/MambaRL/lib/python3.12/site-packages/pymysql/cursors.py", line 153, in execute
    result = self._query(query)
             ^^^^^^^^^^^^^^^^^^
  File "/home/b0457812963/MambaRL/lib/python3.12/site-packages/pymysql/cursors.py", line 322, in _query
    conn.query(q)
  File "/home/b0457812963/MambaRL/lib/python3.12/site-packages/pymysql/connections.py", line 563, in query
    self._affected_rows = self._read_query_result(unbuffered=unbuffered)
                          ^^^^^^^^^^^^^^^^^^^^^^^^^^^^^^^^^^^^^^^^^^^^^^
  File "/home/b0457812963/MambaRL/lib/python3.12/site-packages/pymysql/connections.py", line 825, in _read_query_result
    result.read()
  File "/home/b0457812963/MambaRL/lib/python3.12/site-packages/pymysql/connections.py", line 1199, in read
    first_packet = self.connection._read_packet()
                   ^^^^^^^^^^^^^^^^^^^^^^^^^^^^^^
  File "/home/b0457812963/MambaRL/lib/python3.12/site-packages/pymysql/connections.py", line 775, in _read_packet
    packet.raise_for_error()
  File "/home/b0457812963/MambaRL/lib/python3.12/site-packages/pymysql/protocol.py", line 219, in raise_for_error
    err.raise_mysql_exception(self._data)
  File "/home/b0457812963/MambaRL/lib/python3.12/site-packages/pymysql/err.py", line 150, in raise_mysql_exception
    raise errorclass(errno, errval)
pymysql.err.ProgrammingError: (1064, "You have an error in your SQL syntax; check the manual that corresponds to your MySQL server version for the right syntax to use near 'btrusdt-f-d' at line 1")

The above exception was the direct cause of the following exception:

Traceback (most recent call last):
  File "/home/b0457812963/MambaRL/SynapseX/Database/SQL_operate.py", line 48, in read_Dateframe
    return pd.read_sql(text_msg, con=conn)
           ^^^^^^^^^^^^^^^^^^^^^^^^^^^^^^^
  File "/home/b0457812963/MambaRL/lib/python3.12/site-packages/pandas/io/sql.py", line 734, in read_sql
    return pandas_sql.read_query(
           ^^^^^^^^^^^^^^^^^^^^^^
  File "/home/b0457812963/MambaRL/lib/python3.12/site-packages/pandas/io/sql.py", line 1836, in read_query
    result = self.execute(sql, params)
             ^^^^^^^^^^^^^^^^^^^^^^^^^
  File "/home/b0457812963/MambaRL/lib/python3.12/site-packages/pandas/io/sql.py", line 1659, in execute
    return self.con.exec_driver_sql(sql, *args)
           ^^^^^^^^^^^^^^^^^^^^^^^^^^^^^^^^^^^^
  File "/home/b0457812963/MambaRL/lib/python3.12/site-packages/sqlalchemy/engine/base.py", line 1779, in exec_driver_sql
    ret = self._execute_context(
          ^^^^^^^^^^^^^^^^^^^^^^
  File "/home/b0457812963/MambaRL/lib/python3.12/site-packages/sqlalchemy/engine/base.py", line 1846, in _execute_context
    return self._exec_single_context(
           ^^^^^^^^^^^^^^^^^^^^^^^^^^
  File "/home/b0457812963/MambaRL/lib/python3.12/site-packages/sqlalchemy/engine/base.py", line 1986, in _exec_single_context
    self._handle_dbapi_exception(
  File "/home/b0457812963/MambaRL/lib/python3.12/site-packages/sqlalchemy/engine/base.py", line 2355, in _handle_dbapi_exception
    raise sqlalchemy_exception.with_traceback(exc_info[2]) from e
  File "/home/b0457812963/MambaRL/lib/python3.12/site-packages/sqlalchemy/engine/base.py", line 1967, in _exec_single_context
    self.dialect.do_execute(
  File "/home/b0457812963/MambaRL/lib/python3.12/site-packages/sqlalchemy/engine/default.py", line 941, in do_execute
    cursor.execute(statement, parameters)
  File "/home/b0457812963/MambaRL/lib/python3.12/site-packages/pymysql/cursors.py", line 153, in execute
    result = self._query(query)
             ^^^^^^^^^^^^^^^^^^
  File "/home/b0457812963/MambaRL/lib/python3.12/site-packages/pymysql/cursors.py", line 322, in _query
    conn.query(q)
  File "/home/b0457812963/MambaRL/lib/python3.12/site-packages/pymysql/connections.py", line 563, in query
    self._affected_rows = self._read_query_result(unbuffered=unbuffered)
                          ^^^^^^^^^^^^^^^^^^^^^^^^^^^^^^^^^^^^^^^^^^^^^^
  File "/home/b0457812963/MambaRL/lib/python3.12/site-packages/pymysql/connections.py", line 825, in _read_query_result
    result.read()
  File "/home/b0457812963/MambaRL/lib/python3.12/site-packages/pymysql/connections.py", line 1199, in read
    first_packet = self.connection._read_packet()
                   ^^^^^^^^^^^^^^^^^^^^^^^^^^^^^^
  File "/home/b0457812963/MambaRL/lib/python3.12/site-packages/pymysql/connections.py", line 775, in _read_packet
    packet.raise_for_error()
  File "/home/b0457812963/MambaRL/lib/python3.12/site-packages/pymysql/protocol.py", line 219, in raise_for_error
    err.raise_mysql_exception(self._data)
  File "/home/b0457812963/MambaRL/lib/python3.12/site-packages/pymysql/err.py", line 150, in raise_mysql_exception
    raise errorclass(errno, errval)
sqlalchemy.exc.ProgrammingError: (pymysql.err.ProgrammingError) (1064, "You have an error in your SQL syntax; check the manual that corresponds to your MySQL server version for the right syntax to use near 'btrusdt-f-d' at line 1")
[SQL: btrusdt-f-d]
(Background on this error at: https://sqlalche.me/e/20/f405)

2025-09-08 23:12 ERROR Traceback (most recent call last):
  File "/home/b0457812963/MambaRL/lib/python3.12/site-packages/sqlalchemy/engine/base.py", line 1967, in _exec_single_context
    self.dialect.do_execute(
  File "/home/b0457812963/MambaRL/lib/python3.12/site-packages/sqlalchemy/engine/default.py", line 941, in do_execute
    cursor.execute(statement, parameters)
  File "/home/b0457812963/MambaRL/lib/python3.12/site-packages/pymysql/cursors.py", line 153, in execute
    result = self._query(query)
             ^^^^^^^^^^^^^^^^^^
  File "/home/b0457812963/MambaRL/lib/python3.12/site-packages/pymysql/cursors.py", line 322, in _query
    conn.query(q)
  File "/home/b0457812963/MambaRL/lib/python3.12/site-packages/pymysql/connections.py", line 563, in query
    self._affected_rows = self._read_query_result(unbuffered=unbuffered)
                          ^^^^^^^^^^^^^^^^^^^^^^^^^^^^^^^^^^^^^^^^^^^^^^
  File "/home/b0457812963/MambaRL/lib/python3.12/site-packages/pymysql/connections.py", line 825, in _read_query_result
    result.read()
  File "/home/b0457812963/MambaRL/lib/python3.12/site-packages/pymysql/connections.py", line 1199, in read
    first_packet = self.connection._read_packet()
                   ^^^^^^^^^^^^^^^^^^^^^^^^^^^^^^
  File "/home/b0457812963/MambaRL/lib/python3.12/site-packages/pymysql/connections.py", line 775, in _read_packet
    packet.raise_for_error()
  File "/home/b0457812963/MambaRL/lib/python3.12/site-packages/pymysql/protocol.py", line 219, in raise_for_error
    err.raise_mysql_exception(self._data)
  File "/home/b0457812963/MambaRL/lib/python3.12/site-packages/pymysql/err.py", line 150, in raise_mysql_exception
    raise errorclass(errno, errval)
pymysql.err.ProgrammingError: (1064, "You have an error in your SQL syntax; check the manual that corresponds to your MySQL server version for the right syntax to use near 'mitousdt-f-d' at line 1")

The above exception was the direct cause of the following exception:

Traceback (most recent call last):
  File "/home/b0457812963/MambaRL/SynapseX/Database/SQL_operate.py", line 48, in read_Dateframe
    return pd.read_sql(text_msg, con=conn)
           ^^^^^^^^^^^^^^^^^^^^^^^^^^^^^^^
  File "/home/b0457812963/MambaRL/lib/python3.12/site-packages/pandas/io/sql.py", line 734, in read_sql
    return pandas_sql.read_query(
           ^^^^^^^^^^^^^^^^^^^^^^
  File "/home/b0457812963/MambaRL/lib/python3.12/site-packages/pandas/io/sql.py", line 1836, in read_query
    result = self.execute(sql, params)
             ^^^^^^^^^^^^^^^^^^^^^^^^^
  File "/home/b0457812963/MambaRL/lib/python3.12/site-packages/pandas/io/sql.py", line 1659, in execute
    return self.con.exec_driver_sql(sql, *args)
           ^^^^^^^^^^^^^^^^^^^^^^^^^^^^^^^^^^^^
  File "/home/b0457812963/MambaRL/lib/python3.12/site-packages/sqlalchemy/engine/base.py", line 1779, in exec_driver_sql
    ret = self._execute_context(
          ^^^^^^^^^^^^^^^^^^^^^^
  File "/home/b0457812963/MambaRL/lib/python3.12/site-packages/sqlalchemy/engine/base.py", line 1846, in _execute_context
    return self._exec_single_context(
           ^^^^^^^^^^^^^^^^^^^^^^^^^^
  File "/home/b0457812963/MambaRL/lib/python3.12/site-packages/sqlalchemy/engine/base.py", line 1986, in _exec_single_context
    self._handle_dbapi_exception(
  File "/home/b0457812963/MambaRL/lib/python3.12/site-packages/sqlalchemy/engine/base.py", line 2355, in _handle_dbapi_exception
    raise sqlalchemy_exception.with_traceback(exc_info[2]) from e
  File "/home/b0457812963/MambaRL/lib/python3.12/site-packages/sqlalchemy/engine/base.py", line 1967, in _exec_single_context
    self.dialect.do_execute(
  File "/home/b0457812963/MambaRL/lib/python3.12/site-packages/sqlalchemy/engine/default.py", line 941, in do_execute
    cursor.execute(statement, parameters)
  File "/home/b0457812963/MambaRL/lib/python3.12/site-packages/pymysql/cursors.py", line 153, in execute
    result = self._query(query)
             ^^^^^^^^^^^^^^^^^^
  File "/home/b0457812963/MambaRL/lib/python3.12/site-packages/pymysql/cursors.py", line 322, in _query
    conn.query(q)
  File "/home/b0457812963/MambaRL/lib/python3.12/site-packages/pymysql/connections.py", line 563, in query
    self._affected_rows = self._read_query_result(unbuffered=unbuffered)
                          ^^^^^^^^^^^^^^^^^^^^^^^^^^^^^^^^^^^^^^^^^^^^^^
  File "/home/b0457812963/MambaRL/lib/python3.12/site-packages/pymysql/connections.py", line 825, in _read_query_result
    result.read()
  File "/home/b0457812963/MambaRL/lib/python3.12/site-packages/pymysql/connections.py", line 1199, in read
    first_packet = self.connection._read_packet()
                   ^^^^^^^^^^^^^^^^^^^^^^^^^^^^^^
  File "/home/b0457812963/MambaRL/lib/python3.12/site-packages/pymysql/connections.py", line 775, in _read_packet
    packet.raise_for_error()
  File "/home/b0457812963/MambaRL/lib/python3.12/site-packages/pymysql/protocol.py", line 219, in raise_for_error
    err.raise_mysql_exception(self._data)
  File "/home/b0457812963/MambaRL/lib/python3.12/site-packages/pymysql/err.py", line 150, in raise_mysql_exception
    raise errorclass(errno, errval)
sqlalchemy.exc.ProgrammingError: (pymysql.err.ProgrammingError) (1064, "You have an error in your SQL syntax; check the manual that corresponds to your MySQL server version for the right syntax to use near 'mitousdt-f-d' at line 1")
[SQL: mitousdt-f-d]
(Background on this error at: https://sqlalche.me/e/20/f405)

2025-09-08 23:12 ERROR Traceback (most recent call last):
  File "/home/b0457812963/MambaRL/lib/python3.12/site-packages/sqlalchemy/engine/base.py", line 1967, in _exec_single_context
    self.dialect.do_execute(
  File "/home/b0457812963/MambaRL/lib/python3.12/site-packages/sqlalchemy/engine/default.py", line 941, in do_execute
    cursor.execute(statement, parameters)
  File "/home/b0457812963/MambaRL/lib/python3.12/site-packages/pymysql/cursors.py", line 153, in execute
    result = self._query(query)
             ^^^^^^^^^^^^^^^^^^
  File "/home/b0457812963/MambaRL/lib/python3.12/site-packages/pymysql/cursors.py", line 322, in _query
    conn.query(q)
  File "/home/b0457812963/MambaRL/lib/python3.12/site-packages/pymysql/connections.py", line 563, in query
    self._affected_rows = self._read_query_result(unbuffered=unbuffered)
                          ^^^^^^^^^^^^^^^^^^^^^^^^^^^^^^^^^^^^^^^^^^^^^^
  File "/home/b0457812963/MambaRL/lib/python3.12/site-packages/pymysql/connections.py", line 825, in _read_query_result
    result.read()
  File "/home/b0457812963/MambaRL/lib/python3.12/site-packages/pymysql/connections.py", line 1199, in read
    first_packet = self.connection._read_packet()
                   ^^^^^^^^^^^^^^^^^^^^^^^^^^^^^^
  File "/home/b0457812963/MambaRL/lib/python3.12/site-packages/pymysql/connections.py", line 775, in _read_packet
    packet.raise_for_error()
  File "/home/b0457812963/MambaRL/lib/python3.12/site-packages/pymysql/protocol.py", line 219, in raise_for_error
    err.raise_mysql_exception(self._data)
  File "/home/b0457812963/MambaRL/lib/python3.12/site-packages/pymysql/err.py", line 150, in raise_mysql_exception
    raise errorclass(errno, errval)
pymysql.err.ProgrammingError: (1064, "You have an error in your SQL syntax; check the manual that corresponds to your MySQL server version for the right syntax to use near 'hemiusdt-f-d' at line 1")

The above exception was the direct cause of the following exception:

Traceback (most recent call last):
  File "/home/b0457812963/MambaRL/SynapseX/Database/SQL_operate.py", line 48, in read_Dateframe
    return pd.read_sql(text_msg, con=conn)
           ^^^^^^^^^^^^^^^^^^^^^^^^^^^^^^^
  File "/home/b0457812963/MambaRL/lib/python3.12/site-packages/pandas/io/sql.py", line 734, in read_sql
    return pandas_sql.read_query(
           ^^^^^^^^^^^^^^^^^^^^^^
  File "/home/b0457812963/MambaRL/lib/python3.12/site-packages/pandas/io/sql.py", line 1836, in read_query
    result = self.execute(sql, params)
             ^^^^^^^^^^^^^^^^^^^^^^^^^
  File "/home/b0457812963/MambaRL/lib/python3.12/site-packages/pandas/io/sql.py", line 1659, in execute
    return self.con.exec_driver_sql(sql, *args)
           ^^^^^^^^^^^^^^^^^^^^^^^^^^^^^^^^^^^^
  File "/home/b0457812963/MambaRL/lib/python3.12/site-packages/sqlalchemy/engine/base.py", line 1779, in exec_driver_sql
    ret = self._execute_context(
          ^^^^^^^^^^^^^^^^^^^^^^
  File "/home/b0457812963/MambaRL/lib/python3.12/site-packages/sqlalchemy/engine/base.py", line 1846, in _execute_context
    return self._exec_single_context(
           ^^^^^^^^^^^^^^^^^^^^^^^^^^
  File "/home/b0457812963/MambaRL/lib/python3.12/site-packages/sqlalchemy/engine/base.py", line 1986, in _exec_single_context
    self._handle_dbapi_exception(
  File "/home/b0457812963/MambaRL/lib/python3.12/site-packages/sqlalchemy/engine/base.py", line 2355, in _handle_dbapi_exception
    raise sqlalchemy_exception.with_traceback(exc_info[2]) from e
  File "/home/b0457812963/MambaRL/lib/python3.12/site-packages/sqlalchemy/engine/base.py", line 1967, in _exec_single_context
    self.dialect.do_execute(
  File "/home/b0457812963/MambaRL/lib/python3.12/site-packages/sqlalchemy/engine/default.py", line 941, in do_execute
    cursor.execute(statement, parameters)
  File "/home/b0457812963/MambaRL/lib/python3.12/site-packages/pymysql/cursors.py", line 153, in execute
    result = self._query(query)
             ^^^^^^^^^^^^^^^^^^
  File "/home/b0457812963/MambaRL/lib/python3.12/site-packages/pymysql/cursors.py", line 322, in _query
    conn.query(q)
  File "/home/b0457812963/MambaRL/lib/python3.12/site-packages/pymysql/connections.py", line 563, in query
    self._affected_rows = self._read_query_result(unbuffered=unbuffered)
                          ^^^^^^^^^^^^^^^^^^^^^^^^^^^^^^^^^^^^^^^^^^^^^^
  File "/home/b0457812963/MambaRL/lib/python3.12/site-packages/pymysql/connections.py", line 825, in _read_query_result
    result.read()
  File "/home/b0457812963/MambaRL/lib/python3.12/site-packages/pymysql/connections.py", line 1199, in read
    first_packet = self.connection._read_packet()
                   ^^^^^^^^^^^^^^^^^^^^^^^^^^^^^^
  File "/home/b0457812963/MambaRL/lib/python3.12/site-packages/pymysql/connections.py", line 775, in _read_packet
    packet.raise_for_error()
  File "/home/b0457812963/MambaRL/lib/python3.12/site-packages/pymysql/protocol.py", line 219, in raise_for_error
    err.raise_mysql_exception(self._data)
  File "/home/b0457812963/MambaRL/lib/python3.12/site-packages/pymysql/err.py", line 150, in raise_mysql_exception
    raise errorclass(errno, errval)
sqlalchemy.exc.ProgrammingError: (pymysql.err.ProgrammingError) (1064, "You have an error in your SQL syntax; check the manual that corresponds to your MySQL server version for the right syntax to use near 'hemiusdt-f-d' at line 1")
[SQL: hemiusdt-f-d]
(Background on this error at: https://sqlalche.me/e/20/f405)

2025-09-08 23:12 ERROR Traceback (most recent call last):
  File "/home/b0457812963/MambaRL/lib/python3.12/site-packages/sqlalchemy/engine/base.py", line 1967, in _exec_single_context
    self.dialect.do_execute(
  File "/home/b0457812963/MambaRL/lib/python3.12/site-packages/sqlalchemy/engine/default.py", line 941, in do_execute
    cursor.execute(statement, parameters)
  File "/home/b0457812963/MambaRL/lib/python3.12/site-packages/pymysql/cursors.py", line 153, in execute
    result = self._query(query)
             ^^^^^^^^^^^^^^^^^^
  File "/home/b0457812963/MambaRL/lib/python3.12/site-packages/pymysql/cursors.py", line 322, in _query
    conn.query(q)
  File "/home/b0457812963/MambaRL/lib/python3.12/site-packages/pymysql/connections.py", line 563, in query
    self._affected_rows = self._read_query_result(unbuffered=unbuffered)
                          ^^^^^^^^^^^^^^^^^^^^^^^^^^^^^^^^^^^^^^^^^^^^^^
  File "/home/b0457812963/MambaRL/lib/python3.12/site-packages/pymysql/connections.py", line 825, in _read_query_result
    result.read()
  File "/home/b0457812963/MambaRL/lib/python3.12/site-packages/pymysql/connections.py", line 1199, in read
    first_packet = self.connection._read_packet()
                   ^^^^^^^^^^^^^^^^^^^^^^^^^^^^^^
  File "/home/b0457812963/MambaRL/lib/python3.12/site-packages/pymysql/connections.py", line 775, in _read_packet
    packet.raise_for_error()
  File "/home/b0457812963/MambaRL/lib/python3.12/site-packages/pymysql/protocol.py", line 219, in raise_for_error
    err.raise_mysql_exception(self._data)
  File "/home/b0457812963/MambaRL/lib/python3.12/site-packages/pymysql/err.py", line 150, in raise_mysql_exception
    raise errorclass(errno, errval)
pymysql.err.ProgrammingError: (1064, "You have an error in your SQL syntax; check the manual that corresponds to your MySQL server version for the right syntax to use near 'lineausdt-f-d' at line 1")

The above exception was the direct cause of the following exception:

Traceback (most recent call last):
  File "/home/b0457812963/MambaRL/SynapseX/Database/SQL_operate.py", line 48, in read_Dateframe
    return pd.read_sql(text_msg, con=conn)
           ^^^^^^^^^^^^^^^^^^^^^^^^^^^^^^^
  File "/home/b0457812963/MambaRL/lib/python3.12/site-packages/pandas/io/sql.py", line 734, in read_sql
    return pandas_sql.read_query(
           ^^^^^^^^^^^^^^^^^^^^^^
  File "/home/b0457812963/MambaRL/lib/python3.12/site-packages/pandas/io/sql.py", line 1836, in read_query
    result = self.execute(sql, params)
             ^^^^^^^^^^^^^^^^^^^^^^^^^
  File "/home/b0457812963/MambaRL/lib/python3.12/site-packages/pandas/io/sql.py", line 1659, in execute
    return self.con.exec_driver_sql(sql, *args)
           ^^^^^^^^^^^^^^^^^^^^^^^^^^^^^^^^^^^^
  File "/home/b0457812963/MambaRL/lib/python3.12/site-packages/sqlalchemy/engine/base.py", line 1779, in exec_driver_sql
    ret = self._execute_context(
          ^^^^^^^^^^^^^^^^^^^^^^
  File "/home/b0457812963/MambaRL/lib/python3.12/site-packages/sqlalchemy/engine/base.py", line 1846, in _execute_context
    return self._exec_single_context(
           ^^^^^^^^^^^^^^^^^^^^^^^^^^
  File "/home/b0457812963/MambaRL/lib/python3.12/site-packages/sqlalchemy/engine/base.py", line 1986, in _exec_single_context
    self._handle_dbapi_exception(
  File "/home/b0457812963/MambaRL/lib/python3.12/site-packages/sqlalchemy/engine/base.py", line 2355, in _handle_dbapi_exception
    raise sqlalchemy_exception.with_traceback(exc_info[2]) from e
  File "/home/b0457812963/MambaRL/lib/python3.12/site-packages/sqlalchemy/engine/base.py", line 1967, in _exec_single_context
    self.dialect.do_execute(
  File "/home/b0457812963/MambaRL/lib/python3.12/site-packages/sqlalchemy/engine/default.py", line 941, in do_execute
    cursor.execute(statement, parameters)
  File "/home/b0457812963/MambaRL/lib/python3.12/site-packages/pymysql/cursors.py", line 153, in execute
    result = self._query(query)
             ^^^^^^^^^^^^^^^^^^
  File "/home/b0457812963/MambaRL/lib/python3.12/site-packages/pymysql/cursors.py", line 322, in _query
    conn.query(q)
  File "/home/b0457812963/MambaRL/lib/python3.12/site-packages/pymysql/connections.py", line 563, in query
    self._affected_rows = self._read_query_result(unbuffered=unbuffered)
                          ^^^^^^^^^^^^^^^^^^^^^^^^^^^^^^^^^^^^^^^^^^^^^^
  File "/home/b0457812963/MambaRL/lib/python3.12/site-packages/pymysql/connections.py", line 825, in _read_query_result
    result.read()
  File "/home/b0457812963/MambaRL/lib/python3.12/site-packages/pymysql/connections.py", line 1199, in read
    first_packet = self.connection._read_packet()
                   ^^^^^^^^^^^^^^^^^^^^^^^^^^^^^^
  File "/home/b0457812963/MambaRL/lib/python3.12/site-packages/pymysql/connections.py", line 775, in _read_packet
    packet.raise_for_error()
  File "/home/b0457812963/MambaRL/lib/python3.12/site-packages/pymysql/protocol.py", line 219, in raise_for_error
    err.raise_mysql_exception(self._data)
  File "/home/b0457812963/MambaRL/lib/python3.12/site-packages/pymysql/err.py", line 150, in raise_mysql_exception
    raise errorclass(errno, errval)
sqlalchemy.exc.ProgrammingError: (pymysql.err.ProgrammingError) (1064, "You have an error in your SQL syntax; check the manual that corresponds to your MySQL server version for the right syntax to use near 'lineausdt-f-d' at line 1")
[SQL: lineausdt-f-d]
(Background on this error at: https://sqlalche.me/e/20/f405)

2025-09-08 23:12 ERROR Traceback (most recent call last):
  File "/home/b0457812963/MambaRL/lib/python3.12/site-packages/sqlalchemy/engine/base.py", line 1967, in _exec_single_context
    self.dialect.do_execute(
  File "/home/b0457812963/MambaRL/lib/python3.12/site-packages/sqlalchemy/engine/default.py", line 941, in do_execute
    cursor.execute(statement, parameters)
  File "/home/b0457812963/MambaRL/lib/python3.12/site-packages/pymysql/cursors.py", line 153, in execute
    result = self._query(query)
             ^^^^^^^^^^^^^^^^^^
  File "/home/b0457812963/MambaRL/lib/python3.12/site-packages/pymysql/cursors.py", line 322, in _query
    conn.query(q)
  File "/home/b0457812963/MambaRL/lib/python3.12/site-packages/pymysql/connections.py", line 563, in query
    self._affected_rows = self._read_query_result(unbuffered=unbuffered)
                          ^^^^^^^^^^^^^^^^^^^^^^^^^^^^^^^^^^^^^^^^^^^^^^
  File "/home/b0457812963/MambaRL/lib/python3.12/site-packages/pymysql/connections.py", line 825, in _read_query_result
    result.read()
  File "/home/b0457812963/MambaRL/lib/python3.12/site-packages/pymysql/connections.py", line 1199, in read
    first_packet = self.connection._read_packet()
                   ^^^^^^^^^^^^^^^^^^^^^^^^^^^^^^
  File "/home/b0457812963/MambaRL/lib/python3.12/site-packages/pymysql/connections.py", line 775, in _read_packet
    packet.raise_for_error()
  File "/home/b0457812963/MambaRL/lib/python3.12/site-packages/pymysql/protocol.py", line 219, in raise_for_error
    err.raise_mysql_exception(self._data)
  File "/home/b0457812963/MambaRL/lib/python3.12/site-packages/pymysql/err.py", line 150, in raise_mysql_exception
    raise errorclass(errno, errval)
pymysql.err.ProgrammingError: (1064, "You have an error in your SQL syntax; check the manual that corresponds to your MySQL server version for the right syntax to use near 'qusdt-f-d' at line 1")

The above exception was the direct cause of the following exception:

Traceback (most recent call last):
  File "/home/b0457812963/MambaRL/SynapseX/Database/SQL_operate.py", line 48, in read_Dateframe
    return pd.read_sql(text_msg, con=conn)
           ^^^^^^^^^^^^^^^^^^^^^^^^^^^^^^^
  File "/home/b0457812963/MambaRL/lib/python3.12/site-packages/pandas/io/sql.py", line 734, in read_sql
    return pandas_sql.read_query(
           ^^^^^^^^^^^^^^^^^^^^^^
  File "/home/b0457812963/MambaRL/lib/python3.12/site-packages/pandas/io/sql.py", line 1836, in read_query
    result = self.execute(sql, params)
             ^^^^^^^^^^^^^^^^^^^^^^^^^
  File "/home/b0457812963/MambaRL/lib/python3.12/site-packages/pandas/io/sql.py", line 1659, in execute
    return self.con.exec_driver_sql(sql, *args)
           ^^^^^^^^^^^^^^^^^^^^^^^^^^^^^^^^^^^^
  File "/home/b0457812963/MambaRL/lib/python3.12/site-packages/sqlalchemy/engine/base.py", line 1779, in exec_driver_sql
    ret = self._execute_context(
          ^^^^^^^^^^^^^^^^^^^^^^
  File "/home/b0457812963/MambaRL/lib/python3.12/site-packages/sqlalchemy/engine/base.py", line 1846, in _execute_context
    return self._exec_single_context(
           ^^^^^^^^^^^^^^^^^^^^^^^^^^
  File "/home/b0457812963/MambaRL/lib/python3.12/site-packages/sqlalchemy/engine/base.py", line 1986, in _exec_single_context
    self._handle_dbapi_exception(
  File "/home/b0457812963/MambaRL/lib/python3.12/site-packages/sqlalchemy/engine/base.py", line 2355, in _handle_dbapi_exception
    raise sqlalchemy_exception.with_traceback(exc_info[2]) from e
  File "/home/b0457812963/MambaRL/lib/python3.12/site-packages/sqlalchemy/engine/base.py", line 1967, in _exec_single_context
    self.dialect.do_execute(
  File "/home/b0457812963/MambaRL/lib/python3.12/site-packages/sqlalchemy/engine/default.py", line 941, in do_execute
    cursor.execute(statement, parameters)
  File "/home/b0457812963/MambaRL/lib/python3.12/site-packages/pymysql/cursors.py", line 153, in execute
    result = self._query(query)
             ^^^^^^^^^^^^^^^^^^
  File "/home/b0457812963/MambaRL/lib/python3.12/site-packages/pymysql/cursors.py", line 322, in _query
    conn.query(q)
  File "/home/b0457812963/MambaRL/lib/python3.12/site-packages/pymysql/connections.py", line 563, in query
    self._affected_rows = self._read_query_result(unbuffered=unbuffered)
                          ^^^^^^^^^^^^^^^^^^^^^^^^^^^^^^^^^^^^^^^^^^^^^^
  File "/home/b0457812963/MambaRL/lib/python3.12/site-packages/pymysql/connections.py", line 825, in _read_query_result
    result.read()
  File "/home/b0457812963/MambaRL/lib/python3.12/site-packages/pymysql/connections.py", line 1199, in read
    first_packet = self.connection._read_packet()
                   ^^^^^^^^^^^^^^^^^^^^^^^^^^^^^^
  File "/home/b0457812963/MambaRL/lib/python3.12/site-packages/pymysql/connections.py", line 775, in _read_packet
    packet.raise_for_error()
  File "/home/b0457812963/MambaRL/lib/python3.12/site-packages/pymysql/protocol.py", line 219, in raise_for_error
    err.raise_mysql_exception(self._data)
  File "/home/b0457812963/MambaRL/lib/python3.12/site-packages/pymysql/err.py", line 150, in raise_mysql_exception
    raise errorclass(errno, errval)
sqlalchemy.exc.ProgrammingError: (pymysql.err.ProgrammingError) (1064, "You have an error in your SQL syntax; check the manual that corresponds to your MySQL server version for the right syntax to use near 'qusdt-f-d' at line 1")
[SQL: qusdt-f-d]
(Background on this error at: https://sqlalche.me/e/20/f405)

2025-09-08 23:12 ERROR Traceback (most recent call last):
  File "/home/b0457812963/MambaRL/lib/python3.12/site-packages/sqlalchemy/engine/base.py", line 1967, in _exec_single_context
    self.dialect.do_execute(
  File "/home/b0457812963/MambaRL/lib/python3.12/site-packages/sqlalchemy/engine/default.py", line 941, in do_execute
    cursor.execute(statement, parameters)
  File "/home/b0457812963/MambaRL/lib/python3.12/site-packages/pymysql/cursors.py", line 153, in execute
    result = self._query(query)
             ^^^^^^^^^^^^^^^^^^
  File "/home/b0457812963/MambaRL/lib/python3.12/site-packages/pymysql/cursors.py", line 322, in _query
    conn.query(q)
  File "/home/b0457812963/MambaRL/lib/python3.12/site-packages/pymysql/connections.py", line 563, in query
    self._affected_rows = self._read_query_result(unbuffered=unbuffered)
                          ^^^^^^^^^^^^^^^^^^^^^^^^^^^^^^^^^^^^^^^^^^^^^^
  File "/home/b0457812963/MambaRL/lib/python3.12/site-packages/pymysql/connections.py", line 825, in _read_query_result
    result.read()
  File "/home/b0457812963/MambaRL/lib/python3.12/site-packages/pymysql/connections.py", line 1199, in read
    first_packet = self.connection._read_packet()
                   ^^^^^^^^^^^^^^^^^^^^^^^^^^^^^^
  File "/home/b0457812963/MambaRL/lib/python3.12/site-packages/pymysql/connections.py", line 775, in _read_packet
    packet.raise_for_error()
  File "/home/b0457812963/MambaRL/lib/python3.12/site-packages/pymysql/protocol.py", line 219, in raise_for_error
    err.raise_mysql_exception(self._data)
  File "/home/b0457812963/MambaRL/lib/python3.12/site-packages/pymysql/err.py", line 150, in raise_mysql_exception
    raise errorclass(errno, errval)
pymysql.err.ProgrammingError: (1064, "You have an error in your SQL syntax; check the manual that corresponds to your MySQL server version for the right syntax to use near 'ariausdt-f-d' at line 1")

The above exception was the direct cause of the following exception:

Traceback (most recent call last):
  File "/home/b0457812963/MambaRL/SynapseX/Database/SQL_operate.py", line 48, in read_Dateframe
    return pd.read_sql(text_msg, con=conn)
           ^^^^^^^^^^^^^^^^^^^^^^^^^^^^^^^
  File "/home/b0457812963/MambaRL/lib/python3.12/site-packages/pandas/io/sql.py", line 734, in read_sql
    return pandas_sql.read_query(
           ^^^^^^^^^^^^^^^^^^^^^^
  File "/home/b0457812963/MambaRL/lib/python3.12/site-packages/pandas/io/sql.py", line 1836, in read_query
    result = self.execute(sql, params)
             ^^^^^^^^^^^^^^^^^^^^^^^^^
  File "/home/b0457812963/MambaRL/lib/python3.12/site-packages/pandas/io/sql.py", line 1659, in execute
    return self.con.exec_driver_sql(sql, *args)
           ^^^^^^^^^^^^^^^^^^^^^^^^^^^^^^^^^^^^
  File "/home/b0457812963/MambaRL/lib/python3.12/site-packages/sqlalchemy/engine/base.py", line 1779, in exec_driver_sql
    ret = self._execute_context(
          ^^^^^^^^^^^^^^^^^^^^^^
  File "/home/b0457812963/MambaRL/lib/python3.12/site-packages/sqlalchemy/engine/base.py", line 1846, in _execute_context
    return self._exec_single_context(
           ^^^^^^^^^^^^^^^^^^^^^^^^^^
  File "/home/b0457812963/MambaRL/lib/python3.12/site-packages/sqlalchemy/engine/base.py", line 1986, in _exec_single_context
    self._handle_dbapi_exception(
  File "/home/b0457812963/MambaRL/lib/python3.12/site-packages/sqlalchemy/engine/base.py", line 2355, in _handle_dbapi_exception
    raise sqlalchemy_exception.with_traceback(exc_info[2]) from e
  File "/home/b0457812963/MambaRL/lib/python3.12/site-packages/sqlalchemy/engine/base.py", line 1967, in _exec_single_context
    self.dialect.do_execute(
  File "/home/b0457812963/MambaRL/lib/python3.12/site-packages/sqlalchemy/engine/default.py", line 941, in do_execute
    cursor.execute(statement, parameters)
  File "/home/b0457812963/MambaRL/lib/python3.12/site-packages/pymysql/cursors.py", line 153, in execute
    result = self._query(query)
             ^^^^^^^^^^^^^^^^^^
  File "/home/b0457812963/MambaRL/lib/python3.12/site-packages/pymysql/cursors.py", line 322, in _query
    conn.query(q)
  File "/home/b0457812963/MambaRL/lib/python3.12/site-packages/pymysql/connections.py", line 563, in query
    self._affected_rows = self._read_query_result(unbuffered=unbuffered)
                          ^^^^^^^^^^^^^^^^^^^^^^^^^^^^^^^^^^^^^^^^^^^^^^
  File "/home/b0457812963/MambaRL/lib/python3.12/site-packages/pymysql/connections.py", line 825, in _read_query_result
    result.read()
  File "/home/b0457812963/MambaRL/lib/python3.12/site-packages/pymysql/connections.py", line 1199, in read
    first_packet = self.connection._read_packet()
                   ^^^^^^^^^^^^^^^^^^^^^^^^^^^^^^
  File "/home/b0457812963/MambaRL/lib/python3.12/site-packages/pymysql/connections.py", line 775, in _read_packet
    packet.raise_for_error()
  File "/home/b0457812963/MambaRL/lib/python3.12/site-packages/pymysql/protocol.py", line 219, in raise_for_error
    err.raise_mysql_exception(self._data)
  File "/home/b0457812963/MambaRL/lib/python3.12/site-packages/pymysql/err.py", line 150, in raise_mysql_exception
    raise errorclass(errno, errval)
sqlalchemy.exc.ProgrammingError: (pymysql.err.ProgrammingError) (1064, "You have an error in your SQL syntax; check the manual that corresponds to your MySQL server version for the right syntax to use near 'ariausdt-f-d' at line 1")
[SQL: ariausdt-f-d]
(Background on this error at: https://sqlalche.me/e/20/f405)

2025-09-08 23:12 ERROR Traceback (most recent call last):
  File "/home/b0457812963/MambaRL/lib/python3.12/site-packages/sqlalchemy/engine/base.py", line 1967, in _exec_single_context
    self.dialect.do_execute(
  File "/home/b0457812963/MambaRL/lib/python3.12/site-packages/sqlalchemy/engine/default.py", line 941, in do_execute
    cursor.execute(statement, parameters)
  File "/home/b0457812963/MambaRL/lib/python3.12/site-packages/pymysql/cursors.py", line 153, in execute
    result = self._query(query)
             ^^^^^^^^^^^^^^^^^^
  File "/home/b0457812963/MambaRL/lib/python3.12/site-packages/pymysql/cursors.py", line 322, in _query
    conn.query(q)
  File "/home/b0457812963/MambaRL/lib/python3.12/site-packages/pymysql/connections.py", line 563, in query
    self._affected_rows = self._read_query_result(unbuffered=unbuffered)
                          ^^^^^^^^^^^^^^^^^^^^^^^^^^^^^^^^^^^^^^^^^^^^^^
  File "/home/b0457812963/MambaRL/lib/python3.12/site-packages/pymysql/connections.py", line 825, in _read_query_result
    result.read()
  File "/home/b0457812963/MambaRL/lib/python3.12/site-packages/pymysql/connections.py", line 1199, in read
    first_packet = self.connection._read_packet()
                   ^^^^^^^^^^^^^^^^^^^^^^^^^^^^^^
  File "/home/b0457812963/MambaRL/lib/python3.12/site-packages/pymysql/connections.py", line 775, in _read_packet
    packet.raise_for_error()
  File "/home/b0457812963/MambaRL/lib/python3.12/site-packages/pymysql/protocol.py", line 219, in raise_for_error
    err.raise_mysql_exception(self._data)
  File "/home/b0457812963/MambaRL/lib/python3.12/site-packages/pymysql/err.py", line 150, in raise_mysql_exception
    raise errorclass(errno, errval)
pymysql.err.ProgrammingError: (1064, "You have an error in your SQL syntax; check the manual that corresponds to your MySQL server version for the right syntax to use near 'takeusdt-f-d' at line 1")

The above exception was the direct cause of the following exception:

Traceback (most recent call last):
  File "/home/b0457812963/MambaRL/SynapseX/Database/SQL_operate.py", line 48, in read_Dateframe
    return pd.read_sql(text_msg, con=conn)
           ^^^^^^^^^^^^^^^^^^^^^^^^^^^^^^^
  File "/home/b0457812963/MambaRL/lib/python3.12/site-packages/pandas/io/sql.py", line 734, in read_sql
    return pandas_sql.read_query(
           ^^^^^^^^^^^^^^^^^^^^^^
  File "/home/b0457812963/MambaRL/lib/python3.12/site-packages/pandas/io/sql.py", line 1836, in read_query
    result = self.execute(sql, params)
             ^^^^^^^^^^^^^^^^^^^^^^^^^
  File "/home/b0457812963/MambaRL/lib/python3.12/site-packages/pandas/io/sql.py", line 1659, in execute
    return self.con.exec_driver_sql(sql, *args)
           ^^^^^^^^^^^^^^^^^^^^^^^^^^^^^^^^^^^^
  File "/home/b0457812963/MambaRL/lib/python3.12/site-packages/sqlalchemy/engine/base.py", line 1779, in exec_driver_sql
    ret = self._execute_context(
          ^^^^^^^^^^^^^^^^^^^^^^
  File "/home/b0457812963/MambaRL/lib/python3.12/site-packages/sqlalchemy/engine/base.py", line 1846, in _execute_context
    return self._exec_single_context(
           ^^^^^^^^^^^^^^^^^^^^^^^^^^
  File "/home/b0457812963/MambaRL/lib/python3.12/site-packages/sqlalchemy/engine/base.py", line 1986, in _exec_single_context
    self._handle_dbapi_exception(
  File "/home/b0457812963/MambaRL/lib/python3.12/site-packages/sqlalchemy/engine/base.py", line 2355, in _handle_dbapi_exception
    raise sqlalchemy_exception.with_traceback(exc_info[2]) from e
  File "/home/b0457812963/MambaRL/lib/python3.12/site-packages/sqlalchemy/engine/base.py", line 1967, in _exec_single_context
    self.dialect.do_execute(
  File "/home/b0457812963/MambaRL/lib/python3.12/site-packages/sqlalchemy/engine/default.py", line 941, in do_execute
    cursor.execute(statement, parameters)
  File "/home/b0457812963/MambaRL/lib/python3.12/site-packages/pymysql/cursors.py", line 153, in execute
    result = self._query(query)
             ^^^^^^^^^^^^^^^^^^
  File "/home/b0457812963/MambaRL/lib/python3.12/site-packages/pymysql/cursors.py", line 322, in _query
    conn.query(q)
  File "/home/b0457812963/MambaRL/lib/python3.12/site-packages/pymysql/connections.py", line 563, in query
    self._affected_rows = self._read_query_result(unbuffered=unbuffered)
                          ^^^^^^^^^^^^^^^^^^^^^^^^^^^^^^^^^^^^^^^^^^^^^^
  File "/home/b0457812963/MambaRL/lib/python3.12/site-packages/pymysql/connections.py", line 825, in _read_query_result
    result.read()
  File "/home/b0457812963/MambaRL/lib/python3.12/site-packages/pymysql/connections.py", line 1199, in read
    first_packet = self.connection._read_packet()
                   ^^^^^^^^^^^^^^^^^^^^^^^^^^^^^^
  File "/home/b0457812963/MambaRL/lib/python3.12/site-packages/pymysql/connections.py", line 775, in _read_packet
    packet.raise_for_error()
  File "/home/b0457812963/MambaRL/lib/python3.12/site-packages/pymysql/protocol.py", line 219, in raise_for_error
    err.raise_mysql_exception(self._data)
  File "/home/b0457812963/MambaRL/lib/python3.12/site-packages/pymysql/err.py", line 150, in raise_mysql_exception
    raise errorclass(errno, errval)
sqlalchemy.exc.ProgrammingError: (pymysql.err.ProgrammingError) (1064, "You have an error in your SQL syntax; check the manual that corresponds to your MySQL server version for the right syntax to use near 'takeusdt-f-d' at line 1")
[SQL: takeusdt-f-d]
(Background on this error at: https://sqlalche.me/e/20/f405)

2025-09-08 23:12 ERROR Traceback (most recent call last):
  File "/home/b0457812963/MambaRL/lib/python3.12/site-packages/sqlalchemy/engine/base.py", line 1967, in _exec_single_context
    self.dialect.do_execute(
  File "/home/b0457812963/MambaRL/lib/python3.12/site-packages/sqlalchemy/engine/default.py", line 941, in do_execute
    cursor.execute(statement, parameters)
  File "/home/b0457812963/MambaRL/lib/python3.12/site-packages/pymysql/cursors.py", line 153, in execute
    result = self._query(query)
             ^^^^^^^^^^^^^^^^^^
  File "/home/b0457812963/MambaRL/lib/python3.12/site-packages/pymysql/cursors.py", line 322, in _query
    conn.query(q)
  File "/home/b0457812963/MambaRL/lib/python3.12/site-packages/pymysql/connections.py", line 563, in query
    self._affected_rows = self._read_query_result(unbuffered=unbuffered)
                          ^^^^^^^^^^^^^^^^^^^^^^^^^^^^^^^^^^^^^^^^^^^^^^
  File "/home/b0457812963/MambaRL/lib/python3.12/site-packages/pymysql/connections.py", line 825, in _read_query_result
    result.read()
  File "/home/b0457812963/MambaRL/lib/python3.12/site-packages/pymysql/connections.py", line 1199, in read
    first_packet = self.connection._read_packet()
                   ^^^^^^^^^^^^^^^^^^^^^^^^^^^^^^
  File "/home/b0457812963/MambaRL/lib/python3.12/site-packages/pymysql/connections.py", line 775, in _read_packet
    packet.raise_for_error()
  File "/home/b0457812963/MambaRL/lib/python3.12/site-packages/pymysql/protocol.py", line 219, in raise_for_error
    err.raise_mysql_exception(self._data)
  File "/home/b0457812963/MambaRL/lib/python3.12/site-packages/pymysql/err.py", line 150, in raise_mysql_exception
    raise errorclass(errno, errval)
pymysql.err.ProgrammingError: (1064, "You have an error in your SQL syntax; check the manual that corresponds to your MySQL server version for the right syntax to use near 'ptbusdt-f-d' at line 1")

The above exception was the direct cause of the following exception:

Traceback (most recent call last):
  File "/home/b0457812963/MambaRL/SynapseX/Database/SQL_operate.py", line 48, in read_Dateframe
    return pd.read_sql(text_msg, con=conn)
           ^^^^^^^^^^^^^^^^^^^^^^^^^^^^^^^
  File "/home/b0457812963/MambaRL/lib/python3.12/site-packages/pandas/io/sql.py", line 734, in read_sql
    return pandas_sql.read_query(
           ^^^^^^^^^^^^^^^^^^^^^^
  File "/home/b0457812963/MambaRL/lib/python3.12/site-packages/pandas/io/sql.py", line 1836, in read_query
    result = self.execute(sql, params)
             ^^^^^^^^^^^^^^^^^^^^^^^^^
  File "/home/b0457812963/MambaRL/lib/python3.12/site-packages/pandas/io/sql.py", line 1659, in execute
    return self.con.exec_driver_sql(sql, *args)
           ^^^^^^^^^^^^^^^^^^^^^^^^^^^^^^^^^^^^
  File "/home/b0457812963/MambaRL/lib/python3.12/site-packages/sqlalchemy/engine/base.py", line 1779, in exec_driver_sql
    ret = self._execute_context(
          ^^^^^^^^^^^^^^^^^^^^^^
  File "/home/b0457812963/MambaRL/lib/python3.12/site-packages/sqlalchemy/engine/base.py", line 1846, in _execute_context
    return self._exec_single_context(
           ^^^^^^^^^^^^^^^^^^^^^^^^^^
  File "/home/b0457812963/MambaRL/lib/python3.12/site-packages/sqlalchemy/engine/base.py", line 1986, in _exec_single_context
    self._handle_dbapi_exception(
  File "/home/b0457812963/MambaRL/lib/python3.12/site-packages/sqlalchemy/engine/base.py", line 2355, in _handle_dbapi_exception
    raise sqlalchemy_exception.with_traceback(exc_info[2]) from e
  File "/home/b0457812963/MambaRL/lib/python3.12/site-packages/sqlalchemy/engine/base.py", line 1967, in _exec_single_context
    self.dialect.do_execute(
  File "/home/b0457812963/MambaRL/lib/python3.12/site-packages/sqlalchemy/engine/default.py", line 941, in do_execute
    cursor.execute(statement, parameters)
  File "/home/b0457812963/MambaRL/lib/python3.12/site-packages/pymysql/cursors.py", line 153, in execute
    result = self._query(query)
             ^^^^^^^^^^^^^^^^^^
  File "/home/b0457812963/MambaRL/lib/python3.12/site-packages/pymysql/cursors.py", line 322, in _query
    conn.query(q)
  File "/home/b0457812963/MambaRL/lib/python3.12/site-packages/pymysql/connections.py", line 563, in query
    self._affected_rows = self._read_query_result(unbuffered=unbuffered)
                          ^^^^^^^^^^^^^^^^^^^^^^^^^^^^^^^^^^^^^^^^^^^^^^
  File "/home/b0457812963/MambaRL/lib/python3.12/site-packages/pymysql/connections.py", line 825, in _read_query_result
    result.read()
  File "/home/b0457812963/MambaRL/lib/python3.12/site-packages/pymysql/connections.py", line 1199, in read
    first_packet = self.connection._read_packet()
                   ^^^^^^^^^^^^^^^^^^^^^^^^^^^^^^
  File "/home/b0457812963/MambaRL/lib/python3.12/site-packages/pymysql/connections.py", line 775, in _read_packet
    packet.raise_for_error()
  File "/home/b0457812963/MambaRL/lib/python3.12/site-packages/pymysql/protocol.py", line 219, in raise_for_error
    err.raise_mysql_exception(self._data)
  File "/home/b0457812963/MambaRL/lib/python3.12/site-packages/pymysql/err.py", line 150, in raise_mysql_exception
    raise errorclass(errno, errval)
sqlalchemy.exc.ProgrammingError: (pymysql.err.ProgrammingError) (1064, "You have an error in your SQL syntax; check the manual that corresponds to your MySQL server version for the right syntax to use near 'ptbusdt-f-d' at line 1")
[SQL: ptbusdt-f-d]
(Background on this error at: https://sqlalche.me/e/20/f405)

2025-09-08 23:12 ERROR Traceback (most recent call last):
  File "/home/b0457812963/MambaRL/lib/python3.12/site-packages/sqlalchemy/engine/base.py", line 1967, in _exec_single_context
    self.dialect.do_execute(
  File "/home/b0457812963/MambaRL/lib/python3.12/site-packages/sqlalchemy/engine/default.py", line 941, in do_execute
    cursor.execute(statement, parameters)
  File "/home/b0457812963/MambaRL/lib/python3.12/site-packages/pymysql/cursors.py", line 153, in execute
    result = self._query(query)
             ^^^^^^^^^^^^^^^^^^
  File "/home/b0457812963/MambaRL/lib/python3.12/site-packages/pymysql/cursors.py", line 322, in _query
    conn.query(q)
  File "/home/b0457812963/MambaRL/lib/python3.12/site-packages/pymysql/connections.py", line 563, in query
    self._affected_rows = self._read_query_result(unbuffered=unbuffered)
                          ^^^^^^^^^^^^^^^^^^^^^^^^^^^^^^^^^^^^^^^^^^^^^^
  File "/home/b0457812963/MambaRL/lib/python3.12/site-packages/pymysql/connections.py", line 825, in _read_query_result
    result.read()
  File "/home/b0457812963/MambaRL/lib/python3.12/site-packages/pymysql/connections.py", line 1199, in read
    first_packet = self.connection._read_packet()
                   ^^^^^^^^^^^^^^^^^^^^^^^^^^^^^^
  File "/home/b0457812963/MambaRL/lib/python3.12/site-packages/pymysql/connections.py", line 775, in _read_packet
    packet.raise_for_error()
  File "/home/b0457812963/MambaRL/lib/python3.12/site-packages/pymysql/protocol.py", line 219, in raise_for_error
    err.raise_mysql_exception(self._data)
  File "/home/b0457812963/MambaRL/lib/python3.12/site-packages/pymysql/err.py", line 150, in raise_mysql_exception
    raise errorclass(errno, errval)
pymysql.err.ProgrammingError: (1064, "You have an error in your SQL syntax; check the manual that corresponds to your MySQL server version for the right syntax to use near 'openusdt-f-d' at line 1")

The above exception was the direct cause of the following exception:

Traceback (most recent call last):
  File "/home/b0457812963/MambaRL/SynapseX/Database/SQL_operate.py", line 48, in read_Dateframe
    return pd.read_sql(text_msg, con=conn)
           ^^^^^^^^^^^^^^^^^^^^^^^^^^^^^^^
  File "/home/b0457812963/MambaRL/lib/python3.12/site-packages/pandas/io/sql.py", line 734, in read_sql
    return pandas_sql.read_query(
           ^^^^^^^^^^^^^^^^^^^^^^
  File "/home/b0457812963/MambaRL/lib/python3.12/site-packages/pandas/io/sql.py", line 1836, in read_query
    result = self.execute(sql, params)
             ^^^^^^^^^^^^^^^^^^^^^^^^^
  File "/home/b0457812963/MambaRL/lib/python3.12/site-packages/pandas/io/sql.py", line 1659, in execute
    return self.con.exec_driver_sql(sql, *args)
           ^^^^^^^^^^^^^^^^^^^^^^^^^^^^^^^^^^^^
  File "/home/b0457812963/MambaRL/lib/python3.12/site-packages/sqlalchemy/engine/base.py", line 1779, in exec_driver_sql
    ret = self._execute_context(
          ^^^^^^^^^^^^^^^^^^^^^^
  File "/home/b0457812963/MambaRL/lib/python3.12/site-packages/sqlalchemy/engine/base.py", line 1846, in _execute_context
    return self._exec_single_context(
           ^^^^^^^^^^^^^^^^^^^^^^^^^^
  File "/home/b0457812963/MambaRL/lib/python3.12/site-packages/sqlalchemy/engine/base.py", line 1986, in _exec_single_context
    self._handle_dbapi_exception(
  File "/home/b0457812963/MambaRL/lib/python3.12/site-packages/sqlalchemy/engine/base.py", line 2355, in _handle_dbapi_exception
    raise sqlalchemy_exception.with_traceback(exc_info[2]) from e
  File "/home/b0457812963/MambaRL/lib/python3.12/site-packages/sqlalchemy/engine/base.py", line 1967, in _exec_single_context
    self.dialect.do_execute(
  File "/home/b0457812963/MambaRL/lib/python3.12/site-packages/sqlalchemy/engine/default.py", line 941, in do_execute
    cursor.execute(statement, parameters)
  File "/home/b0457812963/MambaRL/lib/python3.12/site-packages/pymysql/cursors.py", line 153, in execute
    result = self._query(query)
             ^^^^^^^^^^^^^^^^^^
  File "/home/b0457812963/MambaRL/lib/python3.12/site-packages/pymysql/cursors.py", line 322, in _query
    conn.query(q)
  File "/home/b0457812963/MambaRL/lib/python3.12/site-packages/pymysql/connections.py", line 563, in query
    self._affected_rows = self._read_query_result(unbuffered=unbuffered)
                          ^^^^^^^^^^^^^^^^^^^^^^^^^^^^^^^^^^^^^^^^^^^^^^
  File "/home/b0457812963/MambaRL/lib/python3.12/site-packages/pymysql/connections.py", line 825, in _read_query_result
    result.read()
  File "/home/b0457812963/MambaRL/lib/python3.12/site-packages/pymysql/connections.py", line 1199, in read
    first_packet = self.connection._read_packet()
                   ^^^^^^^^^^^^^^^^^^^^^^^^^^^^^^
  File "/home/b0457812963/MambaRL/lib/python3.12/site-packages/pymysql/connections.py", line 775, in _read_packet
    packet.raise_for_error()
  File "/home/b0457812963/MambaRL/lib/python3.12/site-packages/pymysql/protocol.py", line 219, in raise_for_error
    err.raise_mysql_exception(self._data)
  File "/home/b0457812963/MambaRL/lib/python3.12/site-packages/pymysql/err.py", line 150, in raise_mysql_exception
    raise errorclass(errno, errval)
sqlalchemy.exc.ProgrammingError: (pymysql.err.ProgrammingError) (1064, "You have an error in your SQL syntax; check the manual that corresponds to your MySQL server version for the right syntax to use near 'openusdt-f-d' at line 1")
[SQL: openusdt-f-d]
(Background on this error at: https://sqlalche.me/e/20/f405)

