2025-01-21 03:32 ERROR Traceback (most recent call last):
  File "C:\Users\a046829713\Desktop\program\RLTrading\SynapseX\Database\SQL_operate.py", line 13, in get_db_data
    self.userconn = router.Router().mysql_conn
  File "C:\Users\a046829713\Desktop\program\RLTrading\SynapseX\Database\router.py", line 13, in __init__
    self._mysql_conn = self.get_mysql_conn()
  File "C:\Users\a046829713\Desktop\program\RLTrading\SynapseX\Database\router.py", line 28, in get_mysql_conn
    connect = engine.connect()
  File "C:\Users\a046829713\Desktop\program\RLTrading\lib\site-packages\sqlalchemy\engine\base.py", line 3278, in connect
    return self._connection_cls(self)
  File "C:\Users\a046829713\Desktop\program\RLTrading\lib\site-packages\sqlalchemy\engine\base.py", line 146, in __init__
    self._dbapi_connection = engine.raw_connection()
  File "C:\Users\a046829713\Desktop\program\RLTrading\lib\site-packages\sqlalchemy\engine\base.py", line 3302, in raw_connection
    return self.pool.connect()
  File "C:\Users\a046829713\Desktop\program\RLTrading\lib\site-packages\sqlalchemy\pool\base.py", line 449, in connect
    return _ConnectionFairy._checkout(self)
  File "C:\Users\a046829713\Desktop\program\RLTrading\lib\site-packages\sqlalchemy\pool\base.py", line 1263, in _checkout
    fairy = _ConnectionRecord.checkout(pool)
  File "C:\Users\a046829713\Desktop\program\RLTrading\lib\site-packages\sqlalchemy\pool\base.py", line 712, in checkout
    rec = pool._do_get()
  File "C:\Users\a046829713\Desktop\program\RLTrading\lib\site-packages\sqlalchemy\pool\impl.py", line 179, in _do_get
    with util.safe_reraise():
  File "C:\Users\a046829713\Desktop\program\RLTrading\lib\site-packages\sqlalchemy\util\langhelpers.py", line 146, in __exit__
    raise exc_value.with_traceback(exc_tb)
  File "C:\Users\a046829713\Desktop\program\RLTrading\lib\site-packages\sqlalchemy\pool\impl.py", line 177, in _do_get
    return self._create_connection()
  File "C:\Users\a046829713\Desktop\program\RLTrading\lib\site-packages\sqlalchemy\pool\base.py", line 390, in _create_connection
    return _ConnectionRecord(self)
  File "C:\Users\a046829713\Desktop\program\RLTrading\lib\site-packages\sqlalchemy\pool\base.py", line 674, in __init__
    self.__connect()
  File "C:\Users\a046829713\Desktop\program\RLTrading\lib\site-packages\sqlalchemy\pool\base.py", line 900, in __connect
    with util.safe_reraise():
  File "C:\Users\a046829713\Desktop\program\RLTrading\lib\site-packages\sqlalchemy\util\langhelpers.py", line 146, in __exit__
    raise exc_value.with_traceback(exc_tb)
  File "C:\Users\a046829713\Desktop\program\RLTrading\lib\site-packages\sqlalchemy\pool\base.py", line 896, in __connect
    self.dbapi_connection = connection = pool._invoke_creator(self)
  File "C:\Users\a046829713\Desktop\program\RLTrading\lib\site-packages\sqlalchemy\engine\create.py", line 643, in connect
    return dialect.connect(*cargs, **cparams)
  File "C:\Users\a046829713\Desktop\program\RLTrading\lib\site-packages\sqlalchemy\engine\default.py", line 621, in connect
    return self.loaded_dbapi.connect(*cargs, **cparams)
  File "C:\Users\a046829713\Desktop\program\RLTrading\lib\site-packages\pymysql\connections.py", line 361, in __init__
    self.connect()
  File "C:\Users\a046829713\Desktop\program\RLTrading\lib\site-packages\pymysql\connections.py", line 669, in connect
    self._request_authentication()
  File "C:\Users\a046829713\Desktop\program\RLTrading\lib\site-packages\pymysql\connections.py", line 979, in _request_authentication
    auth_packet = _auth.caching_sha2_password_auth(self, auth_packet)
  File "C:\Users\a046829713\Desktop\program\RLTrading\lib\site-packages\pymysql\_auth.py", line 267, in caching_sha2_password_auth
    data = sha2_rsa_encrypt(conn.password, conn.salt, conn.server_public_key)
  File "C:\Users\a046829713\Desktop\program\RLTrading\lib\site-packages\pymysql\_auth.py", line 144, in sha2_rsa_encrypt
    raise RuntimeError(
RuntimeError: 'cryptography' package is required for sha256_password or caching_sha2_password auth methods

2025-01-21 03:32 ERROR Traceback (most recent call last):
  File "C:\Users\a046829713\Desktop\program\RLTrading\lib\site-packages\sqlalchemy\engine\base.py", line 1967, in _exec_single_context
    self.dialect.do_execute(
  File "C:\Users\a046829713\Desktop\program\RLTrading\lib\site-packages\sqlalchemy\engine\default.py", line 941, in do_execute
    cursor.execute(statement, parameters)
  File "C:\Users\a046829713\Desktop\program\RLTrading\lib\site-packages\pymysql\cursors.py", line 153, in execute
    result = self._query(query)
  File "C:\Users\a046829713\Desktop\program\RLTrading\lib\site-packages\pymysql\cursors.py", line 322, in _query
    conn.query(q)
  File "C:\Users\a046829713\Desktop\program\RLTrading\lib\site-packages\pymysql\connections.py", line 563, in query
    self._affected_rows = self._read_query_result(unbuffered=unbuffered)
  File "C:\Users\a046829713\Desktop\program\RLTrading\lib\site-packages\pymysql\connections.py", line 825, in _read_query_result
    result.read()
  File "C:\Users\a046829713\Desktop\program\RLTrading\lib\site-packages\pymysql\connections.py", line 1199, in read
    first_packet = self.connection._read_packet()
  File "C:\Users\a046829713\Desktop\program\RLTrading\lib\site-packages\pymysql\connections.py", line 775, in _read_packet
    packet.raise_for_error()
  File "C:\Users\a046829713\Desktop\program\RLTrading\lib\site-packages\pymysql\protocol.py", line 219, in raise_for_error
    err.raise_mysql_exception(self._data)
  File "C:\Users\a046829713\Desktop\program\RLTrading\lib\site-packages\pymysql\err.py", line 150, in raise_mysql_exception
    raise errorclass(errno, errval)
pymysql.err.ProgrammingError: (1064, "You have an error in your SQL syntax; check the manual that corresponds to your MySQL server version for the right syntax to use near 'solvusdt-f-d' at line 1")

The above exception was the direct cause of the following exception:

Traceback (most recent call last):
  File "C:\Users\a046829713\Desktop\program\RLTrading\SynapseX\Database\SQL_operate.py", line 48, in read_Dateframe
    return pd.read_sql(text_msg, con=conn)
  File "C:\Users\a046829713\Desktop\program\RLTrading\lib\site-packages\pandas\io\sql.py", line 734, in read_sql
    return pandas_sql.read_query(
  File "C:\Users\a046829713\Desktop\program\RLTrading\lib\site-packages\pandas\io\sql.py", line 1836, in read_query
    result = self.execute(sql, params)
  File "C:\Users\a046829713\Desktop\program\RLTrading\lib\site-packages\pandas\io\sql.py", line 1659, in execute
    return self.con.exec_driver_sql(sql, *args)
  File "C:\Users\a046829713\Desktop\program\RLTrading\lib\site-packages\sqlalchemy\engine\base.py", line 1779, in exec_driver_sql
    ret = self._execute_context(
  File "C:\Users\a046829713\Desktop\program\RLTrading\lib\site-packages\sqlalchemy\engine\base.py", line 1846, in _execute_context
    return self._exec_single_context(
  File "C:\Users\a046829713\Desktop\program\RLTrading\lib\site-packages\sqlalchemy\engine\base.py", line 1986, in _exec_single_context
    self._handle_dbapi_exception(
  File "C:\Users\a046829713\Desktop\program\RLTrading\lib\site-packages\sqlalchemy\engine\base.py", line 2355, in _handle_dbapi_exception
    raise sqlalchemy_exception.with_traceback(exc_info[2]) from e
  File "C:\Users\a046829713\Desktop\program\RLTrading\lib\site-packages\sqlalchemy\engine\base.py", line 1967, in _exec_single_context
    self.dialect.do_execute(
  File "C:\Users\a046829713\Desktop\program\RLTrading\lib\site-packages\sqlalchemy\engine\default.py", line 941, in do_execute
    cursor.execute(statement, parameters)
  File "C:\Users\a046829713\Desktop\program\RLTrading\lib\site-packages\pymysql\cursors.py", line 153, in execute
    result = self._query(query)
  File "C:\Users\a046829713\Desktop\program\RLTrading\lib\site-packages\pymysql\cursors.py", line 322, in _query
    conn.query(q)
  File "C:\Users\a046829713\Desktop\program\RLTrading\lib\site-packages\pymysql\connections.py", line 563, in query
    self._affected_rows = self._read_query_result(unbuffered=unbuffered)
  File "C:\Users\a046829713\Desktop\program\RLTrading\lib\site-packages\pymysql\connections.py", line 825, in _read_query_result
    result.read()
  File "C:\Users\a046829713\Desktop\program\RLTrading\lib\site-packages\pymysql\connections.py", line 1199, in read
    first_packet = self.connection._read_packet()
  File "C:\Users\a046829713\Desktop\program\RLTrading\lib\site-packages\pymysql\connections.py", line 775, in _read_packet
    packet.raise_for_error()
  File "C:\Users\a046829713\Desktop\program\RLTrading\lib\site-packages\pymysql\protocol.py", line 219, in raise_for_error
    err.raise_mysql_exception(self._data)
  File "C:\Users\a046829713\Desktop\program\RLTrading\lib\site-packages\pymysql\err.py", line 150, in raise_mysql_exception
    raise errorclass(errno, errval)
sqlalchemy.exc.ProgrammingError: (pymysql.err.ProgrammingError) (1064, "You have an error in your SQL syntax; check the manual that corresponds to your MySQL server version for the right syntax to use near 'solvusdt-f-d' at line 1")
[SQL: solvusdt-f-d]
(Background on this error at: https://sqlalche.me/e/20/f405)

2025-01-21 03:32 ERROR Traceback (most recent call last):
  File "C:\Users\a046829713\Desktop\program\RLTrading\lib\site-packages\sqlalchemy\engine\base.py", line 1967, in _exec_single_context
    self.dialect.do_execute(
  File "C:\Users\a046829713\Desktop\program\RLTrading\lib\site-packages\sqlalchemy\engine\default.py", line 941, in do_execute
    cursor.execute(statement, parameters)
  File "C:\Users\a046829713\Desktop\program\RLTrading\lib\site-packages\pymysql\cursors.py", line 153, in execute
    result = self._query(query)
  File "C:\Users\a046829713\Desktop\program\RLTrading\lib\site-packages\pymysql\cursors.py", line 322, in _query
    conn.query(q)
  File "C:\Users\a046829713\Desktop\program\RLTrading\lib\site-packages\pymysql\connections.py", line 563, in query
    self._affected_rows = self._read_query_result(unbuffered=unbuffered)
  File "C:\Users\a046829713\Desktop\program\RLTrading\lib\site-packages\pymysql\connections.py", line 825, in _read_query_result
    result.read()
  File "C:\Users\a046829713\Desktop\program\RLTrading\lib\site-packages\pymysql\connections.py", line 1199, in read
    first_packet = self.connection._read_packet()
  File "C:\Users\a046829713\Desktop\program\RLTrading\lib\site-packages\pymysql\connections.py", line 775, in _read_packet
    packet.raise_for_error()
  File "C:\Users\a046829713\Desktop\program\RLTrading\lib\site-packages\pymysql\protocol.py", line 219, in raise_for_error
    err.raise_mysql_exception(self._data)
  File "C:\Users\a046829713\Desktop\program\RLTrading\lib\site-packages\pymysql\err.py", line 150, in raise_mysql_exception
    raise errorclass(errno, errval)
pymysql.err.ProgrammingError: (1064, "You have an error in your SQL syntax; check the manual that corresponds to your MySQL server version for the right syntax to use near 'arcusdt-f-d' at line 1")

The above exception was the direct cause of the following exception:

Traceback (most recent call last):
  File "C:\Users\a046829713\Desktop\program\RLTrading\SynapseX\Database\SQL_operate.py", line 48, in read_Dateframe
    return pd.read_sql(text_msg, con=conn)
  File "C:\Users\a046829713\Desktop\program\RLTrading\lib\site-packages\pandas\io\sql.py", line 734, in read_sql
    return pandas_sql.read_query(
  File "C:\Users\a046829713\Desktop\program\RLTrading\lib\site-packages\pandas\io\sql.py", line 1836, in read_query
    result = self.execute(sql, params)
  File "C:\Users\a046829713\Desktop\program\RLTrading\lib\site-packages\pandas\io\sql.py", line 1659, in execute
    return self.con.exec_driver_sql(sql, *args)
  File "C:\Users\a046829713\Desktop\program\RLTrading\lib\site-packages\sqlalchemy\engine\base.py", line 1779, in exec_driver_sql
    ret = self._execute_context(
  File "C:\Users\a046829713\Desktop\program\RLTrading\lib\site-packages\sqlalchemy\engine\base.py", line 1846, in _execute_context
    return self._exec_single_context(
  File "C:\Users\a046829713\Desktop\program\RLTrading\lib\site-packages\sqlalchemy\engine\base.py", line 1986, in _exec_single_context
    self._handle_dbapi_exception(
  File "C:\Users\a046829713\Desktop\program\RLTrading\lib\site-packages\sqlalchemy\engine\base.py", line 2355, in _handle_dbapi_exception
    raise sqlalchemy_exception.with_traceback(exc_info[2]) from e
  File "C:\Users\a046829713\Desktop\program\RLTrading\lib\site-packages\sqlalchemy\engine\base.py", line 1967, in _exec_single_context
    self.dialect.do_execute(
  File "C:\Users\a046829713\Desktop\program\RLTrading\lib\site-packages\sqlalchemy\engine\default.py", line 941, in do_execute
    cursor.execute(statement, parameters)
  File "C:\Users\a046829713\Desktop\program\RLTrading\lib\site-packages\pymysql\cursors.py", line 153, in execute
    result = self._query(query)
  File "C:\Users\a046829713\Desktop\program\RLTrading\lib\site-packages\pymysql\cursors.py", line 322, in _query
    conn.query(q)
  File "C:\Users\a046829713\Desktop\program\RLTrading\lib\site-packages\pymysql\connections.py", line 563, in query
    self._affected_rows = self._read_query_result(unbuffered=unbuffered)
  File "C:\Users\a046829713\Desktop\program\RLTrading\lib\site-packages\pymysql\connections.py", line 825, in _read_query_result
    result.read()
  File "C:\Users\a046829713\Desktop\program\RLTrading\lib\site-packages\pymysql\connections.py", line 1199, in read
    first_packet = self.connection._read_packet()
  File "C:\Users\a046829713\Desktop\program\RLTrading\lib\site-packages\pymysql\connections.py", line 775, in _read_packet
    packet.raise_for_error()
  File "C:\Users\a046829713\Desktop\program\RLTrading\lib\site-packages\pymysql\protocol.py", line 219, in raise_for_error
    err.raise_mysql_exception(self._data)
  File "C:\Users\a046829713\Desktop\program\RLTrading\lib\site-packages\pymysql\err.py", line 150, in raise_mysql_exception
    raise errorclass(errno, errval)
sqlalchemy.exc.ProgrammingError: (pymysql.err.ProgrammingError) (1064, "You have an error in your SQL syntax; check the manual that corresponds to your MySQL server version for the right syntax to use near 'arcusdt-f-d' at line 1")
[SQL: arcusdt-f-d]
(Background on this error at: https://sqlalche.me/e/20/f405)

2025-01-21 03:32 ERROR Traceback (most recent call last):
  File "C:\Users\a046829713\Desktop\program\RLTrading\lib\site-packages\sqlalchemy\engine\base.py", line 1967, in _exec_single_context
    self.dialect.do_execute(
  File "C:\Users\a046829713\Desktop\program\RLTrading\lib\site-packages\sqlalchemy\engine\default.py", line 941, in do_execute
    cursor.execute(statement, parameters)
  File "C:\Users\a046829713\Desktop\program\RLTrading\lib\site-packages\pymysql\cursors.py", line 153, in execute
    result = self._query(query)
  File "C:\Users\a046829713\Desktop\program\RLTrading\lib\site-packages\pymysql\cursors.py", line 322, in _query
    conn.query(q)
  File "C:\Users\a046829713\Desktop\program\RLTrading\lib\site-packages\pymysql\connections.py", line 563, in query
    self._affected_rows = self._read_query_result(unbuffered=unbuffered)
  File "C:\Users\a046829713\Desktop\program\RLTrading\lib\site-packages\pymysql\connections.py", line 825, in _read_query_result
    result.read()
  File "C:\Users\a046829713\Desktop\program\RLTrading\lib\site-packages\pymysql\connections.py", line 1199, in read
    first_packet = self.connection._read_packet()
  File "C:\Users\a046829713\Desktop\program\RLTrading\lib\site-packages\pymysql\connections.py", line 775, in _read_packet
    packet.raise_for_error()
  File "C:\Users\a046829713\Desktop\program\RLTrading\lib\site-packages\pymysql\protocol.py", line 219, in raise_for_error
    err.raise_mysql_exception(self._data)
  File "C:\Users\a046829713\Desktop\program\RLTrading\lib\site-packages\pymysql\err.py", line 150, in raise_mysql_exception
    raise errorclass(errno, errval)
pymysql.err.ProgrammingError: (1064, "You have an error in your SQL syntax; check the manual that corresponds to your MySQL server version for the right syntax to use near 'avaaiusdt-f-d' at line 1")

The above exception was the direct cause of the following exception:

Traceback (most recent call last):
  File "C:\Users\a046829713\Desktop\program\RLTrading\SynapseX\Database\SQL_operate.py", line 48, in read_Dateframe
    return pd.read_sql(text_msg, con=conn)
  File "C:\Users\a046829713\Desktop\program\RLTrading\lib\site-packages\pandas\io\sql.py", line 734, in read_sql
    return pandas_sql.read_query(
  File "C:\Users\a046829713\Desktop\program\RLTrading\lib\site-packages\pandas\io\sql.py", line 1836, in read_query
    result = self.execute(sql, params)
  File "C:\Users\a046829713\Desktop\program\RLTrading\lib\site-packages\pandas\io\sql.py", line 1659, in execute
    return self.con.exec_driver_sql(sql, *args)
  File "C:\Users\a046829713\Desktop\program\RLTrading\lib\site-packages\sqlalchemy\engine\base.py", line 1779, in exec_driver_sql
    ret = self._execute_context(
  File "C:\Users\a046829713\Desktop\program\RLTrading\lib\site-packages\sqlalchemy\engine\base.py", line 1846, in _execute_context
    return self._exec_single_context(
  File "C:\Users\a046829713\Desktop\program\RLTrading\lib\site-packages\sqlalchemy\engine\base.py", line 1986, in _exec_single_context
    self._handle_dbapi_exception(
  File "C:\Users\a046829713\Desktop\program\RLTrading\lib\site-packages\sqlalchemy\engine\base.py", line 2355, in _handle_dbapi_exception
    raise sqlalchemy_exception.with_traceback(exc_info[2]) from e
  File "C:\Users\a046829713\Desktop\program\RLTrading\lib\site-packages\sqlalchemy\engine\base.py", line 1967, in _exec_single_context
    self.dialect.do_execute(
  File "C:\Users\a046829713\Desktop\program\RLTrading\lib\site-packages\sqlalchemy\engine\default.py", line 941, in do_execute
    cursor.execute(statement, parameters)
  File "C:\Users\a046829713\Desktop\program\RLTrading\lib\site-packages\pymysql\cursors.py", line 153, in execute
    result = self._query(query)
  File "C:\Users\a046829713\Desktop\program\RLTrading\lib\site-packages\pymysql\cursors.py", line 322, in _query
    conn.query(q)
  File "C:\Users\a046829713\Desktop\program\RLTrading\lib\site-packages\pymysql\connections.py", line 563, in query
    self._affected_rows = self._read_query_result(unbuffered=unbuffered)
  File "C:\Users\a046829713\Desktop\program\RLTrading\lib\site-packages\pymysql\connections.py", line 825, in _read_query_result
    result.read()
  File "C:\Users\a046829713\Desktop\program\RLTrading\lib\site-packages\pymysql\connections.py", line 1199, in read
    first_packet = self.connection._read_packet()
  File "C:\Users\a046829713\Desktop\program\RLTrading\lib\site-packages\pymysql\connections.py", line 775, in _read_packet
    packet.raise_for_error()
  File "C:\Users\a046829713\Desktop\program\RLTrading\lib\site-packages\pymysql\protocol.py", line 219, in raise_for_error
    err.raise_mysql_exception(self._data)
  File "C:\Users\a046829713\Desktop\program\RLTrading\lib\site-packages\pymysql\err.py", line 150, in raise_mysql_exception
    raise errorclass(errno, errval)
sqlalchemy.exc.ProgrammingError: (pymysql.err.ProgrammingError) (1064, "You have an error in your SQL syntax; check the manual that corresponds to your MySQL server version for the right syntax to use near 'avaaiusdt-f-d' at line 1")
[SQL: avaaiusdt-f-d]
(Background on this error at: https://sqlalche.me/e/20/f405)

2025-01-21 03:32 ERROR Traceback (most recent call last):
  File "C:\Users\a046829713\Desktop\program\RLTrading\lib\site-packages\sqlalchemy\engine\base.py", line 1967, in _exec_single_context
    self.dialect.do_execute(
  File "C:\Users\a046829713\Desktop\program\RLTrading\lib\site-packages\sqlalchemy\engine\default.py", line 941, in do_execute
    cursor.execute(statement, parameters)
  File "C:\Users\a046829713\Desktop\program\RLTrading\lib\site-packages\pymysql\cursors.py", line 153, in execute
    result = self._query(query)
  File "C:\Users\a046829713\Desktop\program\RLTrading\lib\site-packages\pymysql\cursors.py", line 322, in _query
    conn.query(q)
  File "C:\Users\a046829713\Desktop\program\RLTrading\lib\site-packages\pymysql\connections.py", line 563, in query
    self._affected_rows = self._read_query_result(unbuffered=unbuffered)
  File "C:\Users\a046829713\Desktop\program\RLTrading\lib\site-packages\pymysql\connections.py", line 825, in _read_query_result
    result.read()
  File "C:\Users\a046829713\Desktop\program\RLTrading\lib\site-packages\pymysql\connections.py", line 1199, in read
    first_packet = self.connection._read_packet()
  File "C:\Users\a046829713\Desktop\program\RLTrading\lib\site-packages\pymysql\connections.py", line 775, in _read_packet
    packet.raise_for_error()
  File "C:\Users\a046829713\Desktop\program\RLTrading\lib\site-packages\pymysql\protocol.py", line 219, in raise_for_error
    err.raise_mysql_exception(self._data)
  File "C:\Users\a046829713\Desktop\program\RLTrading\lib\site-packages\pymysql\err.py", line 150, in raise_mysql_exception
    raise errorclass(errno, errval)
pymysql.err.ProgrammingError: (1064, "You have an error in your SQL syntax; check the manual that corresponds to your MySQL server version for the right syntax to use near 'trumpusdt-f-d' at line 1")

The above exception was the direct cause of the following exception:

Traceback (most recent call last):
  File "C:\Users\a046829713\Desktop\program\RLTrading\SynapseX\Database\SQL_operate.py", line 48, in read_Dateframe
    return pd.read_sql(text_msg, con=conn)
  File "C:\Users\a046829713\Desktop\program\RLTrading\lib\site-packages\pandas\io\sql.py", line 734, in read_sql
    return pandas_sql.read_query(
  File "C:\Users\a046829713\Desktop\program\RLTrading\lib\site-packages\pandas\io\sql.py", line 1836, in read_query
    result = self.execute(sql, params)
  File "C:\Users\a046829713\Desktop\program\RLTrading\lib\site-packages\pandas\io\sql.py", line 1659, in execute
    return self.con.exec_driver_sql(sql, *args)
  File "C:\Users\a046829713\Desktop\program\RLTrading\lib\site-packages\sqlalchemy\engine\base.py", line 1779, in exec_driver_sql
    ret = self._execute_context(
  File "C:\Users\a046829713\Desktop\program\RLTrading\lib\site-packages\sqlalchemy\engine\base.py", line 1846, in _execute_context
    return self._exec_single_context(
  File "C:\Users\a046829713\Desktop\program\RLTrading\lib\site-packages\sqlalchemy\engine\base.py", line 1986, in _exec_single_context
    self._handle_dbapi_exception(
  File "C:\Users\a046829713\Desktop\program\RLTrading\lib\site-packages\sqlalchemy\engine\base.py", line 2355, in _handle_dbapi_exception
    raise sqlalchemy_exception.with_traceback(exc_info[2]) from e
  File "C:\Users\a046829713\Desktop\program\RLTrading\lib\site-packages\sqlalchemy\engine\base.py", line 1967, in _exec_single_context
    self.dialect.do_execute(
  File "C:\Users\a046829713\Desktop\program\RLTrading\lib\site-packages\sqlalchemy\engine\default.py", line 941, in do_execute
    cursor.execute(statement, parameters)
  File "C:\Users\a046829713\Desktop\program\RLTrading\lib\site-packages\pymysql\cursors.py", line 153, in execute
    result = self._query(query)
  File "C:\Users\a046829713\Desktop\program\RLTrading\lib\site-packages\pymysql\cursors.py", line 322, in _query
    conn.query(q)
  File "C:\Users\a046829713\Desktop\program\RLTrading\lib\site-packages\pymysql\connections.py", line 563, in query
    self._affected_rows = self._read_query_result(unbuffered=unbuffered)
  File "C:\Users\a046829713\Desktop\program\RLTrading\lib\site-packages\pymysql\connections.py", line 825, in _read_query_result
    result.read()
  File "C:\Users\a046829713\Desktop\program\RLTrading\lib\site-packages\pymysql\connections.py", line 1199, in read
    first_packet = self.connection._read_packet()
  File "C:\Users\a046829713\Desktop\program\RLTrading\lib\site-packages\pymysql\connections.py", line 775, in _read_packet
    packet.raise_for_error()
  File "C:\Users\a046829713\Desktop\program\RLTrading\lib\site-packages\pymysql\protocol.py", line 219, in raise_for_error
    err.raise_mysql_exception(self._data)
  File "C:\Users\a046829713\Desktop\program\RLTrading\lib\site-packages\pymysql\err.py", line 150, in raise_mysql_exception
    raise errorclass(errno, errval)
sqlalchemy.exc.ProgrammingError: (pymysql.err.ProgrammingError) (1064, "You have an error in your SQL syntax; check the manual that corresponds to your MySQL server version for the right syntax to use near 'trumpusdt-f-d' at line 1")
[SQL: trumpusdt-f-d]
(Background on this error at: https://sqlalche.me/e/20/f405)

2025-01-21 03:32 ERROR Traceback (most recent call last):
  File "C:\Users\a046829713\Desktop\program\RLTrading\lib\site-packages\sqlalchemy\engine\base.py", line 1967, in _exec_single_context
    self.dialect.do_execute(
  File "C:\Users\a046829713\Desktop\program\RLTrading\lib\site-packages\sqlalchemy\engine\default.py", line 941, in do_execute
    cursor.execute(statement, parameters)
  File "C:\Users\a046829713\Desktop\program\RLTrading\lib\site-packages\pymysql\cursors.py", line 153, in execute
    result = self._query(query)
  File "C:\Users\a046829713\Desktop\program\RLTrading\lib\site-packages\pymysql\cursors.py", line 322, in _query
    conn.query(q)
  File "C:\Users\a046829713\Desktop\program\RLTrading\lib\site-packages\pymysql\connections.py", line 563, in query
    self._affected_rows = self._read_query_result(unbuffered=unbuffered)
  File "C:\Users\a046829713\Desktop\program\RLTrading\lib\site-packages\pymysql\connections.py", line 825, in _read_query_result
    result.read()
  File "C:\Users\a046829713\Desktop\program\RLTrading\lib\site-packages\pymysql\connections.py", line 1199, in read
    first_packet = self.connection._read_packet()
  File "C:\Users\a046829713\Desktop\program\RLTrading\lib\site-packages\pymysql\connections.py", line 775, in _read_packet
    packet.raise_for_error()
  File "C:\Users\a046829713\Desktop\program\RLTrading\lib\site-packages\pymysql\protocol.py", line 219, in raise_for_error
    err.raise_mysql_exception(self._data)
  File "C:\Users\a046829713\Desktop\program\RLTrading\lib\site-packages\pymysql\err.py", line 150, in raise_mysql_exception
    raise errorclass(errno, errval)
pymysql.err.ProgrammingError: (1064, "You have an error in your SQL syntax; check the manual that corresponds to your MySQL server version for the right syntax to use near 'melaniausdt-f-d' at line 1")

The above exception was the direct cause of the following exception:

Traceback (most recent call last):
  File "C:\Users\a046829713\Desktop\program\RLTrading\SynapseX\Database\SQL_operate.py", line 48, in read_Dateframe
    return pd.read_sql(text_msg, con=conn)
  File "C:\Users\a046829713\Desktop\program\RLTrading\lib\site-packages\pandas\io\sql.py", line 734, in read_sql
    return pandas_sql.read_query(
  File "C:\Users\a046829713\Desktop\program\RLTrading\lib\site-packages\pandas\io\sql.py", line 1836, in read_query
    result = self.execute(sql, params)
  File "C:\Users\a046829713\Desktop\program\RLTrading\lib\site-packages\pandas\io\sql.py", line 1659, in execute
    return self.con.exec_driver_sql(sql, *args)
  File "C:\Users\a046829713\Desktop\program\RLTrading\lib\site-packages\sqlalchemy\engine\base.py", line 1779, in exec_driver_sql
    ret = self._execute_context(
  File "C:\Users\a046829713\Desktop\program\RLTrading\lib\site-packages\sqlalchemy\engine\base.py", line 1846, in _execute_context
    return self._exec_single_context(
  File "C:\Users\a046829713\Desktop\program\RLTrading\lib\site-packages\sqlalchemy\engine\base.py", line 1986, in _exec_single_context
    self._handle_dbapi_exception(
  File "C:\Users\a046829713\Desktop\program\RLTrading\lib\site-packages\sqlalchemy\engine\base.py", line 2355, in _handle_dbapi_exception
    raise sqlalchemy_exception.with_traceback(exc_info[2]) from e
  File "C:\Users\a046829713\Desktop\program\RLTrading\lib\site-packages\sqlalchemy\engine\base.py", line 1967, in _exec_single_context
    self.dialect.do_execute(
  File "C:\Users\a046829713\Desktop\program\RLTrading\lib\site-packages\sqlalchemy\engine\default.py", line 941, in do_execute
    cursor.execute(statement, parameters)
  File "C:\Users\a046829713\Desktop\program\RLTrading\lib\site-packages\pymysql\cursors.py", line 153, in execute
    result = self._query(query)
  File "C:\Users\a046829713\Desktop\program\RLTrading\lib\site-packages\pymysql\cursors.py", line 322, in _query
    conn.query(q)
  File "C:\Users\a046829713\Desktop\program\RLTrading\lib\site-packages\pymysql\connections.py", line 563, in query
    self._affected_rows = self._read_query_result(unbuffered=unbuffered)
  File "C:\Users\a046829713\Desktop\program\RLTrading\lib\site-packages\pymysql\connections.py", line 825, in _read_query_result
    result.read()
  File "C:\Users\a046829713\Desktop\program\RLTrading\lib\site-packages\pymysql\connections.py", line 1199, in read
    first_packet = self.connection._read_packet()
  File "C:\Users\a046829713\Desktop\program\RLTrading\lib\site-packages\pymysql\connections.py", line 775, in _read_packet
    packet.raise_for_error()
  File "C:\Users\a046829713\Desktop\program\RLTrading\lib\site-packages\pymysql\protocol.py", line 219, in raise_for_error
    err.raise_mysql_exception(self._data)
  File "C:\Users\a046829713\Desktop\program\RLTrading\lib\site-packages\pymysql\err.py", line 150, in raise_mysql_exception
    raise errorclass(errno, errval)
sqlalchemy.exc.ProgrammingError: (pymysql.err.ProgrammingError) (1064, "You have an error in your SQL syntax; check the manual that corresponds to your MySQL server version for the right syntax to use near 'melaniausdt-f-d' at line 1")
[SQL: melaniausdt-f-d]
(Background on this error at: https://sqlalche.me/e/20/f405)

